Workbook

Sheet Summary
A2: % Dominance gain wrt Non-Causal Baseline [median] | M2: % Sequential Time gain wrt Non-Causal Baseline [median]
A3: Target or symm.; Gain > 0 | B3: Leakage | D3: Data Size | E3: Name | F3: Algorithm | M3: Target or symm.; Gain > 0 | N3: Leakage | P3: Data Size | Q3: Name | R3: Algorithm
B4: Open | C4: Closed | F4: BNL | G4: BNL HM | H4: SFS | I4: SaLSa | J4: D&C | K4: BBS | N4: Open | O4: Closed | R4: BNL | S4: BNL HM | T4: SFS | U4: SaLSa | V4: D&C | W4: BBS
A5: lnSkyline (0.6, 0.4) | B5: 0.6 | C5: 0.4 | D5: 50K | E5: lnSkyline (0.6, 0.4) | F5: ='50K'!M644 -> 0.2921895 | G5: ='50K'!N644 -> 0.28581688 | H5: ='50K'!O644 -> 0.58014496 | I5: ='50K'!P644 -> 0.64019211 | J5: ='50K'!Q644 -> 0.20451954 | K5: ='50K'!R644 -> 0.76714638 | M5: lnSkyline (0.6, 0.4) | N5: 0.6 | O5: 0.4 | P5: 50K | Q5: lnSkyline (0.6, 0.4) | R5: ='50K'!T644 -> 0.16619748 | S5: ='50K'!U644 -> 0.20049112 | T5: ='50K'!V644 -> 0.41801894 | U5: ='50K'!W644 -> 0.44066132 | V5: ='50K'!X644 -> 0.014348409 | W5: ='50K'!Y644 -> 0.19742246
A6: lnSkyline (0.6, 0.4) | B6: 0.6 | C6: 0.4 | D6: 100K | E6: lnSkyline (0.6, 0.4) | F6: ='100K'!M644 -> 0.27543892 | G6: ='100K'!N644 -> 0.26740692 | H6: ='100K'!O644 -> 0.63335814 | I6: ='100K'!P644 -> 0.69540805 | J6: ='100K'!Q644 -> 0.19571997 | K6: ='100K'!R644 -> 0.77587823 | M6: lnSkyline (0.6, 0.4) | N6: 0.6 | O6: 0.4 | P6: 100K | Q6: lnSkyline (0.6, 0.4) | R6: ='100K'!T644 -> 0.23335552 | S6: ='100K'!U644 -> 0.23468235 | T6: ='100K'!V644 -> 0.46509343 | U6: ='100K'!W644 -> 0.53858971 | V6: ='100K'!X644 -> 0.0086722981 | W6: ='100K'!Y644 -> 0.3956884
A7: lnSkyline (0.6, 0.4) | B7: 0.6 | C7: 0.4 | D7: 200K | E7: lnSkyline (0.6, 0.4) | F7: ='200K'!M649 -> 0.33265982 | G7: ='200K'!N649 -> 0.32951513 | H7: ='200K'!O649 -> 0.67091148 | I7: ='200K'!P649 -> 0.76107603 | J7: ='200K'!Q649 -> 0.18514995 | K7: ='200K'!R649 -> 0.79145208 | M7: lnSkyline (0.6, 0.4) | N7: 0.6 | O7: 0.4 | P7: 200K | Q7: lnSkyline (0.6, 0.4) | R7: ='200K'!T649 -> 0.26401017 | S7: ='200K'!U649 -> 0.26483101 | T7: ='200K'!V649 -> 0.4862091 | U7: ='200K'!W649 -> 0.54150486 | V7: ='200K'!X649 -> 0.02999235 | W7: ='200K'!Y649 -> 0.5196199
A8: lnSkyline (0.6, 0.4) | B8: 0.6 | C8: 0.4 | D8: 400K | E8: lnSkyline (0.6, 0.4) | F8: ='400K'!M644 -> 0.32866529 | G8: ='400K'!N644 -> 0.32475739 | H8: ='400K'!O644 -> 0.73114689 | I8: ='400K'!P644 -> 0.77245306 | J8: ='400K'!Q644 -> 0.17960713 | K8: ='400K'!R644 -> 0.77857484 | M8: lnSkyline (0.6, 0.4) | N8: 0.6 | O8: 0.4 | P8: 400K | Q8: lnSkyline (0.6, 0.4) | R8: ='400K'!T644 -> 0.31150666 | S8: ='400K'!U644 -> 0.31528621 | T8: ='400K'!V644 -> 0.5587785 | U8: ='400K'!W644 -> 0.6238663 | V8: ='400K'!X644 -> 0.033298634 | W8: ='400K'!Y644 -> 0.60129309

Sheet 50K
M1: Average Benchmark (results) | Y1: Average Benchmark (sequential timing) | AK1: Average Benchmark (parallel timing) | AW1: Average Benchmark (cluster_time)
F2: =F648 -> TargetN | G2: =G648 -> #N | H2: =H648 -> Target (or sym) | I2: =I648 -> Gain <=0 | J2: =J648 -> Gain > 0 | K2: =K648 -> Pref | L2: =L648 -> Pref&Target | M2: BNL | N2: BNL Causal | O2: BNL Causal HM | P2: SFS | Q2: SFS Causal | R2: SaLSa | S2: SaLSa Causal | T2: D&C | U2: D&C Causal | V2: BBS | W2: BBS Causal | Y2: BNL | Z2: BNL Causal | AA2: BNL Causal HM | AB2: SFS | AC2: SFS Causal | AD2: SaLSa | AE2: SaLSa Causal | AF2: D&C | AG2: D&C Causal | AH2: BBS | AI2: BBS Causal | AK2: BNL | AL2: BNL Causal | AM2: BNL Causal HM | AN2: SFS | AO2: SFS Causal | AP2: SaLSa | AQ2: SaLSa Causal | AR2: D&C | AS2: D&C Causal | AT2: BBS | AU2: BBS Causal | AW2: KMeans Time (seconds) | AY2: Gain | AZ2: =AX648 -> Target (or sym) ; Gain | BA2: =AY648 -> Gain<=0 | BB2: =AZ648 -> Gain>0
A3: 21 | B3: 156XXXX | C3: Hong_Kong_Weather_3 | D3: {cloud, mean_wet_bulb_temp, rainfall, rel_humidity} | F3: =F649 -> 0 | G3: =G649 -> 0 | H3: =H649 -> 1 | I3: =I649 -> 1 | J3: =J649 -> 0 | K3: =K649 -> 4 | L3: =L649 -> 4 | M3: 269984.4 | N3: 578669.8 | O3: 583009.4 | P3: 323111.6 | Q3: 271772.6 | R3: 221468 | S3: 379587.4 | T3: 948204.6 | U3: 995750.8 | V3: 398373.6 | W3: 448453.4 | Y3: 0.31130449 | Z3: 0.46694044 | AA3: 0.46585424 | AB3: 0.38659678 | AC3: 0.34456494 | AD3: 0.27762634 | AE3: 0.48752316 | AF3: 0.43352386 | AG3: 0.75832728 | AH3: 0.48186491 | AI3: 1.1752611 | AK3: 0.31130449 | AL3: 0.13564001 | AM3: 0.13171094 | AN3: 0.38659678 | AO3: 0.11752638 | AP3: 0.27762634 | AQ3: 0.14759665 | AR3: 0.26669934 | AS3: 0.12294607 | AT3: 0.48186491 | AU3: 0.86669171 | AW3: 0.047619221 | AY3: =BB339 -> -0.35233006 | AZ3: =AX649 -> -0.35233006 | BA3: =AY649 -> -0.35233006 | BB3: =AZ649
A4: 21 | B4: 156XXXN | C4: Hong_Kong_Weather_3 | D4: {cloud, mean_wet_bulb_temp, rainfall, rel_humidity} | F4: =F650 -> 0 | G4: =G650 -> 1 | H4: =H650 -> 0 | I4: =I650 -> 1 | J4: =J650 -> 0 | K4: =K650 -> 4 | L4: =L650 -> 0 | M4: 3257755.6 | N4: 2505039.6 | O4: 2581337.8 | P4: 2557830.2 | Q4: 829023.8 | R4: 3615106 | S4: 1652636 | T4: 1236247 | U4: 1139764.8 | V4: 3699807.4 | W4: 1797880 | Y4: 2.2436864 | Z4: 1.6640197 | AA4: 1.6948634 | AB4: 1.4201252 | AC4: 0.74167301 | AD4: 2.3113559 | AE4: 1.2721517 | AF4: 0.72656669 | AG4: 0.92852619 | AH4: 1.2752694 | AI4: 3.1760625 | AK4: 2.2436864 | AL4: 0.62424011 | AM4: 0.65694211 | AN4: 1.4201252 | AO4: 0.27268982 | AP4: 2.3113559 | AQ4: 0.42223873 | AR4: 0.39860019 | AS4: 0.20684827 | AT4: 1.2752694 | AU4: 2.7017394 | AW4: 0.048989649 | AY4: =BB340 -> -0.058564036 | AZ4: =AX650 | BA4: =AY650 -> -0.058564036 | BB4: =AZ650
A5: 21 | B5: 156XXNX | C5: Hong_Kong_Weather_3 | D5: {cloud, mean_wet_bulb_temp, rainfall, rel_humidity} | F5: =F651 -> 0 | G5: =G651 -> 1 | H5: =H651 -> 0 | I5: =I651 -> 1 | J5: =J651 -> 0 | K5: =K651 -> 4 | L5: =L651 -> 0 | M5: 1086194.2 | N5: 1080916 | O5: 1086936 | P5: 303141.6 | Q5: 371605.6 | R5: 196672.6 | S5: 263791 | T5: 976989.4 | U5: 972998.2 | V5: 540024.2 | W5: 502720.2 | Y5: 0.86786147 | Z5: 0.77284459 | AA5: 0.76519141 | AB5: 0.49591518 | AC5: 0.46384334 | AD5: 0.44310027 | AE5: 0.48320975 | AF5: 0.45127055 | AG5: 0.70698286 | AH5: 0.55899443 | AI5: 1.4028484 | AK5: 0.86786147 | AL5: 0.25859907 | AM5: 0.25288211 | AN5: 0.49591518 | AO5: 0.18533953 | AP5: 0.44310027 | AQ5: 0.15661274 | AR5: 0.30439443 | AS5: 0.14978538 | AT5: 0.55899443 | AU5: 1.0864082 | AW5: 0.047973658 | AY5: =BB341 -> -0.12790196 | AZ5: =AX651 | BA5: =AY651 -> -0.12790196 | BB5: =AZ651
A6: 21 | B6: 156XXNN | C6: Hong_Kong_Weather_3 | D6: {cloud, mean_wet_bulb_temp, rainfall, rel_humidity} | F6: =F652 -> 0 | G6: =G652 -> 0 | H6: =H652 -> 0 | I6: =I652 -> 0 | J6: =J652 -> 1 | K6: =K652 -> 4 | L6: =L652 -> 0 | M6: 1742747.6 | N6: 1098925 | O6: 1116451.6 | P6: 458208 | Q6: 383061.2 | R6: 337896 | S6: 305661.4 | T6: 1079943.4 | U6: 744567.6 | V6: 1768674.2 | W6: 335948 | Y6: 1.3216479 | Z6: 0.86774749 | AA6: 0.86872147 | AB6: 0.65332104 | AC6: 0.51293454 | AD6: 0.71250727 | AE6: 0.62079889 | AF6: 0.52897701 | AG6: 0.50343214 | AH6: 0.91162493 | AI6: 1.1435893 | AK6: 1.3216479 | AL6: 0.31392297 | AM6: 0.31580093 | AN6: 0.65332104 | AO6: 0.18760895 | AP6: 0.71250727 | AQ6: 0.20758691 | AR6: 0.29671005 | AS6: 0.11865458 | AT6: 0.91162493 | AU6: 0.86697056 | AW6: 0.048967177 | AY6: =BB342 -> 0.11627095 | AZ6: =AX652 | BA6: =AY652 | BB6: =AZ652 -> 0.11627095
A7: 21 | B7: 156XNXX | C7: Hong_Kong_Weather_3 | D7: {cloud, mean_wet_bulb_temp, rainfall, rel_humidity} | F7: =F653 -> 0 | G7: =G653 -> 1 | H7: =H653 -> 0 | I7: =I653 -> 0 | J7: =J653 -> 1 | K7: =K653 -> 4 | L7: =L653 -> 0 | M7: 376402.8 | N7: 265111.4 | O7: 267464.8 | P7: 583506 | Q7: 118208.4 | R7: 316829.6 | S7: 123080.2 | T7: 1131124.6 | U7: 829331.2 | V7: 1325021.2 | W7: 180534.2 | Y7: 0.41767454 | Z7: 0.30271788 | AA7: 0.29582352 | AB7: 0.58185386 | AC7: 0.22843721 | AD7: 0.62219746 | AE7: 0.28472281 | AF7: 0.62986446 | AG7: 0.62613573 | AH7: 0.78464564 | AI7: 0.59338349 | AK7: 0.41767454 | AL7: 0.11813437 | AM7: 0.1109549 | AN7: 0.58185386 | AO7: 0.090459982 | AP7: 0.62219746 | AQ7: 0.10460196 | AR7: 0.32315636 | AS7: 0.10431334 | AT7: 0.78464564 | AU7: 0.38848551 | AW7: 0.049190626 | AY7: =BB343 -> 0.23808718 | AZ7: =AX653 | BA7: =AY653 | BB7: =AZ653 -> 0.23808718
A8: 21 | B8: 156XNXN | C8: Hong_Kong_Weather_3 | D8: {cloud, mean_wet_bulb_temp, rainfall, rel_humidity} | F8: =F654 -> 0 | G8: =G654 -> 0 | H8: =H654 -> 0 | I8: =I654 -> 0 | J8: =J654 -> 1 | K8: =K654 -> 4 | L8: =L654 -> 0 | M8: 1313530.4 | N8: 2646597.4 | O8: 2656997.6 | P8: 914736.6 | Q8: 1042407.8 | R8: 980203.2 | S8: 1952153.4 | T8: 950071.4 | U8: 1332403.2 | V8: 3183123.2 | W8: 1959840.6 | Y8: 1.1725625 | Z8: 1.7823396 | AA8: 1.7877421 | AB8: 1.119448 | AC8: 0.77173628 | AD8: 1.2317946 | AE8: 1.359707 | AF8: 0.46761409 | AG8: 1.1909256 | AH8: 1.115568 | AI8: 4.0899927 | AK8: 1.1725625 | AL8: 0.56054718 | AM8: 0.56511701 | AN8: 1.119448 | AO8: 0.27627251 | AP8: 1.2317946 | AQ8: 0.3558864 | AR8: 0.31201111 | AS8: 0.21036292 | AT8: 1.115568 | AU8: 3.5498679 | AW8: 0.048453175 | AY8: =BB344 -> 0.089505628 | AZ8: =AX654 | BA8: =AY654 | BB8: =AZ654 -> 0.089505628
A9: 21 | B9: 156XNNX | C9: Hong_Kong_Weather_3 | D9: {cloud, mean_wet_bulb_temp, rainfall, rel_humidity} | F9: =F655 -> 0 | G9: =G655 -> 0 | H9: =H655 -> 0 | I9: =I655 -> 0 | J9: =J655 -> 1 | K9: =K655 -> 4 | L9: =L655 -> 0 | M9: 493127.2 | N9: 532666.2 | O9: 536081.6 | P9: 353382.8 | Q9: 185567 | R9: 147489.4 | S9: 125503 | T9: 1072550.8 | U9: 773606.8 | V9: 150033.2 | W9: 128327 | Y9: 0.46102336 | Z9: 0.47603831 | AA9: 0.46812081 | AB9: 0.44072307 | AC9: 0.29557961 | AD9: 0.39890276 | AE9: 0.38884355 | AF9: 0.53307827 | AG9: 0.53806397 | AH9: 0.44276683 | AI9: 0.68167674 | AK9: 0.46102336 | AL9: 0.16280767 | AM9: 0.15610499 | AN9: 0.44072307 | AO9: 0.13102153 | AP9: 0.39890276 | AQ9: 0.11725277 | AR9: 0.29569909 | AS9: 0.10689375 | AT9: 0.44276683 | AU9: 0.48057664 | AW9: 0.049055408 | AY9: =BB345 -> 0.14655348 | AZ9: =AX655 | BA9: =AY655 | BB9: =AZ655 -> 0.14655348
A10: 21 | B10: 156XNNN | C10: Hong_Kong_Weather_3 | D10: {cloud, mean_wet_bulb_temp, rainfall, rel_humidity} | F10: =F656 -> 0 | G10: =G656 -> 1 | H10: =H656 -> 0 | I10: =I656 -> 1 | J10: =J656 -> 0 | K10: =K656 -> 4 | L10: =L656 -> 0 | M10: 367907.8 | N10: 1122260.4 | O10: 1128993 | P10: 116064.4 | Q10: 254109.4 | R10: 87087.2 | S10: 229793.4 | T10: 820344.8 | U10: 872312.6 | V10: 65256.6 | W10: 311276.4 | Y10: 0.39314735 | Z10: 0.85075649 | AA10: 0.84135945 | AB10: 0.26418936 | AC10: 0.36635746 | AD10: 0.39406833 | AE10: 0.53035051 | AF10: 0.30147554 | AG10: 0.62806453 | AH10: 0.28813609 | AI10: 1.5002517 | AK10: 0.39314735 | AL10: 0.21049846 | AM10: 0.20512451 | AN10: 0.26418936 | AO10: 0.11902807 | AP10: 0.39406833 | AQ10: 0.14971225 | AR10: 0.18795791 | AS10: 0.10420054 | AT10: 0.28813609 | AU10: 1.2063649 | AW10: 0.049859962 | AY10: =BB346 -> -0.051621186 | AZ10: =AX656 | BA10: =AY656 -> -0.051621186 | BB10: =AZ656
A11: 21 | B11: 156NXXX | C11: Hong_Kong_Weather_3 | D11: {cloud, mean_wet_bulb_temp, rainfall, rel_humidity} | F11: =F657 -> 0 | G11: =G657 -> 1 | H11: =H657 -> 0 | I11: =I657 -> 1 | J11: =J657 -> 0 | K11: =K657 -> 4 | L11: =L657 -> 0 | M11: 1890379.4 | N11: 2855553.8 | O11: 2887463.2 | P11: 1434346.8 | Q11: 1032448.2 | R11: 2097475.2 | S11: 1908876.6 | T11: 964880.6 | U11: 1099603 | V11: 3125783.6 | W11: 1955433.8 | Y11: 1.6577712 | Z11: 1.9952103 | AA11: 2.0039708 | AB11: 1.5920481 | AC11: 0.96936235 | AD11: 1.977401 | AE11: 1.7042817 | AF11: 0.4742408 | AG11: 0.91628214 | AH11: 1.5883862 | AI11: 4.4997169 | AK11: 1.6577712 | AL11: 0.65858732 | AM11: 0.66994982 | AN11: 1.5920481 | AO11: 0.37227667 | AP11: 1.977401 | AQ11: 0.57898133 | AR11: 0.28662192 | AS11: 0.1533454 | AT11: 1.5883862 | AU11: 3.9121992 | AW11: 0.050339851 | AY11: =BB347 -> -0.051621186 | AZ11: =AX657 | BA11: =AY657 -> -0.051621186 | BB11: =AZ657
A12: 21 | B12: 156NXXN | C12: Hong_Kong_Weather_3 | D12: {cloud, mean_wet_bulb_temp, rainfall, rel_humidity} | F12: =F658 -> 0 | G12: =G658 -> 0 | H12: =H658 -> 0 | I12: =I658 -> 0 | J12: =J658 -> 1 | K12: =K658 -> 4 | L12: =L658 -> 0 | M12: 1935132.2 | N12: 1559613.6 | O12: 1585575 | P12: 2420692.6 | Q12: 962145.4 | R12: 1920009 | S12: 956384.4 | T12: 1201063.8 | U12: 1044015 | V12: 4786216.8 | W12: 1439257.2 | Y12: 1.5027143 | Z12: 1.1234647 | AA12: 1.1314607 | AB12: 2.0638456 | AC12: 0.95980674 | AD12: 1.9385822 | AE12: 1.1113175 | AF12: 0.72495156 | AG12: 0.86598811 | AH12: 1.6623469 | AI12: 2.116388 | AK12: 1.5027143 | AL12: 0.51716777 | AM12: 0.52389471 | AN12: 2.0638456 | AO12: 0.45308215 | AP12: 1.9385822 | AQ12: 0.45968775 | AR12: 0.38921216 | AS12: 0.1720394 | AT12: 1.6623469 | AU12: 1.6982232 | AW12: 0.050292022 | AY12: =BB348 -> 0.14655348 | AZ12: =AX658 | BA12: =AY658 | BB12: =AZ658 -> 0.14655348
A13: 21 | B13: 156NXNX | C13: Hong_Kong_Weather_3 | D13: {cloud, mean_wet_bulb_temp, rainfall, rel_humidity} | F13: =F659 -> 0 | G13: =G659 -> 0 | H13: =H659 -> 0 | I13: =I659 -> 0 | J13: =J659 -> 1 | K13: =K659 -> 4 | L13: =L659 -> 0 | M13: 1204995 | N13: 1592226.2 | O13: 1595818.8 | P13: 929775.4 | Q13: 751670 | R13: 626525.4 | S13: 587780.6 | T13: 981010.8 | U13: 1004733.6 | V13: 1243023.6 | W13: 1010553.8 | Y13: 1.0264924 | Z13: 1.1464377 | AA13: 1.1365433 | AB13: 0.63149583 | AC13: 0.49795173 | AD13: 0.65310467 | AE13: 0.62226721 | AF13: 0.47119547 | AG13: 0.77044591 | AH13: 0.71706827 | AI13: 1.9539983 | AK13: 1.0264924 | AL13: 0.3497344 | AM13: 0.34027087 | AN13: 0.63149583 | AO13: 0.17179463 | AP13: 0.65310467 | AQ13: 0.18926422 | AR13: 0.3169553 | AS13: 0.15469352 | AT13: 0.71706827 | AU13: 1.5652723 | AW13: 0.050910542 | AY13: =BB349 -> 0.089505628 | AZ13: =AX659 | BA13: =AY659 | BB13: =AZ659 -> 0.089505628
A14: 21 | B14: 156NXNN | C14: Hong_Kong_Weather_3 | D14: {cloud, mean_wet_bulb_temp, rainfall, rel_humidity} | F14: =F660 -> 0 | G14: =G660 -> 1 | H14: =H660 -> 0 | I14: =I660 -> 0 | J14: =J660 -> 1 | K14: =K660 -> 4 | L14: =L660 -> 0 | M14: 616789.6 | N14: 272845.4 | O14: 276069.2 | P14: 949677.2 | Q14: 114977.6 | R14: 746168.6 | S14: 92567.8 | T14: 1064725.6 | U14: 689983.4 | V14: 1700610.4 | W14: 145730 | Y14: 0.52589546 | Z14: 0.30123813 | AA14: 0.29357838 | AB14: 0.7837307 | AC14: 0.21999604 | AD14: 0.85264862 | AE14: 0.36917605 | AF14: 0.51727988 | AG14: 0.45345677 | AH14: 0.88264419 | AI14: 0.4708653 | AK14: 0.52589546 | AL14: 0.11899853 | AM14: 0.11184733 | AN14: 0.7837307 | AO14: 0.092265999 | AP14: 0.85264862 | AQ14: 0.11492884 | AR14: 0.28666471 | AS14: 0.093803715 | AT14: 0.88264419 | AU14: 0.3071542 | AW14: 0.04954614 | AY14: =BB350 -> 0.23808718 | AZ14: =AX660 | BA14: =AY660 | BB14: =AZ660 -> 0.23808718
... A58: 24 | B58: 160NNN | C58: AutoMPG8 | D58: {acceleration, displacement, weight} | F58: =F704 -> 0 | G58: =G704 -> 1 | H58: =H704 -> 0 | I58: =I704 -> 1 | J58: =J704 -> 0 | K58: =K704 -> 3 | L58: =L704 -> 0 | M58: 392252.4 | N58: 324159.4 | O58: 326848.8 | P58: 209236.2 | Q58: 119625.6 | R58: 223061.4 | S58: 111655.6 | T58: 780876.8 | U58: 713363.6 | V58: 659255.8 | W58: 300460 | Y58: 0.41253289 | Z58: 0.35739431 | AA58: 0.34604394 | AB58: 0.33009452 | AC58: 0.25987152 | AD58: 0.30585887 | AE58: 0.2046818 | AF58: 0.38027424 | AG58: 0.48695699 | AH58: 0.60349227 | AI58: 0.63933964 | AK58: 0.41253289 | AL58: 0.15168838 | AM58: 0.14181243 | AN58: 0.33009452 | AO58: 0.11809127 | AP58: 0.30585887 | AQ58: 0.10263054 | AR58: 0.19459239 | AS58: 0.10697394 | AT58: 0.60349227 | AU58: 0.39181141 | AW58: 0.073129573 | AY58: =BB394 -> -0.16298496 | AZ58: =AX704 | BA58: =AY704 -> -0.16298496 | BB58: =AZ704
K292: Mean | L292: =X292 -> 0.6 | M292: BNL | N292: BNL Causal | O292: BNL Causal HM | P292: SFS | Q292: SFS Causal | R292: SaLSa | S292: SaLSa Causal | T292: D&C | U292: D&C Causal | V292: BBS | W292: BBS Causal | X292: 0.6 | Y292: BNL | Z292: BNL Causal | AA292: BNL Causal HM | AB292: SFS | AC292: SFS Causal | AD292: SaLSa | AE292: SaLSa Causal | AF292: D&C | AG292: D&C Causal | AH292: BBS | AI292: BBS Causal | AJ292: =X292 -> 0.6 | AK292: BNL | AL292: BNL Causal | AM292: BNL Causal HM | AN292: SFS | AO292: SFS Causal | AP292: SaLSa | AQ292: SaLSa Causal | AR292: D&C | AS292: D&C Causal | AT292: BBS | AU292: BBS Causal
L293: ALL | M293: =AVERAGE(M3:M290) -> 930554.28 | N293: =AVERAGE(N3:N290) -> 901672.42 | O293: =AVERAGE(O3:O290) -> 912537.68 | P293: =AVERAGE(P3:P290) -> 1081169.6 | Q293: =AVERAGE(Q3:Q290) -> 444080.32 | R293: =AVERAGE(R3:R290) -> 940308.81 | S293: =AVERAGE(S3:S290) -> 542860.25 | T293: =AVERAGE(T3:T290) -> 1154167.8 | ... W293: =AVERAGE(W3:W290) -> 802702.26 | X293: ALL | Y293: =AVERAGE(Y3:Y290) -> 0.78288923 | Z293: =AVERAGE(Z3:Z290) -> 0.73730059 | AA293: =AVERAGE(AA3:AA290) -> 0.73054789 | AB293: =AVERAGE(AB3:AB290) -> 0.94668167 | AC293: =AVERAGE(AC3:AC290) -> 0.47936071 | AD293: =AVERAGE(AD3:AD290) -> 0.89846014 | AE293: =AVERAGE(AE3:AE290) -> 0.63691626 | AF293: =AVERAGE(AF3:AF290) -> 0.70732907 | ... AI293: =AVERAGE(AI3:AI290) -> 1.4116762 | AJ293: =X293 -> ALL | AK293: =AVERAGE(AK3:AK290) -> 0.78288923 | AL293: =AVERAGE(AL3:AL290) -> 0.26982183 | AM293: =AVERAGE(AM3:AM290) -> 0.26474568 | AN293: =AVERAGE(AN3:AN290) -> 0.94668167 | AO293: =AVERAGE(AO3:AO290) -> 0.18990318 | AP293: =AVERAGE(AP3:AP290) -> 0.89846014 | AQ293: =AVERAGE(AQ3:AQ290) -> 0.22499563 | AR293: =AVERAGE(AR3:AR290) -> 0.38422142 | ... AU293: =AVERAGE(AU3:AU290) -> 1.0474587
L294: ="Target; Gain > "&L292 -> Target; Gain > 0.6 | M294: =AVERAGEIF($AZ3:$AZ290,">"&$X292,M3:M290) -> 685346.9 | N294: =AVERAGEIF($AZ3:$AZ290,">"&$X292,N3:N290) -> 480107.7 | O294: =AVERAGEIF($AZ3:$AZ290,">"&$X292,O3:O290) -> 485880.7 | P294: =AVERAGEIF($AZ3:$AZ290,">"&$X292,P3:P290) -> 1346578.3 | Q294: =AVERAGEIF($AZ3:$AZ290,">"&$X292,Q3:Q290) -> 208301.2 | R294: =AVERAGEIF($AZ3:$AZ290,">"&$X292,R3:R290) -> 1135925.3 | S294: =AVERAGEIF($AZ3:$AZ290,">"&$X292,S3:S290) -> 270708.2 | T294: =AVERAGEIF($AZ3:$AZ290,">"&$X292,T3:T290) -> 1773110.8 | ... W294: =AVERAGEIF($AZ3:$AZ290,">"&$X292,W3:W290) -> 515448.8 | X294: ="Target; Gain > "&X292 -> Target; Gain > 0.6 | Y294: =AVERAGEIF($AZ3:$AZ290,">"&$X292,Y3:Y290) -> 0.6387409 | Z294: =AVERAGEIF($AZ3:$AZ290,">"&$X292,Z3:Z290) -> 0.48132225 | AA294: =AVERAGEIF($AZ3:$AZ290,">"&$X292,AA3:AA290) -> 0.45052002 | AB294: =AVERAGEIF($AZ3:$AZ290,">"&$X292,AB3:AB290) -> 0.70820817 | AC294: =AVERAGEIF($AZ3:$AZ290,">"&$X292,AC3:AC290) -> 0.30266795 | AD294: =AVERAGEIF($AZ3:$AZ290,">"&$X292,AD3:AD290) -> 0.89626822 | AE294: =AVERAGEIF($AZ3:$AZ290,">"&$X292,AE3:AE290) -> 0.35417583 | AF294: =AVERAGEIF($AZ3:$AZ290,">"&$X292,AF3:AF290) -> 1.2212485 | ... AI294: =AVERAGEIF($AZ3:$AZ290,">"&$X292,AI3:AI290) -> 0.82691584 | AJ294: =X294 -> Target; Gain > 0.6 | AK294: =AVERAGEIF($AZ3:$AZ290,">"&$X292,AK3:AK290) -> 0.6387409 | AL294: =AVERAGEIF($AZ3:$AZ290,">"&$X292,AL3:AL290) -> 0.199286 | AM294: =AVERAGEIF($AZ3:$AZ290,">"&$X292,AM3:AM290) -> 0.17337059 | AN294: =AVERAGEIF($AZ3:$AZ290,">"&$X292,AN3:AN290) -> 0.70820817 | AO294: =AVERAGEIF($AZ3:$AZ290,">"&$X292,AO3:AO290) -> 0.14006037 | AP294: =AVERAGEIF($AZ3:$AZ290,">"&$X292,AP3:AP290) -> 0.89626822 | AQ294: =AVERAGEIF($AZ3:$AZ290,">"&$X292,AQ3:AQ290) -> 0.15709297 | AR294: =AVERAGEIF($AZ3:$AZ290,">"&$X292,AR3:AR290) -> 0.65659052 | ... AU294: =AVERAGEIF($AZ3:$AZ290,">"&$X292,AU3:AU290) -> 0.52360208
L295: ="Gain > "&L292 -> Gain > 0.6 | M295: =AVERAGEIF($AY3:$AY290,">"&$X292,M3:M290) -> 685346.9 | N295: =AVERAGEIF($AY3:$AY290,">"&$X292,N3:N290) -> 480107.7 | O295: =AVERAGEIF($AY3:$AY290,">"&$X292,O3:O290) -> 485880.7 | P295: =AVERAGEIF($AY3:$AY290,">"&$X292,P3:P290) -> 1346578.3 | Q295: =AVERAGEIF($AY3:$AY290,">"&$X292,Q3:Q290) -> 208301.2 | R295: =AVERAGEIF($AY3:$AY290,">"&$X292,R3:R290) -> 1135925.3 | S295: =AVERAGEIF($AY3:$AY290,">"&$X292,S3:S290) -> 270708.2 | T295: =AVERAGEIF($AY3:$AY290,">"&$X292,T3:T290) -> 1773110.8 | ... W295: =AVERAGEIF($AY3:$AY290,">"&$X292,W3:W290) -> 515448.8 | X295: ="Gain > "&X292 -> Gain > 0.6 | Y295: =AVERAGEIF($AY3:$AY290,">"&$X292,Y3:Y290) -> 0.6387409 | Z295: =AVERAGEIF($AY3:$AY290,">"&$X292,Z3:Z290) -> 0.48132225 | AA295: =AVERAGEIF($AY3:$AY290,">"&$X292,AA3:AA290) -> 0.45052002 | AB295: =AVERAGEIF($AY3:$AY290,">"&$X292,AB3:AB290) -> 0.70820817 | AC295: =AVERAGEIF($AY3:$AY290,">"&$X292,AC3:AC290) -> 0.30266795 | AD295: =AVERAGEIF($AY3:$AY290,">"&$X292,AD3:AD290) -> 0.89626822 | AE295: =AVERAGEIF($AY3:$AY290,">"&$X292,AE3:AE290) -> 0.35417583 | AF295: =AVERAGEIF($AY3:$AY290,">"&$X292,AF3:AF290) -> 1.2212485 | ... AI295: =AVERAGEIF($AY3:$AY290,">"&$X292,AI3:AI290) -> 0.82691584 | AJ295: =X295 -> Gain > 0.6 | AK295: =AVERAGEIF($AY3:$AY290,">"&$X292,AK3:AK290) -> 0.6387409 | AL295: =AVERAGEIF($AY3:$AY290,">"&$X292,AL3:AL290) -> 0.199286 | AM295: =AVERAGEIF($AY3:$AY290,">"&$X292,AM3:AM290) -> 0.17337059 | AN295: =AVERAGEIF($AY3:$AY290,">"&$X292,AN3:AN290) -> 0.70820817 | AO295: =AVERAGEIF($AY3:$AY290,">"&$X292,AO3:AO290) -> 0.14006037 | AP295: =AVERAGEIF($AY3:$AY290,">"&$X292,AP3:AP290) -> 0.89626822 | AQ295: =AVERAGEIF($AY3:$AY290,">"&$X292,AQ3:AQ290) -> 0.15709297 | AR295: =AVERAGEIF($AY3:$AY290,">"&$X292,AR3:AR290) -> 0.65659052 | ... AU295: =AVERAGEIF($AY3:$AY290,">"&$X292,AU3:AU290) -> 0.52360208
L296: Target | M296: =AVERAGEIF($H3:$H290,"=1",M3:M290) -> 425377.96 | N296: =AVERAGEIF($H3:$H290,"=1",N3:N290) -> 391017.57 | O296: =AVERAGEIF($H3:$H290,"=1",O3:O290) -> 395022.63 | P296: =AVERAGEIF($H3:$H290,"=1",P3:P290) -> 524906.84 | Q296: =AVERAGEIF($H3:$H290,"=1",Q3:Q290) -> 169387.12 | R296: =AVERAGEIF($H3:$H290,"=1",R3:R290) -> 419415.22 | S296: =AVERAGEIF($H3:$H290,"=1",S3:S290) -> 169136.25 | T296: =AVERAGEIF($H3:$H290,"=1",T3:T290) -> 1107860.6 | ... W296: =AVERAGEIF($H3:$H290,"=1",W3:W290) -> 333296.43 | X296: Target | Y296: =AVERAGEIF($H3:$H290,"=1",Y3:Y290) -> 0.42943907 | Z296: =AVERAGEIF($H3:$H290,"=1",Z3:Z290) -> 0.40453604 | AA296: =AVERAGEIF($H3:$H290,"=1",AA3:AA290) -> 0.39076161 | AB296: =AVERAGEIF($H3:$H290,"=1",AB3:AB290) -> 0.48178629 | AC296: =AVERAGEIF($H3:$H290,"=1",AC3:AC290) -> 0.27137128 | AD296: =AVERAGEIF($H3:$H290,"=1",AD3:AD290) -> 0.48775923 | AE296: =AVERAGEIF($H3:$H290,"=1",AE3:AE290) -> 0.3257159 | AF296: =AVERAGEIF($H3:$H290,"=1",AF3:AF290) -> 0.65561214 | ... AI296: =AVERAGEIF($H3:$H290,"=1",AI3:AI290) -> 0.75205511 | AJ296: =X296 -> Target | AK296: =AVERAGEIF($H3:$H290,"=1",AK3:AK290) -> 0.42943907 | AL296: =AVERAGEIF($H3:$H290,"=1",AL3:AL290) -> 0.15407663 | AM296: =AVERAGEIF($H3:$H290,"=1",AM3:AM290) -> 0.14169897 | AN296: =AVERAGEIF($H3:$H290,"=1",AN3:AN290) -> 0.48178629 | AO296: =AVERAGEIF($H3:$H290,"=1",AO3:AO290) -> 0.11492757 | AP296: =AVERAGEIF($H3:$H290,"=1",AP3:AP290) -> 0.48775923 | AQ296: =AVERAGEIF($H3:$H290,"=1",AQ3:AQ290) -> 0.12758825 | AR296: =AVERAGEIF($H3:$H290,"=1",AR3:AR290) -> 0.35545763 | ... AU296: =AVERAGEIF($H3:$H290,"=1",AU3:AU290) -> 0.50314838
L297: =X297 -> Gain > 0 | M297: =AVERAGEIF($J3:$J290,"=1",M3:M290) -> 767736.74 | N297: =AVERAGEIF($J3:$J290,"=1",N3:N290) -> 714441.96 | O297: =AVERAGEIF($J3:$J290,"=1",O3:O290) -> 723387.44 | P297: =AVERAGEIF($J3:$J290,"=1",P3:P290) -> 887824.38 | Q297: =AVERAGEIF($J3:$J290,"=1",Q3:Q290) -> 340934.13 | R297: =AVERAGEIF($J3:$J290,"=1",R3:R290) -> 721952.97 | S297: =AVERAGEIF($J3:$J290,"=1",S3:S290) -> 369673.02 | T297: =AVERAGEIF($J3:$J290,"=1",T3:T290) -> 1171617 | ... W297: =AVERAGEIF($J3:$J290,"=1",W3:W290) -> 571921.94 | X297: Gain > 0 | Y297: =AVERAGEIF($J3:$J290,"=1",Y3:Y290) -> 0.68216796 | Z297: =AVERAGEIF($J3:$J290,"=1",Z3:Z290) -> 0.6250495 | AA297: =AVERAGEIF($J3:$J290,"=1",AA3:AA290) -> 0.61800298 | AB297: =AVERAGEIF($J3:$J290,"=1",AB3:AB290) -> 0.75096589 | AC297: =AVERAGEIF($J3:$J290,"=1",AC3:AC290) -> 0.39841302 | AD297: =AVERAGEIF($J3:$J290,"=1",AD3:AD290) -> 0.80986517 | AE297: =AVERAGEIF($J3:$J290,"=1",AE3:AE290) -> 0.52971711 | AF297: =AVERAGEIF($J3:$J290,"=1",AF3:AF290) -> 0.72945996 | ... AI297: =AVERAGEIF($J3:$J290,"=1",AI3:AI290) -> 1.1469417 | AJ297: =X297 -> Gain > 0 | AK297: =AVERAGEIF($J3:$J290,"=1",AK3:AK290) -> 0.68216796 | AL297: =AVERAGEIF($J3:$J290,"=1",AL3:AL290) -> 0.23170105 | AM297: =AVERAGEIF($J3:$J290,"=1",AM3:AM290) -> 0.22630951 | AN297: =AVERAGEIF($J3:$J290,"=1",AN3:AN290) -> 0.75096589 | AO297: =AVERAGEIF($J3:$J290,"=1",AO3:AO290) -> 0.16138868 | AP297: =AVERAGEIF($J3:$J290,"=1",AP3:AP290) -> 0.80986517 | AQ297: =AVERAGEIF($J3:$J290,"=1",AQ3:AQ290) -> 0.19048218 | AR297: =AVERAGEIF($J3:$J290,"=1",AR3:AR290) -> 0.39095467 | ... AU297: =AVERAGEIF($J3:$J290,"=1",AU3:AU290) -> 0.83884343
L298: =X298 -> Gain <=0 | M298: =AVERAGEIF($I3:$I290,"=1",M3:M290) -> 1071662.8 | N298: =AVERAGEIF($I3:$I290,"=1",N3:N290) -> 1063938.8 | O298: =AVERAGEIF($I3:$I290,"=1",O3:O290) -> 1076467.9 | P298: =AVERAGEIF($I3:$I290,"=1",P3:P290) -> 1248735.4 | Q298: =AVERAGEIF($I3:$I290,"=1",Q3:Q290) -> 533473.68 | R298: =AVERAGEIF($I3:$I290,"=1",R3:R290) -> 1129550.5 | S298: =AVERAGEIF($I3:$I290,"=1",S3:S290) -> 692955.85 | T298: =AVERAGEIF($I3:$I290,"=1",T3:T290) -> 1139045.1 | ... W298: =AVERAGEIF($I3:$I290,"=1",W3:W290) -> 1002711.9 | X298: Gain <=0 | Y298: =AVERAGEIF($I3:$I290,"=1",Y3:Y290) -> 0.87018099 | Z298: =AVERAGEIF($I3:$I290,"=1",Z3:Z290) -> 0.83458487 | AA298: =AVERAGEIF($I3:$I290,"=1",AA3:AA290) -> 0.82808682 | AB298: =AVERAGEIF($I3:$I290,"=1",AB3:AB290) -> 1.116302 | AC298: =AVERAGEIF($I3:$I290,"=1",AC3:AC290) -> 0.54951537 | AD298: =AVERAGEIF($I3:$I290,"=1",AD3:AD290) -> 0.97524244 | AE298: =AVERAGEIF($I3:$I290,"=1",AE3:AE290) -> 0.72982218 | AF298: =AVERAGEIF($I3:$I290,"=1",AF3:AF290) -> 0.68814897 | ... AI298: =AVERAGEIF($I3:$I290,"=1",AI3:AI290) -> 1.6411127 | AJ298: =X298 -> Gain <=0 | AK298: =AVERAGEIF($I3:$I290,"=1",AK3:AK290) -> 0.87018099 | AL298: =AVERAGEIF($I3:$I290,"=1",AL3:AL290) -> 0.30285984 | AM298: =AVERAGEIF($I3:$I290,"=1",AM3:AM290) -> 0.29805703 | AN298: =AVERAGEIF($I3:$I290,"=1",AN3:AN290) -> 1.116302 | AO298: =AVERAGEIF($I3:$I290,"=1",AO3:AO290) -> 0.21461575 | AP298: =AVERAGEIF($I3:$I290,"=1",AP3:AP290) -> 0.97524244 | AQ298: =AVERAGEIF($I3:$I290,"=1",AQ3:AQ290) -> 0.25490729 | AR298: =AVERAGEIF($I3:$I290,"=1",AR3:AR290) -> 0.37838593 | ... AU298: =AVERAGEIF($I3:$I290,"=1",AU3:AU290) -> 1.2282585
L299: =X299 -> Target;Gain > 0.6; #pref=2 | M299: =AVERAGEIFS(M3:M290, $H$3:$H$290, "=1",$K3:$K290,"=2",$AY3:$AY290,">"&$X$292) -> #DIV/0! | N299: =AVERAGEIFS(N3:N290, $H$3:$H$290, "=1",$K3:$K290,"=2",$AY3:$AY290,">"&$X$292) -> #DIV/0! | O299: =AVERAGEIFS(O3:O290, $H$3:$H$290, "=1",$K3:$K290,"=2",$AY3:$AY290,">"&$X$292) -> #DIV/0! | P299: =AVERAGEIFS(P3:P290, $H$3:$H$290, "=1",$K3:$K290,"=2",$AY3:$AY290,">"&$X$292) -> #DIV/0! | Q299: =AVERAGEIFS(Q3:Q290, $H$3:$H$290, "=1",$K3:$K290,"=2",$AY3:$AY290,">"&$X$292) -> #DIV/0! | R299: =AVERAGEIFS(R3:R290, $H$3:$H$290, "=1",$K3:$K290,"=2",$AY3:$AY290,">"&$X$292) -> #DIV/0! | S299: =AVERAGEIFS(S3:S290, $H$3:$H$290, "=1",$K3:$K290,"=2",$AY3:$AY290,">"&$X$292) -> #DIV/0! | T299: =AVERAGEIFS(T3:T290, $H$3:$H$290, "=1",$K3:$K290,"=2",$AY3:$AY290,">"&$X$292) -> #DIV/0! | ... W299: =AVERAGEIFS(W3:W290, $H$3:$H$290, "=1",$K3:$K290,"=2",$AY3:$AY290,">"&$X$292) -> #DIV/0! | X299: ="Target;Gain > "&X292&"; #pref=2" -> Target;Gain > 0.6; #pref=2 | Y299: =AVERAGEIFS(Y3:Y290, $H$3:$H$290, "=1",$K3:$K290,"=2",$AY3:$AY290,">"&$X$292) -> #DIV/0! | Z299: =AVERAGEIFS(Z3:Z290, $H$3:$H$290, "=1",$K3:$K290,"=2",$AY3:$AY290,">"&$X$292) -> #DIV/0! | AA299: =AVERAGEIFS(AA3:AA290, $H$3:$H$290, "=1",$K3:$K290,"=2",$AY3:$AY290,">"&$X$292) -> #DIV/0! | AB299: =AVERAGEIFS(AB3:AB290, $H$3:$H$290, "=1",$K3:$K290,"=2",$AY3:$AY290,">"&$X$292) -> #DIV/0! | AC299: =AVERAGEIFS(AC3:AC290, $H$3:$H$290, "=1",$K3:$K290,"=2",$AY3:$AY290,">"&$X$292) -> #DIV/0! | AD299: =AVERAGEIFS(AD3:AD290, $H$3:$H$290, "=1",$K3:$K290,"=2",$AY3:$AY290,">"&$X$292) -> #DIV/0! | AE299: =AVERAGEIFS(AE3:AE290, $H$3:$H$290, "=1",$K3:$K290,"=2",$AY3:$AY290,">"&$X$292) -> #DIV/0! | AF299: =AVERAGEIFS(AF3:AF290, $H$3:$H$290, "=1",$K3:$K290,"=2",$AY3:$AY290,">"&$X$292) -> #DIV/0! | ... AI299: =AVERAGEIFS(AI3:AI290, $H$3:$H$290, "=1",$K3:$K290,"=2",$AY3:$AY290,">"&$X$292) -> #DIV/0! | AJ299: =X299 -> Target;Gain > 0.6; #pref=2 | AK299: =AVERAGEIFS(AK3:AK290, $H$3:$H$290, "=1",$K3:$K290,"=2",$AY3:$AY290,">"&$X$292) -> #DIV/0! | AL299: =AVERAGEIFS(AL3:AL290, $H$3:$H$290, "=1",$K3:$K290,"=2",$AY3:$AY290,">"&$X$292) -> #DIV/0! | AM299: =AVERAGEIFS(AM3:AM290, $H$3:$H$290, "=1",$K3:$K290,"=2",$AY3:$AY290,">"&$X$292) -> #DIV/0! | AN299: =AVERAGEIFS(AN3:AN290, $H$3:$H$290, "=1",$K3:$K290,"=2",$AY3:$AY290,">"&$X$292) -> #DIV/0! | AO299: =AVERAGEIFS(AO3:AO290, $H$3:$H$290, "=1",$K3:$K290,"=2",$AY3:$AY290,">"&$X$292) -> #DIV/0! | AP299: =AVERAGEIFS(AP3:AP290, $H$3:$H$290, "=1",$K3:$K290,"=2",$AY3:$AY290,">"&$X$292) -> #DIV/0! | AQ299: =AVERAGEIFS(AQ3:AQ290, $H$3:$H$290, "=1",$K3:$K290,"=2",$AY3:$AY290,">"&$X$292) -> #DIV/0! | AR299: =AVERAGEIFS(AR3:AR290, $H$3:$H$290, "=1",$K3:$K290,"=2",$AY3:$AY290,">"&$X$292) -> #DIV/0! | ... AU299: =AVERAGEIFS(AU3:AU290, $H$3:$H$290, "=1",$K3:$K290,"=2",$AY3:$AY290,">"&$X$292) -> #DIV/0!
L300: =X300 -> Target; Gain > 0.6; #pref=3 | M300: =AVERAGEIFS(M3:M290, $H$3:$H$290, "=1",$K3:$K290,"=3",$AY3:$AY290,">"&$X$292) -> 685346.9 | N300: =AVERAGEIFS(N3:N290, $H$3:$H$290, "=1",$K3:$K290,"=3",$AY3:$AY290,">"&$X$292) -> 480107.7 | O300: =AVERAGEIFS(O3:O290, $H$3:$H$290, "=1",$K3:$K290,"=3",$AY3:$AY290,">"&$X$292) -> 485880.7 | P300: =AVERAGEIFS(P3:P290, $H$3:$H$290, "=1",$K3:$K290,"=3",$AY3:$AY290,">"&$X$292) -> 1346578.3 | Q300: =AVERAGEIFS(Q3:Q290, $H$3:$H$290, "=1",$K3:$K290,"=3",$AY3:$AY290,">"&$X$292) -> 208301.2 | R300: =AVERAGEIFS(R3:R290, $H$3:$H$290, "=1",$K3:$K290,"=3",$AY3:$AY290,">"&$X$292) -> 1135925.3 | S300: =AVERAGEIFS(S3:S290, $H$3:$H$290, "=1",$K3:$K290,"=3",$AY3:$AY290,">"&$X$292) -> 270708.2 | T300: =AVERAGEIFS(T3:T290, $H$3:$H$290, "=1",$K3:$K290,"=3",$AY3:$AY290,">"&$X$292) -> 1773110.8 | ... W300: =AVERAGEIFS(W3:W290, $H$3:$H$290, "=1",$K3:$K290,"=3",$AY3:$AY290,">"&$X$292) -> 515448.8 | X300: ="Target; Gain > "&X292&"; #pref=3" -> Target; Gain > 0.6; #pref=3 | Y300: =AVERAGEIFS(Y3:Y290, $H$3:$H$290, "=1",$K3:$K290,"=3",$AY3:$AY290,">"&$X$292) -> 0.6387409 | Z300: =AVERAGEIFS(Z3:Z290, $H$3:$H$290, "=1",$K3:$K290,"=3",$AY3:$AY290,">"&$X$292) -> 0.48132225 | AA300: =AVERAGEIFS(AA3:AA290, $H$3:$H$290, "=1",$K3:$K290,"=3",$AY3:$AY290,">"&$X$292) -> 0.45052002 | AB300: =AVERAGEIFS(AB3:AB290, $H$3:$H$290, "=1",$K3:$K290,"=3",$AY3:$AY290,">"&$X$292) -> 0.70820817 | AC300: =AVERAGEIFS(AC3:AC290, $H$3:$H$290, "=1",$K3:$K290,"=3",$AY3:$AY290,">"&$X$292) -> 0.30266795 | AD300: =AVERAGEIFS(AD3:AD290, $H$3:$H$290, "=1",$K3:$K290,"=3",$AY3:$AY290,">"&$X$292) -> 0.89626822 | AE300: =AVERAGEIFS(AE3:AE290, $H$3:$H$290, "=1",$K3:$K290,"=3",$AY3:$AY290,">"&$X$292) -> 0.35417583 | AF300: =AVERAGEIFS(AF3:AF290, $H$3:$H$290, "=1",$K3:$K290,"=3",$AY3:$AY290,">"&$X$292) -> 1.2212485 | ... AI300: =AVERAGEIFS(AI3:AI290, $H$3:$H$290, "=1",$K3:$K290,"=3",$AY3:$AY290,">"&$X$292) -> 0.82691584 | AJ300: =X300 -> Target; Gain > 0.6; #pref=3 | AK300: =AVERAGEIFS(AK3:AK290, $H$3:$H$290, "=1",$K3:$K290,"=3",$AY3:$AY290,">"&$X$292) -> 0.6387409 | AL300: =AVERAGEIFS(AL3:AL290, $H$3:$H$290, "=1",$K3:$K290,"=3",$AY3:$AY290,">"&$X$292) -> 0.199286 | AM300: =AVERAGEIFS(AM3:AM290, $H$3:$H$290, "=1",$K3:$K290,"=3",$AY3:$AY290,">"&$X$292) -> 0.17337059 | AN300: =AVERAGEIFS(AN3:AN290, $H$3:$H$290, "=1",$K3:$K290,"=3",$AY3:$AY290,">"&$X$292) -> 0.70820817 | AO300: =AVERAGEIFS(AO3:AO290, $H$3:$H$290, "=1",$K3:$K290,"=3",$AY3:$AY290,">"&$X$292) -> 0.14006037 | AP300: =AVERAGEIFS(AP3:AP290, $H$3:$H$290, "=1",$K3:$K290,"=3",$AY3:$AY290,">"&$X$292) -> 0.89626822 | AQ300: =AVERAGEIFS(AQ3:AQ290, $H$3:$H$290, "=1",$K3:$K290,"=3",$AY3:$AY290,">"&$X$292) -> 0.15709297 | AR300: =AVERAGEIFS(AR3:AR290, $H$3:$H$290, "=1",$K3:$K290,"=3",$AY3:$AY290,">"&$X$292) -> 0.65659052 | ... AU300: =AVERAGEIFS(AU3:AU290, $H$3:$H$290, "=1",$K3:$K290,"=3",$AY3:$AY290,">"&$X$292) -> 0.52360208
L301: =X301 -> Target; Gain > 0.6; #pref=4 | M301: =AVERAGEIFS(M3:M290, $H$3:$H$290, "=1",$K3:$K290,"=4",$AY3:$AY290,">"&$X$292) -> #DIV/0! | N301: =AVERAGEIFS(N3:N290, $H$3:$H$290, "=1",$K3:$K290,"=4",$AY3:$AY290,">"&$X$292) -> #DIV/0! | O301: =AVERAGEIFS(O3:O290, $H$3:$H$290, "=1",$K3:$K290,"=4",$AY3:$AY290,">"&$X$292) -> #DIV/0! | P301: =AVERAGEIFS(P3:P290, $H$3:$H$290, "=1",$K3:$K290,"=4",$AY3:$AY290,">"&$X$292) -> #DIV/0! | Q301: =AVERAGEIFS(Q3:Q290, $H$3:$H$290, "=1",$K3:$K290,"=4",$AY3:$AY290,">"&$X$292) -> #DIV/0! | R301: =AVERAGEIFS(R3:R290, $H$3:$H$290, "=1",$K3:$K290,"=4",$AY3:$AY290,">"&$X$292) -> #DIV/0! | S301: =AVERAGEIFS(S3:S290, $H$3:$H$290, "=1",$K3:$K290,"=4",$AY3:$AY290,">"&$X$292) -> #DIV/0! | T301: =AVERAGEIFS(T3:T290, $H$3:$H$290, "=1",$K3:$K290,"=4",$AY3:$AY290,">"&$X$292) -> #DIV/0! | ... W301: =AVERAGEIFS(W3:W290, $H$3:$H$290, "=1",$K3:$K290,"=4",$AY3:$AY290,">"&$X$292) -> #DIV/0! | X301: ="Target; Gain > "&X292&"; #pref=4" -> Target; Gain > 0.6; #pref=4 | Y301: =AVERAGEIFS(Y3:Y290, $H$3:$H$290, "=1",$K3:$K290,"=4",$AY3:$AY290,">"&$X$292) -> #DIV/0! | Z301: =AVERAGEIFS(Z3:Z290, $H$3:$H$290, "=1",$K3:$K290,"=4",$AY3:$AY290,">"&$X$292) -> #DIV/0! | AA301: =AVERAGEIFS(AA3:AA290, $H$3:$H$290, "=1",$K3:$K290,"=4",$AY3:$AY290,">"&$X$292) -> #DIV/0! | AB301: =AVERAGEIFS(AB3:AB290, $H$3:$H$290, "=1",$K3:$K290,"=4",$AY3:$AY290,">"&$X$292) -> #DIV/0! | AC301: =AVERAGEIFS(AC3:AC290, $H$3:$H$290, "=1",$K3:$K290,"=4",$AY3:$AY290,">"&$X$292) -> #DIV/0! | AD301: =AVERAGEIFS(AD3:AD290, $H$3:$H$290, "=1",$K3:$K290,"=4",$AY3:$AY290,">"&$X$292) -> #DIV/0! | AE301: =AVERAGEIFS(AE3:AE290, $H$3:$H$290, "=1",$K3:$K290,"=4",$AY3:$AY290,">"&$X$292) -> #DIV/0! | AF301: =AVERAGEIFS(AF3:AF290, $H$3:$H$290, "=1",$K3:$K290,"=4",$AY3:$AY290,">"&$X$292) -> #DIV/0! | ... AI301: =AVERAGEIFS(AI3:AI290, $H$3:$H$290, "=1",$K3:$K290,"=4",$AY3:$AY290,">"&$X$292) -> #DIV/0! | AJ301: =X301 -> Target; Gain > 0.6; #pref=4 | AK301: =AVERAGEIFS(AK3:AK290, $H$3:$H$290, "=1",$K3:$K290,"=4",$AY3:$AY290,">"&$X$292) -> #DIV/0! | AL301: =AVERAGEIFS(AL3:AL290, $H$3:$H$290, "=1",$K3:$K290,"=4",$AY3:$AY290,">"&$X$292) -> #DIV/0! | AM301: =AVERAGEIFS(AM3:AM290, $H$3:$H$290, "=1",$K3:$K290,"=4",$AY3:$AY290,">"&$X$292) -> #DIV/0! | AN301: =AVERAGEIFS(AN3:AN290, $H$3:$H$290, "=1",$K3:$K290,"=4",$AY3:$AY290,">"&$X$292) -> #DIV/0! | AO301: =AVERAGEIFS(AO3:AO290, $H$3:$H$290, "=1",$K3:$K290,"=4",$AY3:$AY290,">"&$X$292) -> #DIV/0! | AP301: =AVERAGEIFS(AP3:AP290, $H$3:$H$290, "=1",$K3:$K290,"=4",$AY3:$AY290,">"&$X$292) -> #DIV/0! | AQ301: =AVERAGEIFS(AQ3:AQ290, $H$3:$H$290, "=1",$K3:$K290,"=4",$AY3:$AY290,">"&$X$292) -> #DIV/0! | AR301: =AVERAGEIFS(AR3:AR290, $H$3:$H$290, "=1",$K3:$K290,"=4",$AY3:$AY290,">"&$X$292) -> #DIV/0! | ... AU301: =AVERAGEIFS(AU3:AU290, $H$3:$H$290, "=1",$K3:$K290,"=4",$AY3:$AY290,">"&$X$292) -> #DIV/0!
L302: =X302 -> Target; Gain > 0 | M302: =AVERAGEIFS(M3:M290,$H3:$H290,"=1",$J3:$J290,"=1") -> 481471.03 | N302: =AVERAGEIFS(N3:N290,$H3:$H290,"=1",$J3:$J290,"=1") -> 360082.81 | O302: =AVERAGEIFS(O3:O290,$H3:$H290,"=1",$J3:$J290,"=1") -> 364372.56 | P302: =AVERAGEIFS(P3:P290,$H3:$H290,"=1",$J3:$J290,"=1") -> 604226.65 | Q302: =AVERAGEIFS(Q3:Q290,$H3:$H290,"=1",$J3:$J290,"=1") -> 161546.42 | R302: =AVERAGEIFS(R3:R290,$H3:$H290,"=1",$J3:$J290,"=1") -> 487500.95 | S302: =AVERAGEIFS(S3:S290,$H3:$H290,"=1",$J3:$J290,"=1") -> 150024.96 | T302: =AVERAGEIFS(T3:T290,$H3:$H290,"=1",$J3:$J290,"=1") -> 1164279.1 | ... W302: =AVERAGEIFS(W3:W290,$H3:$H290,"=1",$J3:$J290,"=1") -> 326232.56 | X302: Target; Gain > 0 | Y302: =AVERAGEIFS(Y3:Y290,$H3:$H290,"=1",$J3:$J290,"=1") -> 0.47739559 | Z302: =AVERAGEIFS(Z3:Z290,$H3:$H290,"=1",$J3:$J290,"=1") -> 0.39620235 | AA302: =AVERAGEIFS(AA3:AA290,$H3:$H290,"=1",$J3:$J290,"=1") -> 0.38026575 | AB302: =AVERAGEIFS(AB3:AB290,$H3:$H290,"=1",$J3:$J290,"=1") -> 0.53295429 | AC302: =AVERAGEIFS(AC3:AC290,$H3:$H290,"=1",$J3:$J290,"=1") -> 0.26648288 | AD302: =AVERAGEIFS(AD3:AD290,$H3:$H290,"=1",$J3:$J290,"=1") -> 0.53747418 | AE302: =AVERAGEIFS(AE3:AE290,$H3:$H290,"=1",$J3:$J290,"=1") -> 0.29644202 | AF302: =AVERAGEIFS(AF3:AF290,$H3:$H290,"=1",$J3:$J290,"=1") -> 0.72778816 | ... AI302: =AVERAGEIFS(AI3:AI290,$H3:$H290,"=1",$J3:$J290,"=1") -> 0.70481378 | AJ302: =X302 -> Target; Gain > 0 | AK302: =AVERAGEIFS(AK3:AK290,$H3:$H290,"=1",$J3:$J290,"=1") -> 0.47739559 | AL302: =AVERAGEIFS(AL3:AL290,$H3:$H290,"=1",$J3:$J290,"=1") -> 0.16044057 | AM302: =AVERAGEIFS(AM3:AM290,$H3:$H290,"=1",$J3:$J290,"=1") -> 0.14649748 | AN302: =AVERAGEIFS(AN3:AN290,$H3:$H290,"=1",$J3:$J290,"=1") -> 0.53295429 | AO302: =AVERAGEIFS(AO3:AO290,$H3:$H290,"=1",$J3:$J290,"=1") -> 0.11898458 | AP302: =AVERAGEIFS(AP3:AP290,$H3:$H290,"=1",$J3:$J290,"=1") -> 0.53747418 | AQ302: =AVERAGEIFS(AQ3:AQ290,$H3:$H290,"=1",$J3:$J290,"=1") -> 0.12789843 | AR302: =AVERAGEIFS(AR3:AR290,$H3:$H290,"=1",$J3:$J290,"=1") -> 0.38701458 | ... AU302: =AVERAGEIFS(AU3:AU290,$H3:$H290,"=1",$J3:$J290,"=1") -> 0.46643011
L303: =L292 -> 0.6 | N303: =N292 -> BNL Causal | O303: =O292 -> BNL Causal HM | P303: =Q292 -> SFS Causal | Q303: =S292 -> SaLSa Causal | R303: =U292 -> D&C Causal | S303: =W292 -> BBS Causal | U303: =X292 -> 0.6 | V303: =Z292 -> BNL Causal | W303: =AA292 -> BNL Causal HM | X303: =AC292 -> SFS Causal | Y303: =AE292 -> SaLSa Causal | Z303: =AG292 -> D&C Causal | AA303: =AI292 -> BBS Causal | AC303: =AJ292 -> 0.6 | AD303: =AL292 -> BNL Causal | AE303: =AM292 -> BNL Causal HM | AF303: =AO292 -> SFS Causal | AG303: =AQ292 -> SaLSa Causal | AH303: =AS292 -> D&C Causal | AI303: =AU292 -> BBS Causal
L304: =L293 -> ALL | N304: =N293 -> 901672.42 | O304: =O293 -> 912537.68 | P304: =Q293 -> 444080.32 | Q304: =S293 -> 542860.25 | R304: =U293 -> 966820.98 | S304: =W293 -> 802702.26 | U304: =X293 -> ALL | V304: =Z293 -> 0.73730059 | W304: =AA293 -> 0.73054789 | X304: =AC293 -> 0.47936071 | Y304: =AE293 -> 0.63691626 | Z304: =AG293 -> 0.75750508 | AA304: =AI293 -> 1.4116762 | AC304: =AJ293 -> ALL | AD304: =AL293 -> 0.26982183 | AE304: =AM293 -> 0.26474568 | AF304: =AO293 -> 0.18990318 | AG304: =AQ293 -> 0.22499563 | AH304: =AS293 -> 0.1435604 | AI304: =AU293 -> 1.0474587
L305: =L295 -> Gain > 0.6 | N305: =N295 -> 480107.7 | O305: =O295 -> 485880.7 | P305: =Q295 -> 208301.2 | Q305: =S295 -> 270708.2 | R305: =U295 -> 1103627.6 | S305: =W295 -> 515448.8 | U305: =X295 -> Gain > 0.6 | V305: =Z295 -> 0.48132225 | W305: =AA295 -> 0.45052002 | X305: =AC295 -> 0.30266795 | Y305: =AE295 -> 0.35417583 | Z305: =AG295 -> 0.82885032 | AA305: =AI295 -> 0.82691584 | AC305: =AJ295 -> Gain > 0.6 | AD305: =AL295 -> 0.199286 | AE305: =AM295 -> 0.17337059 | AF305: =AO295 -> 0.14006037 | AG305: =AQ295 -> 0.15709297 | AH305: =AS295 -> 0.15150429 | AI305: =AU295 -> 0.52360208
L306: =L296 -> Target | N306: =N296 -> 391017.57 | O306: =O296 -> 395022.63 | P306: =Q296 -> 169387.12 | Q306: =S296 -> 169136.25 | R306: =U296 -> 878242.28 | S306: =W296 -> 333296.43 | U306: =X296 -> Target | V306: =Z296 -> 0.40453604 | W306: =AA296 -> 0.39076161 | X306: =AC296 -> 0.27137128 | Y306: =AE296 -> 0.3257159 | Z306: =AG296 -> 0.65379647 | AA306: =AI296 -> 0.75205511 | AC306: =AJ296 -> Target | AD306: =AL296 -> 0.15407663 | AE306: =AM296 -> 0.14169897 | AF306: =AO296 -> 0.11492757 | AG306: =AQ296 -> 0.12758825 | AH306: =AS296 -> 0.1232239 | AI306: =AU296 -> 0.50314838
L307: =L297 -> Gain > 0 | N307: =N297 -> 714441.96 | O307: =O297 -> 723387.44 | P307: =Q297 -> 340934.13 | Q307: =S297 -> 369673.02 | R307: =U297 -> 933075.47 | S307: =W297 -> 571921.94 | U307: =X297 -> Gain > 0 | V307: =Z297 -> 0.6250495 | W307: =AA297 -> 0.61800298 | X307: =AC297 -> 0.39841302 | Y307: =AE297 -> 0.52971711 | Z307: =AG297 -> 0.73636558 | AA307: =AI297 -> 1.1469417 | AC307: =AJ297 -> Gain > 0 | AD307: =AL297 -> 0.23170105 | AE307: =AM297 -> 0.22630951 | AF307: =AO297 -> 0.16138868 | AG307: =AQ297 -> 0.19048218 | AH307: =AS297 -> 0.13843962 | AI307: =AU297 -> 0.83884343
L308: =L298 -> Gain <=0 | N308: =N298 -> 1063938.8 | O308: =O298 -> 1076467.9 | P308: =Q298 -> 533473.68 | Q308: =S298 -> 692955.85 | R308: =U298 -> 996067.09 | S308: =W298 -> 1002711.9 | U308: =X298 -> Gain <=0 | V308: =Z298 -> 0.83458487 | W308: =AA298 -> 0.82808682 | X308: =AC298 -> 0.54951537 | Y308: =AE298 -> 0.72982218 | Z308: =AG298 -> 0.77582598 | AA308: =AI298 -> 1.6411127 | AC308: =AJ298 -> Gain <=0 | AD308: =AL298 -> 0.30285984 | AE308: =AM298 -> 0.29805703 | AF308: =AO298 -> 0.21461575 | AG308: =AQ298 -> 0.25490729 | AH308: =AS298 -> 0.14799841 | AI308: =AU298 -> 1.2282585
L309: =L299 -> Target;Gain > 0.6; #pref=2 | N309: =N299 -> #DIV/0! | O309: =O299 -> #DIV/0! | P309: =Q299 -> #DIV/0! | Q309: =S299 -> #DIV/0! | R309: =U299 -> #DIV/0! | S309: =W299 -> #DIV/0! | U309: =X299 -> Target;Gain > 0.6; #pref=2 | V309: =Z299 -> #DIV/0! | W309: =AA299 -> #DIV/0! | X309: =AC299 -> #DIV/0! | Y309: =AE299 -> #DIV/0! | Z309: =AG299 -> #DIV/0! | AA309: =AI299 -> #DIV/0! | AC309: =AJ299 -> Target;Gain > 0.6; #pref=2 | AD309: =AL299 -> #DIV/0! | AE309: =AM299 -> #DIV/0! | AF309: =AO299 -> #DIV/0! | AG309: =AQ299 -> #DIV/0! | AH309: =AS299 -> #DIV/0! | AI309: =AU299 -> #DIV/0!
L310: =L300 -> Target; Gain > 0.6; #pref=3 | N310: =N300 -> 480107.7 | O310: =O300 -> 485880.7 | P310: =Q300 -> 208301.2 | Q310: =S300 -> 270708.2 | R310: =U300 -> 1103627.6 | S310: =W300 -> 515448.8 | U310: =X300 -> Target; Gain > 0.6; #pref=3 | V310: =Z300 -> 0.48132225 | W310: =AA300 -> 0.45052002 | X310: =AC300 -> 0.30266795 | Y310: =AE300 -> 0.35417583 | Z310: =AG300 -> 0.82885032 | AA310: =AI300 -> 0.82691584 | AC310: =AJ300 -> Target; Gain > 0.6; #pref=3 | AD310: =AL300 -> 0.199286 | AE310: =AM300 -> 0.17337059 | AF310: =AO300 -> 0.14006037 | AG310: =AQ300 -> 0.15709297 | AH310: =AS300 -> 0.15150429 | AI310: =AU300 -> 0.52360208
L311: =L301 -> Target; Gain > 0.6; #pref=4 | N311: =N301 -> #DIV/0! | O311: =O301 -> #DIV/0! | P311: =Q301 -> #DIV/0! | Q311: =S301 -> #DIV/0! | R311: =U301 -> #DIV/0! | S311: =W301 -> #DIV/0! | U311: =X301 -> Target; Gain > 0.6; #pref=4 | V311: =Z301 -> #DIV/0! | W311: =AA301 -> #DIV/0! | X311: =AC301 -> #DIV/0! | Y311: =AE301 -> #DIV/0! | Z311: =AG301 -> #DIV/0! | AA311: =AI301 -> #DIV/0! | AC311: =AJ301 -> Target; Gain > 0.6; #pref=4 | AD311: =AL301 -> #DIV/0! | AE311: =AM301 -> #DIV/0! | AF311: =AO301 -> #DIV/0! | AG311: =AQ301 -> #DIV/0! | AH311: =AS301 -> #DIV/0! | AI311: =AU301 -> #DIV/0!
L312: =L302 -> Target; Gain > 0 | N312: =N302 -> 360082.81 | O312: =O302 -> 364372.56 | P312: =Q302 -> 161546.42 | Q312: =S302 -> 150024.96 | R312: =U302 -> 868141.07 | S312: =W302 -> 326232.56 | U312: =X302 -> Target; Gain > 0 | V312: =Z302 -> 0.39620235 | W312: =AA302 -> 0.38026575 | X312: =AC302 -> 0.26648288 | Y312: =AE302 -> 0.29644202 | Z312: =AG302 -> 0.64789767 | AA312: =AI302 -> 0.70481378 | AC312: =AJ302 -> Target; Gain > 0 | AD312: =AL302 -> 0.16044057 | AE312: =AM302 -> 0.14649748 | AF312: =AO302 -> 0.11898458 | AG312: =AQ302 -> 0.12789843 | AH312: =AS302 -> 0.12653661 | AI312: =AU302 -> 0.46643011
K314: Median | L314: =X314 -> 0.6 | M314: BNL | N314: BNL Causal | O314: BNL Causal HM | P314: SFS | Q314: SFS Causal | R314: SaLSa | S314: SaLSa Causal | T314: D&C | U314: D&C Causal | V314: BBS | W314: BBS Causal | X314: =X292 -> 0.6 | Y314: BNL | Z314: BNL Causal | AA314: BNL Causal HM | AB314: SFS | AC314: SFS Causal | AD314: SaLSa | AE314: SaLSa Causal | AF314: D&C | AG314: D&C Causal | AH314: BBS | AI314: BBS Causal | AJ314: =X314 -> 0.6 | AK314: BNL | AL314: BNL Causal | AM314: BNL Causal HM | AN314: SFS | AO314: SFS Causal | AP314: SaLSa | AQ314: SaLSa Causal | AR314: D&C | AS314: D&C Causal | AT314: BBS | AU314: BBS Causal
L315: ALL | M315: =MEDIAN(M3:M290) -> 610015.2 | N315: =MEDIAN(N3:N290) -> 590352.1 | O315: =MEDIAN(O3:O290) -> 598133.57 | P315: =MEDIAN(P3:P290) -> 493787.9 | Q315: =MEDIAN(Q3:Q290) -> 261375.3 | R315: =MEDIAN(R3:R290) -> 426271.4 | S315: =MEDIAN(S3:S290) -> 271616.5 | T315: =MEDIAN(T3:T290) -> 1062404.7 | ... W315: =MEDIAN(W3:W290) -> 504015.5 | X315: ALL | Y315: =MEDIAN(Y3:Y290) -> 0.57431507 | Z315: =MEDIAN(Z3:Z290) -> 0.54567668 | AA315: =MEDIAN(AA3:AA290) -> 0.53989833 | AB315: =MEDIAN(AB3:AB290) -> 0.5925273 | AC315: =MEDIAN(AC3:AC290) -> 0.33592681 | AD315: =MEDIAN(AD3:AD290) -> 0.64953233 | AE315: =MEDIAN(AE3:AE290) -> 0.48635925 | AF315: =MEDIAN(AF3:AF290) -> 0.5551391 | ... AI315: =MEDIAN(AI3:AI290) -> 1.0418998 | AJ315: =X315 -> ALL | AK315: =MEDIAN(AK3:AK290) -> 0.57431507 | AL315: =MEDIAN(AL3:AL290) -> 0.20173347 | AM315: =MEDIAN(AM3:AM290) -> 0.18895947 | AN315: =MEDIAN(AN3:AN290) -> 0.5925273 | AO315: =MEDIAN(AO3:AO290) -> 0.13379783 | AP315: =MEDIAN(AP3:AP290) -> 0.64953233 | AQ315: =MEDIAN(AQ3:AQ290) -> 0.16009622 | AR315: =MEDIAN(AR3:AR290) -> 0.31156743 | ... AU315: =MEDIAN(AU3:AU290) -> 0.7020149
L316: ="Target; Gain > "&L314 -> Target; Gain > 0.6 | M316: {=MEDIAN(_xlfn._xlws.FILTER(M3:M290, ($AZ3:$AZ290 > $X292)*($AZ3:$AZ290 <> "")))} -> 685346.9 | N316: {=MEDIAN(_xlfn._xlws.FILTER(N3:N290, ($AZ3:$AZ290 > $X292)*($AZ3:$AZ290 <> "")))} -> 480107.7 | O316: {=MEDIAN(_xlfn._xlws.FILTER(O3:O290, ($AZ3:$AZ290 > $X292)*($AZ3:$AZ290 <> "")))} -> 485880.7 | P316: {=MEDIAN(_xlfn._xlws.FILTER(P3:P290, ($AZ3:$AZ290 > $X292)*($AZ3:$AZ290 <> "")))} -> 1346578.3 | Q316: {=MEDIAN(_xlfn._xlws.FILTER(Q3:Q290, ($AZ3:$AZ290 > $X292)*($AZ3:$AZ290 <> "")))} -> 208301.2 | R316: {=MEDIAN(_xlfn._xlws.FILTER(R3:R290, ($AZ3:$AZ290 > $X292)*($AZ3:$AZ290 <> "")))} -> 1135925.3 | S316: {=MEDIAN(_xlfn._xlws.FILTER(S3:S290, ($AZ3:$AZ290 > $X292)*($AZ3:$AZ290 <> "")))} -> 270708.2 | T316: {=MEDIAN(_xlfn._xlws.FILTER(T3:T290, ($AZ3:$AZ290 > $X292)*($AZ3:$AZ290 <> "")))} -> 1773110.8 | ... W316: {=MEDIAN(_xlfn._xlws.FILTER(W3:W290, ($AZ3:$AZ290 > $X292)*($AZ3:$AZ290 <> "")))} -> 515448.8 | X316: ="Target; Gain > "&X314 -> Target; Gain > 0.6 | Y316: {=MEDIAN(_xlfn._xlws.FILTER(Y3:Y290, ($AZ3:$AZ290 > $X292)*($AZ3:$AZ290 <> "")))} -> 0.6387409 | Z316: {=MEDIAN(_xlfn._xlws.FILTER(Z3:Z290, ($AZ3:$AZ290 > $X292)*($AZ3:$AZ290 <> "")))} -> 0.48132225 | AA316: {=MEDIAN(_xlfn._xlws.FILTER(AA3:AA290, ($AZ3:$AZ290 > $X292)*($AZ3:$AZ290 <> "")))} -> 0.45052002 | AB316: {=MEDIAN(_xlfn._xlws.FILTER(AB3:AB290, ($AZ3:$AZ290 > $X292)*($AZ3:$AZ290 <> "")))} -> 0.70820817 | AC316: {=MEDIAN(_xlfn._xlws.FILTER(AC3:AC290, ($AZ3:$AZ290 > $X292)*($AZ3:$AZ290 <> "")))} -> 0.30266795 | AD316: {=MEDIAN(_xlfn._xlws.FILTER(AD3:AD290, ($AZ3:$AZ290 > $X292)*($AZ3:$AZ290 <> "")))} -> 0.89626822 | AE316: {=MEDIAN(_xlfn._xlws.FILTER(AE3:AE290, ($AZ3:$AZ290 > $X292)*($AZ3:$AZ290 <> "")))} -> 0.35417583 | AF316: {=MEDIAN(_xlfn._xlws.FILTER(AF3:AF290, ($AZ3:$AZ290 > $X292)*($AZ3:$AZ290 <> "")))} -> 1.2212485 | ... AI316: {=MEDIAN(_xlfn._xlws.FILTER(AI3:AI290, ($AZ3:$AZ290 > $X292)*($AZ3:$AZ290 <> "")))} -> 0.82691584 | AJ316: =X316 -> Target; Gain > 0.6 | AK316: {=MEDIAN(_xlfn._xlws.FILTER(AK3:AK290, ($AZ3:$AZ290 > $X292)*($AZ3:$AZ290 <> "")))} -> 0.6387409 | AL316: {=MEDIAN(_xlfn._xlws.FILTER(AL3:AL290, ($AZ3:$AZ290 > $X292)*($AZ3:$AZ290 <> "")))} -> 0.199286 | AM316: {=MEDIAN(_xlfn._xlws.FILTER(AM3:AM290, ($AZ3:$AZ290 > $X292)*($AZ3:$AZ290 <> "")))} -> 0.17337059 | AN316: {=MEDIAN(_xlfn._xlws.FILTER(AN3:AN290, ($AZ3:$AZ290 > $X292)*($AZ3:$AZ290 <> "")))} -> 0.70820817 | AO316: {=MEDIAN(_xlfn._xlws.FILTER(AO3:AO290, ($AZ3:$AZ290 > $X292)*($AZ3:$AZ290 <> "")))} -> 0.14006037 | AP316: {=MEDIAN(_xlfn._xlws.FILTER(AP3:AP290, ($AZ3:$AZ290 > $X292)*($AZ3:$AZ290 <> "")))} -> 0.89626822 | AQ316: {=MEDIAN(_xlfn._xlws.FILTER(AQ3:AQ290, ($AZ3:$AZ290 > $X292)*($AZ3:$AZ290 <> "")))} -> 0.15709297 | AR316: {=MEDIAN(_xlfn._xlws.FILTER(AR3:AR290, ($AZ3:$AZ290 > $X292)*($AZ3:$AZ290 <> "")))} -> 0.65659052 | ... AU316: {=MEDIAN(_xlfn._xlws.FILTER(AU3:AU290, ($AZ3:$AZ290 > $X292)*($AZ3:$AZ290 <> "")))} -> 0.52360208
L317: ="Gain > "&L314 -> Gain > 0.6 | M317: {=MEDIAN(_xlfn._xlws.FILTER(M3:M290, $AY3:$AY290>$X292))} -> 685346.9 | N317: {=MEDIAN(_xlfn._xlws.FILTER(N3:N290, $AY3:$AY290>$X292))} -> 480107.7 | O317: {=MEDIAN(_xlfn._xlws.FILTER(O3:O290, $AY3:$AY290>$X292))} -> 485880.7 | P317: {=MEDIAN(_xlfn._xlws.FILTER(P3:P290, $AY3:$AY290>$X292))} -> 1346578.3 | Q317: {=MEDIAN(_xlfn._xlws.FILTER(Q3:Q290, $AY3:$AY290>$X292))} -> 208301.2 | R317: {=MEDIAN(_xlfn._xlws.FILTER(R3:R290, $AY3:$AY290>$X292))} -> 1135925.3 | S317: {=MEDIAN(_xlfn._xlws.FILTER(S3:S290, $AY3:$AY290>$X292))} -> 270708.2 | T317: {=MEDIAN(_xlfn._xlws.FILTER(T3:T290, $AY3:$AY290>$X292))} -> 1773110.8 | ... W317: {=MEDIAN(_xlfn._xlws.FILTER(W3:W290, $AY3:$AY290>$X292))} -> 515448.8 | X317: ="Gain > "&X314 -> Gain > 0.6 | Y317: {=MEDIAN(_xlfn._xlws.FILTER(Y3:Y290, $AY3:$AY290>$X292))} -> 0.6387409 | Z317: {=MEDIAN(_xlfn._xlws.FILTER(Z3:Z290, $AY3:$AY290>$X292))} -> 0.48132225 | AA317: {=MEDIAN(_xlfn._xlws.FILTER(AA3:AA290, $AY3:$AY290>$X292))} -> 0.45052002 | AB317: {=MEDIAN(_xlfn._xlws.FILTER(AB3:AB290, $AY3:$AY290>$X292))} -> 0.70820817 | AC317: {=MEDIAN(_xlfn._xlws.FILTER(AC3:AC290, $AY3:$AY290>$X292))} -> 0.30266795 | AD317: {=MEDIAN(_xlfn._xlws.FILTER(AD3:AD290, $AY3:$AY290>$X292))} -> 0.89626822 | AE317: {=MEDIAN(_xlfn._xlws.FILTER(AE3:AE290, $AY3:$AY290>$X292))} -> 0.35417583 | AF317: {=MEDIAN(_xlfn._xlws.FILTER(AF3:AF290, $AY3:$AY290>$X292))} -> 1.2212485 | ... AI317: {=MEDIAN(_xlfn._xlws.FILTER(AI3:AI290, $AY3:$AY290>$X292))} -> 0.82691584 | AJ317: =X317 -> Gain > 0.6 | AK317: {=MEDIAN(_xlfn._xlws.FILTER(AK3:AK290, $AY3:$AY290>$X292))} -> 0.6387409 | AL317: {=MEDIAN(_xlfn._xlws.FILTER(AL3:AL290, $AY3:$AY290>$X292))} -> 0.199286 | AM317: {=MEDIAN(_xlfn._xlws.FILTER(AM3:AM290, $AY3:$AY290>$X292))} -> 0.17337059 | AN317: {=MEDIAN(_xlfn._xlws.FILTER(AN3:AN290, $AY3:$AY290>$X292))} -> 0.70820817 | AO317: {=MEDIAN(_xlfn._xlws.FILTER(AO3:AO290, $AY3:$AY290>$X292))} -> 0.14006037 | AP317: {=MEDIAN(_xlfn._xlws.FILTER(AP3:AP290, $AY3:$AY290>$X292))} -> 0.89626822 | AQ317: {=MEDIAN(_xlfn._xlws.FILTER(AQ3:AQ290, $AY3:$AY290>$X292))} -> 0.15709297 | AR317: {=MEDIAN(_xlfn._xlws.FILTER(AR3:AR290, $AY3:$AY290>$X292))} -> 0.65659052 | ... AU317: {=MEDIAN(_xlfn._xlws.FILTER(AU3:AU290, $AY3:$AY290>$X292))} -> 0.52360208
...

Sheet 100K
M1: Average Benchmark (results) | Y1: Average Benchmark (sequential timing) | AK1: Average Benchmark (parallel timing) | AW1: Average Benchmark (cluster_time)
F2: =F648 -> TargetN | G2: =G648 -> #N | H2: =H648 -> Target (or sym) | I2: =I648 -> Gain <=0 | J2: =J648 -> Gain > 0 | K2: =K648 -> Pref | L2: =L648 -> Pref&Target | M2: BNL | N2: BNL Causal | O2: BNL Causal HM | P2: SFS | Q2: SFS Causal | R2: SaLSa | S2: SaLSa Causal | T2: D&C | U2: D&C Causal | V2: BBS | W2: BBS Causal | Y2: BNL | Z2: BNL Causal | AA2: BNL Causal HM | AB2: SFS | AC2: SFS Causal | AD2: SaLSa | AE2: SaLSa Causal | AF2: D&C | AG2: D&C Causal | AH2: BBS | AI2: BBS Causal | AK2: BNL | AL2: BNL Causal | AM2: BNL Causal HM | AN2: SFS | AO2: SFS Causal | AP2: SaLSa | AQ2: SaLSa Causal | AR2: D&C | AS2: D&C Causal | AT2: BBS | AU2: BBS Causal | AW2: KMeans Time (seconds) | AY2: Gain | AZ2: =AX648 -> Target (or sym) ; Gain | BA2: =AY648 -> Gain<=0 | BB2: =AZ648 -> Gain>0
A3: 21 | B3: 156XXXX | C3: Hong_Kong_Weather_3 | D3: {cloud, mean_wet_bulb_temp, rainfall, rel_humidity} | F3: =F649 -> 0 | G3: =G649 -> 0 | H3: =H649 -> 1 | I3: =I649 -> 1 | J3: =J649 -> 0 | K3: =K649 -> 4 | L3: =L649 -> 4 | M3: 591322.8 | N3: 1131017.4 | O3: 1134285.4 | P3: 610685.6 | Q3: 591221.8 | R3: 558184.6 | S3: 850799.8 | T3: 1990328.4 | U3: 2005935.8 | V3: 806095.8 | W3: 983579.8 | Y3: 0.68790593 | Z3: 0.94351961 | AA3: 0.94054131 | AB3: 0.80676239 | AC3: 0.74834985 | AD3: 0.65796092 | AE3: 1.0270102 | AF3: 0.79895244 | AG3: 1.3444926 | AH3: 1.2159916 | AI3: 2.3067331 | AK3: 0.68790593 | AL3: 0.28158121 | AM3: 0.27704601 | AN3: 0.80676239 | AO3: 0.26755444 | AP3: 0.65796092 | AQ3: 0.35027438 | AR3: 0.50380233 | AS3: 0.23461419 | AT3: 1.2159916 | AU3: 1.6234462 | AW3: 0.079765795 | AY3: =BB339 -> -0.35233006 | AZ3: =AX649 -> -0.35233006 | BA3: =AY649 -> -0.35233006 | BB3: =AZ649
A4: 21 | B4: 156XXXN | C4: Hong_Kong_Weather_3 | D4: {cloud, mean_wet_bulb_temp, rainfall, rel_humidity} | F4: =F650 -> 0 | G4: =G650 -> 1 | H4: =H650 -> 0 | I4: =I650 -> 1 | J4: =J650 -> 0 | K4: =K650 -> 4 | L4: =L650 -> 0 | M4: 5784805.2 | N4: 4417204.4 | O4: 4516919.4 | P4: 5944589 | Q4: 1757442.2 | R4: 8401086.8 | S4: 3710031 | T4: 2452290.6 | U4: 2102672.4 | V4: 9319006.2 | W4: 4277233.4 | Y4: 4.4349503 | Z4: 3.1316225 | AA4: 3.1635416 | AB4: 3.3250108 | AC4: 1.580139 | AD4: 5.4640978 | AE4: 2.8201795 | AF4: 1.2625365 | AG4: 1.5358554 | AH4: 3.4247445 | AI4: 5.8018101 | AK4: 4.4349503 | AL4: 1.2096429 | AM4: 1.249186 | AN4: 3.3250108 | AO4: 0.58884037 | AP4: 5.4640978 | AQ4: 0.94967773 | AR4: 0.71332693 | AS4: 0.36049684 | AT4: 3.4247445 | AU4: 4.6636628 | AW4: 0.079846978 | AY4: =BB340 -> -0.058564036 | AZ4: =AX650 | BA4: =AY650 -> -0.058564036 | BB4: =AZ650
A5: 21 | B5: 156XXNX | C5: Hong_Kong_Weather_3 | D5: {cloud, mean_wet_bulb_temp, rainfall, rel_humidity} | F5: =F651 -> 0 | G5: =G651 -> 1 | H5: =H651 -> 0 | I5: =I651 -> 1 | J5: =J651 -> 0 | K5: =K651 -> 4 | L5: =L651 -> 0 | M5: 2656066 | N5: 2212539.8 | O5: 2201148.6 | P5: 777244.4 | Q5: 625033.8 | R5: 416308.2 | S5: 451931 | T5: 2027516.4 | U5: 1924123.4 | V5: 1527111.2 | W5: 1064940.6 | Y5: 2.1301415 | Z5: 1.6574462 | AA5: 1.636896 | AB5: 1.2432192 | AC5: 0.89618469 | AD5: 0.94773276 | AE5: 0.94394227 | AF5: 0.83007952 | AG5: 1.2086539 | AH5: 1.5732903 | AI5: 2.4382825 | AK5: 2.1301415 | AL5: 0.64858158 | AM5: 0.63129244 | AN5: 1.2432192 | AO5: 0.38674047 | AP5: 0.94773276 | AQ5: 0.33794346 | AR5: 0.55682227 | AS5: 0.27537748 | AT5: 1.5732903 | AU5: 1.7028201 | AW5: 0.082820945 | AY5: =BB341 -> -0.12790196 | AZ5: =AX651 | BA5: =AY651 -> -0.12790196 | BB5: =AZ651
A6: 21 | B6: 156XXNN | C6: Hong_Kong_Weather_3 | D6: {cloud, mean_wet_bulb_temp, rainfall, rel_humidity} | F6: =F652 -> 0 | G6: =G652 -> 0 | H6: =H652 -> 0 | I6: =I652 -> 0 | J6: =J652 -> 1 | K6: =K652 -> 4 | L6: =L652 -> 0 | M6: 3325676.6 | N6: 1874489.4 | O6: 1904038.6 | P6: 770825.8 | Q6: 603198.6 | R6: 605513.8 | S6: 471418.4 | T6: 2219802.8 | U6: 1544412.2 | V6: 3651384.6 | W6: 518458 | Y6: 2.5943821 | Z6: 1.5617345 | AA6: 1.5575454 | AB6: 1.228504 | AC6: 0.89660551 | AD6: 1.4214836 | AE6: 1.1349206 | AF6: 0.96858314 | AG6: 0.87191437 | AH6: 2.286031 | AI6: 1.8913461 | AK6: 2.5943821 | AL6: 0.52368851 | AM6: 0.52560114 | AN6: 1.228504 | AO6: 0.32056126 | AP6: 1.4214836 | AQ6: 0.36702605 | AR6: 0.55182215 | AS6: 0.21005896 | AT6: 2.286031 | AU6: 1.2491217 | AW6: 0.08817629 | AY6: =BB342 -> 0.11627095 | AZ6: =AX652 | BA6: =AY652 | BB6: =AZ652 -> 0.11627095
A7: 21 | B7: 156XNXX | C7: Hong_Kong_Weather_3 | D7: {cloud, mean_wet_bulb_temp, rainfall, rel_humidity} | F7: =F653 -> 0 | G7: =G653 -> 1 | H7: =H653 -> 0 | I7: =I653 -> 0 | J7: =J653 -> 1 | K7: =K653 -> 4 | L7: =L653 -> 0 | M7: 719562.8 | N7: 514981.8 | O7: 518937.2 | P7: 1511964.4 | Q7: 250619.8 | R7: 707016.6 | S7: 228762 | T7: 2288383 | U7: 1687985.6 | V7: 4018571.2 | W7: 378833.2 | Y7: 0.86360003 | Z7: 0.61499745 | AA7: 0.60752526 | AB7: 1.4775579 | AC7: 0.49027639 | AD7: 1.4290163 | AE7: 0.55326075 | AF7: 1.1102086 | AG7: 1.1048217 | AH7: 2.4256375 | AI7: 1.1232568 | AK7: 0.86360003 | AL7: 0.25701692 | AM7: 0.25258218 | AN7: 1.4775579 | AO7: 0.19368886 | AP7: 1.4290163 | AQ7: 0.20973879 | AR7: 0.58542886 | AS7: 0.20766829 | AT7: 2.4256375 | AU7: 0.72332433 | AW7: 0.085144602 | AY7: =BB343 -> 0.23808718 | AZ7: =AX653 | BA7: =AY653 | BB7: =AZ653 -> 0.23808718
A8: 21 | B8: 156XNXN | C8: Hong_Kong_Weather_3 | D8: {cloud, mean_wet_bulb_temp, rainfall, rel_humidity} | F8: =F654 -> 0 | G8: =G654 -> 0 | H8: =H654 -> 0 | I8: =I654 -> 0 | J8: =J654 -> 1 | K8: =K654 -> 4 | L8: =L654 -> 0 | M8: 2694259.6 | N8: 5056444 | O8: 5030009.8 | P8: 2576512.4 | Q8: 2352969.6 | R8: 2006673.2 | S8: 4299936 | T8: 1950584.4 | U8: 2497032.4 | V8: 9822797.6 | W8: 4558580.6 | Y8: 2.5888299 | Z8: 3.5544233 | AA8: 3.4993318 | AB8: 3.1161521 | AC8: 1.6330287 | AD8: 2.7433795 | AE8: 2.9927363 | AF8: 0.83356838 | AG8: 2.0185169 | AH8: 3.5584358 | AI8: 7.0006635 | AK8: 2.5888299 | AL8: 1.1081895 | AM8: 1.0804279 | AN8: 3.1161521 | AO8: 0.5585308 | AP8: 2.7433795 | AQ8: 0.80967589 | AR8: 0.55884432 | AS8: 0.36750091 | AT8: 3.5584358 | AU8: 5.6998284 | AW8: 0.085135836 | AY8: =BB344 -> 0.089505628 | AZ8: =AX654 | BA8: =AY654 | BB8: =AZ654 -> 0.089505628
A9: 21 | B9: 156XNNX | C9: Hong_Kong_Weather_3 | D9: {cloud, mean_wet_bulb_temp, rainfall, rel_humidity} | F9: =F655 -> 0 | G9: =G655 -> 0 | H9: =H655 -> 0 | I9: =I655 -> 0 | J9: =J655 -> 1 | K9: =K655 -> 4 | L9: =L655 -> 0 | M9: 855806.6 | N9: 870324.8 | O9: 874922.6 | P9: 758482 | Q9: 319383 | R9: 251952.2 | S9: 207372 | T9: 2201870.4 | U9: 1604905.4 | V9: 305572.8 | W9: 232329 | Y9: 0.88253907 | Z9: 0.85303863 | AA9: 0.84032082 | AB9: 0.98148527 | AC9: 0.57443237 | AD9: 0.8149278 | AE9: 0.76273022 | AF9: 0.97267769 | AG9: 0.95632661 | AH9: 1.2525279 | AI9: 1.1573414 | AK9: 0.88253907 | AL9: 0.3484898 | AM9: 0.33925478 | AN9: 0.98148527 | AO9: 0.22744982 | AP9: 0.8149278 | AQ9: 0.2471423 | AR9: 0.56090306 | AS9: 0.21696128 | AT9: 1.2525279 | AU9: 0.72657965 | AW9: 0.087667384 | AY9: =BB345 -> 0.14655348 | AZ9: =AX655 | BA9: =AY655 | BB9: =AZ655 -> 0.14655348
A10: 21 | B10: 156XNNN | C10: Hong_Kong_Weather_3 | D10: {cloud, mean_wet_bulb_temp, rainfall, rel_humidity} | F10: =F656 -> 0 | G10: =G656 -> 1 | H10: =H656 -> 0 | I10: =I656 -> 1 | J10: =J656 -> 0 | K10: =K656 -> 4 | L10: =L656 -> 0 | M10: 762461.6 | N10: 2138579.6 | O10: 2143938.6 | P10: 258523.8 | Q10: 466952.2 | R10: 179744.2 | S10: 376655.6 | T10: 1771848.2 | U10: 1813385.6 | V10: 152247.2 | W10: 634684.6 | Y10: 0.8206304 | Z10: 1.6830551 | AA10: 1.6745409 | AB10: 0.54528792 | AC10: 0.76698609 | AD10: 0.81092519 | AE10: 1.0221588 | AF10: 0.60068475 | AG10: 1.1386133 | AH10: 0.78327832 | AI10: 2.4637325 | AK10: 0.8206304 | AL10: 0.45642532 | AM10: 0.45620556 | AN10: 0.54528792 | AO10: 0.27678809 | AP10: 0.81092519 | AQ10: 0.32096604 | AR10: 0.38625747 | AS10: 0.21962169 | AT10: 0.78327832 | AU10: 1.7823788 | AW10: 0.085246643 | AY10: =BB346 -> -0.051621186 | AZ10: =AX656 | BA10: =AY656 -> -0.051621186 | BB10: =AZ656
A11: 21 | B11: 156NXXX | C11: Hong_Kong_Weather_3 | D11: {cloud, mean_wet_bulb_temp, rainfall, rel_humidity} | F11: =F657 -> 0 | G11: =G657 -> 1 | H11: =H657 -> 0 | I11: =I657 -> 1 | J11: =J657 -> 0 | K11: =K657 -> 4 | L11: =L657 -> 0 | M11: 3483312.4 | N11: 5050990.2 | O11: 5114443.6 | P11: 2914342.8 | Q11: 2117099 | R11: 4349300.6 | S11: 4071798 | T11: 2012199.6 | U11: 2131113.2 | V11: 6722022.6 | W11: 4560902.4 | Y11: 3.2947702 | Z11: 3.7537318 | AA11: 3.7373906 | AB11: 3.4209252 | AC11: 2.1461832 | AD11: 4.2697962 | AE11: 3.6977415 | AF11: 0.87113624 | AG11: 1.5714141 | AH11: 4.1265668 | AI11: 7.8868353 | AK11: 3.2947702 | AL11: 1.2683303 | AM11: 1.2835331 | AN11: 3.4209252 | AO11: 0.80756242 | AP11: 4.2697962 | AQ11: 1.2295037 | AR11: 0.54576941 | AS11: 0.28269383 | AT11: 4.1265668 | AU11: 6.4681974 | AW11: 0.085371461 | AY11: =BB347 -> -0.051621186 | AZ11: =AX657 | BA11: =AY657 -> -0.051621186 | BB11: =AZ657
A12: 21 | B12: 156NXXN | C12: Hong_Kong_Weather_3 | D12: {cloud, mean_wet_bulb_temp, rainfall, rel_humidity} | F12: =F658 -> 0 | G12: =G658 -> 0 | H12: =H658 -> 0 | I12: =I658 -> 0 | J12: =J658 -> 1 | K12: =K658 -> 4 | L12: =L658 -> 0 | M12: 3711535.8 | N12: 2675703.2 | O12: 2684537.8 | P12: 5929558.8 | Q12: 2163008.8 | R12: 4448174.2 | S12: 2020884.4 | T12: 2410642.6 | U12: 1974837.4 | V12: 12633703 | W12: 3899083.4 | Y12: 3.175054 | Z12: 2.1138983 | AA12: 2.0979275 | AB12: 5.176313 | AC12: 2.1931484 | AD12: 4.6216452 | AE12: 2.4180419 | AF12: 1.2674212 | AG12: 1.435808 | AH12: 4.8661702 | AI12: 3.757356 | AK12: 3.175054 | AL12: 0.97869132 | AM12: 0.96946591 | AN12: 5.176313 | AO12: 1.1353703 | AP12: 4.6216452 | AQ12: 1.09602 | AR12: 0.70262827 | AS12: 0.31061147 | AT12: 4.8661702 | AU12: 2.7452694 | AW12: 0.085222634 | AY12: =BB348 -> 0.14655348 | AZ12: =AX658 | BA12: =AY658 | BB12: =AZ658 -> 0.14655348
