Workbook

Sheet Summary
A2: % Dominance gain wrt Non-Causal Baseline [median] | M2: % Sequential Time gain wrt Non-Causal Baseline [median]
A3: Target or symm.; Gain > 0 | B3: Leakage | E3: Name | F3: Algorithm | M3: Target or symm.; Gain > 0 | N3: Leakage | Q3: Name | R3: Algorithm
B4: Open | C4: Closed | F4: BNL | G4: BNL HM | H4: SFS | I4: SaLSa | J4: D&C | K4: BBS | N4: Open | O4: Closed | R4: BNL | S4: BNL HM | T4: SFS | U4: SaLSa | V4: D&C | W4: BBS
A5: Pref. Decor. | E5: Pref. Decor. | F5: ='Pure Decorrelation'!M649 -> -4.5013245 | G5: ='Pure Decorrelation'!N649 -> -4.5386725 | H5: ='Pure Decorrelation'!O649 -> -2.2334695 | I5: ='Pure Decorrelation'!P649 -> -5.2291919 | J5: ='Pure Decorrelation'!Q649 -> 0.081259382 | K5: ='Pure Decorrelation'!R649 -> -2.2526636 | M5: Pref. Decor. | Q5: Pref. Decor. | R5: ='Pure Decorrelation'!T649 -> -2.1219164 | S5: ='Pure Decorrelation'!U649 -> -2.1057207 | T5: ='Pure Decorrelation'!V649 -> -1.0373559 | U5: ='Pure Decorrelation'!W649 -> -1.4880852 | V5: ='Pure Decorrelation'!X649 -> -0.18623676 | W5: ='Pure Decorrelation'!Y649 -> -1.8345709
A6: ddSky. | E6: ddSky. | F6: =ddSky!M649 -> 0.35253138 | G6: =ddSky!N649 -> 0.34360311 | H6: =ddSky!O649 -> 0.52110022 | I6: =ddSky!P649 -> 0.55673786 | J6: =ddSky!Q649 -> 0.23949286 | K6: =ddSky!R649 -> 0.81480004 | M6: ddSky. | Q6: ddSky. | R6: =ddSky!T649 -> 0.24808604 | S6: =ddSky!U649 -> 0.25099046 | T6: =ddSky!V649 -> 0.33699401 | U6: =ddSky!W649 -> 0.40704631 | V6: =ddSky!X649 -> -0.031222673 | W6: =ddSky!Y649 -> 0.54132027
A7: gnSky. | D7: (1.0, 0.0) | E7: gnSky. | F7: =gnSky!M649 -> 0.20951122 | G7: =gnSky!N649 -> 0.20262298 | H7: =gnSky!O649 -> 0.35124439 | I7: =gnSky!P649 -> 0.42450225 | J7: =gnSky!Q649 -> 0.23469128 | K7: =gnSky!R649 -> 0.72639277 | M7: gnSky. | P7: (1.0, 0.0) | Q7: gnSky. | R7: =gnSky!T649 -> 0.17816768 | S7: =gnSky!U649 -> 0.1858732 | T7: =gnSky!V649 -> 0.25036007 | U7: =gnSky!W649 -> 0.20214037 | V7: =gnSky!X649 -> 0.030701517 | W7: =gnSky!Y649 -> 0.40980178
A8: lnSky. (0.9, 0.1) | B8: 0.9 | C8: 0.1 | D8: (0.9, 0.1) | E8: lnSky. (0.9, 0.1) | F8: ='lnSky (0.9, 0.1)'!M649 -> 0.20750686 | G8: ='lnSky (0.9, 0.1)'!N649 -> 0.19886044 | H8: ='lnSky (0.9, 0.1)'!O649 -> 0.5711753 | I8: ='lnSky (0.9, 0.1)'!P649 -> 0.5302215 | J8: ='lnSky (0.9, 0.1)'!Q649 -> 0.1907766 | K8: ='lnSky (0.9, 0.1)'!R649 -> 0.73263432 | M8: lnSky. (0.9, 0.1) | N8: 0.9 | O8: 0.1 | P8: (0.9, 0.1) | Q8: lnSky. (0.9, 0.1) | R8: ='lnSky (0.9, 0.1)'!T649 -> 0.16979724 | S8: ='lnSky (0.9, 0.1)'!U649 -> 0.17254509 | T8: ='lnSky (0.9, 0.1)'!V649 -> 0.42245866 | U8: ='lnSky (0.9, 0.1)'!W649 -> 0.34048295 | V8: ='lnSky (0.9, 0.1)'!X649 -> 0.03888698 | W8: ='lnSky (0.9, 0.1)'!Y649 -> 0.42622153
A9: lnSky. (0.8, 0.2) | B9: 0.8 | C9: 0.2 | D9: (0.8, 0.2) | E9: lnSky. (0.8, 0.2) | F9: ='lnSky (0.8, 0.2)'!M649 -> 0.36388962 | G9: ='lnSky (0.8, 0.2)'!N649 -> 0.35713037 | H9: ='lnSky (0.8, 0.2)'!O649 -> 0.67091148 | I9: ='lnSky (0.8, 0.2)'!P649 -> 0.77895715 | J9: ='lnSky (0.8, 0.2)'!Q649 -> 0.18009713 | K9: ='lnSky (0.8, 0.2)'!R649 -> 0.80583693 | M9: lnSky. (0.8, 0.2) | N9: 0.8 | O9: 0.2 | P9: (0.8, 0.2) | Q9: lnSky. (0.8, 0.2) | R9: ='lnSky (0.8, 0.2)'!T649 -> 0.31206602 | S9: ='lnSky (0.8, 0.2)'!U649 -> 0.31412748 | T9: ='lnSky (0.8, 0.2)'!V649 -> 0.49125493 | U9: ='lnSky (0.8, 0.2)'!W649 -> 0.53943442 | V9: ='lnSky (0.8, 0.2)'!X649 -> 0.029709009 | W9: ='lnSky (0.8, 0.2)'!Y649 -> 0.51710924
A10: lnSky. (0.7, 0.3) | B10: 0.7 | C10: 0.3 | D10: (0.7, 0.3) | E10: lnSky. (0.7, 0.3) | F10: ='lnSky (0.7, 0.3)'!M649 -> 0.33265982 | G10: ='lnSky (0.7, 0.3)'!N649 -> 0.32951513 | H10: ='lnSky (0.7, 0.3)'!O649 -> 0.66316949 | I10: ='lnSky (0.7, 0.3)'!P649 -> 0.74521812 | J10: ='lnSky (0.7, 0.3)'!Q649 -> 0.18523748 | K10: ='lnSky (0.7, 0.3)'!R649 -> 0.76327438 | M10: lnSky. (0.7, 0.3) | N10: 0.7 | O10: 0.3 | P10: (0.7, 0.3) | Q10: lnSky. (0.7, 0.3) | R10: ='lnSky (0.7, 0.3)'!T649 -> 0.25518493 | S10: ='lnSky (0.7, 0.3)'!U649 -> 0.25569361 | T10: ='lnSky (0.7, 0.3)'!V649 -> 0.48531823 | U10: ='lnSky (0.7, 0.3)'!W649 -> 0.53666875 | V10: ='lnSky (0.7, 0.3)'!X649 -> 0.037415142 | W10: ='lnSky (0.7, 0.3)'!Y649 -> 0.51516533
A11: lnSky. (0.6, 0.4) | B11: 0.6 | C11: 0.4 | D11: (0.6, 0.4) | E11: lnSky. (0.6, 0.4) | F11: ='lnSky (0.6, 0.4)'!M649 -> 0.33265982 | G11: ='lnSky (0.6, 0.4)'!N649 -> 0.32951513 | H11: ='lnSky (0.6, 0.4)'!O649 -> 0.67091148 | I11: ='lnSky (0.6, 0.4)'!P649 -> 0.76107603 | J11: ='lnSky (0.6, 0.4)'!Q649 -> 0.18514995 | K11: ='lnSky (0.6, 0.4)'!R649 -> 0.79145208 | M11: lnSky. (0.6, 0.4) | N11: 0.6 | O11: 0.4 | P11: (0.6, 0.4) | Q11: lnSky. (0.6, 0.4) | R11: ='lnSky (0.6, 0.4)'!T649 -> 0.26401017 | S11: ='lnSky (0.6, 0.4)'!U649 -> 0.26483101 | T11: ='lnSky (0.6, 0.4)'!V649 -> 0.4862091 | U11: ='lnSky (0.6, 0.4)'!W649 -> 0.54150486 | V11: ='lnSky (0.6, 0.4)'!X649 -> 0.02999235 | W11: ='lnSky (0.6, 0.4)'!Y649 -> 0.5196199
A12: Direct w/ gnSky

Sheet Pure Decorrelation
M1: Average Benchmark (results) | Y1: Average Benchmark (sequential timing) | AK1: Average Benchmark (parallel timing) | AW1: Average Benchmark (cluster_time)
F2: =F654 -> TargetN | G2: =G654 -> #N | H2: =H654 -> Target (or sym) | I2: =I654 -> Gain <=0 | J2: =J654 -> Gain > 0 | K2: =K654 -> Pref | L2: =L654 -> Pref&Target | M2: BNL | N2: BNL Causal | O2: BNL Causal HM | P2: SFS | Q2: SFS Causal | R2: SaLSa | S2: SaLSa Causal | T2: D&C | U2: D&C Causal | V2: BBS | W2: BBS Causal | Y2: BNL | Z2: BNL Causal | AA2: BNL Causal HM | AB2: SFS | AC2: SFS Causal | AD2: SaLSa | AE2: SaLSa Causal | AF2: D&C | AG2: D&C Causal | AH2: BBS | AI2: BBS Causal | AK2: BNL | AL2: BNL Causal | AM2: BNL Causal HM | AN2: SFS | AO2: SFS Causal | AP2: SaLSa | AQ2: SaLSa Causal | AR2: D&C | AS2: D&C Causal | AT2: BBS | AU2: BBS Causal | AW2: KMeans Time (seconds) | AY2: Gain | AZ2: =AX654 -> Target (or sym) ; Gain | BA2: =AY654 -> Gain<=0 | BB2: =AZ654 -> Gain>0
A3: 21 | B3: 156XXXX | C3: Hong_Kong_Weather_3 | D3: {cloud, mean_wet_bulb_temp, rainfall, rel_humidity} | F3: =F655 -> 0 | G3: =G655 -> 0 | H3: =H655 -> 1 | I3: =I655 -> 0 | J3: =J655 -> 1 | K3: =K655 -> 4 | L3: =L655 -> 4 | M3: 984737.8 | N3: 10022863 | O3: 10082711 | P3: 1004122.8 | Q3: 5817876.8 | R3: 881239.4 | S3: 10274494 | T3: 4185627.2 | U3: 4336446.8 | V3: 1396199.2 | W3: 8664971.6 | Y3: 1.3718655 | Z3: 7.3616699 | AA3: 7.3149721 | AB3: 1.6075157 | AC3: 5.2482228 | AD3: 1.0902543 | AE3: 8.100779 | AF3: 1.5241145 | AG3: 2.7269407 | AH3: 2.9582296 | AI3: 14.576076 | AK3: 1.3718655 | AL3: 2.5448769 | AM3: 2.5492649 | AN3: 1.6075157 | AO3: 1.8831961 | AP3: 1.0902543 | AQ3: 2.9239906 | AR3: 0.9750971 | AS3: 0.64183103 | AT3: 2.9582296 | AU3: 11.772234 | AW3: 0.31142347 | AY3: =BB343 -> 1 | AZ3: =AX655 -> 1 | BA3: =AY655 | BB3: =AZ655 -> 1
A4: 21 | B4: 156XXXN | C4: Hong_Kong_Weather_3 | D4: {cloud, mean_wet_bulb_temp, rainfall, rel_humidity} | F4: =F656 -> 0 | G4: =G656 -> 1 | H4: =H656 -> 0 | I4: =I656 -> 1 | J4: =J656 -> 0 | K4: =K656 -> 4 | L4: =L656 -> 0 | M4: 9774060 | N4: 4768147.6 | O4: 4743320.2 | P4: 14747945 | Q4: 1555096.6 | R4: 16571915 | S4: 3159799.4 | T4: 4907318.2 | U4: 3939126.4 | V4: 21091677 | W4: 2550318.6 | Y4: 8.385313 | Z4: 3.8032576 | AA4: 3.7796306 | AB4: 7.9825207 | AC4: 2.2019668 | AD4: 11.337875 | AE4: 3.3661471 | AF4: 2.1943271 | AG4: 2.3247525 | AH4: 7.9510913 | AI4: 5.5401984 | AK4: 8.385313 | AL4: 1.646166 | AM4: 1.6287097 | AN4: 7.9825207 | AO4: 0.97883885 | AP4: 11.337875 | AQ4: 1.2861934 | AR4: 1.2434555 | AS4: 0.63097686 | AT4: 7.9510913 | AU4: 3.9433181 | AW4: 0.31174662 | AY4: =BB344 -> -3 | AZ4: =AX656 | BA4: =AY656 -> -3 | BB4: =AZ656
A5: 21 | B5: 156XXNX | C5: Hong_Kong_Weather_3 | D5: {cloud, mean_wet_bulb_temp, rainfall, rel_humidity} | F5: =F657 -> 0 | G5: =G657 -> 1 | H5: =H657 -> 0 | I5: =I657 -> 1 | J5: =J657 -> 0 | K5: =K657 -> 4 | L5: =L657 -> 0 | M5: 4329316.4 | N5: 5708330.4 | O5: 5876682.4 | P5: 1278792.2 | Q5: 2762314.2 | R5: 616378.2 | S5: 2267205 | T5: 4215981.4 | U5: 3916185.8 | V5: 2636300 | W5: 3949562.8 | Y5: 3.828656 | Z5: 4.4432907 | AA5: 4.5239025 | AB5: 2.3397783 | AC5: 2.714684 | AD5: 1.726517 | AE5: 2.9614979 | AF5: 1.5807121 | AG5: 2.216917 | AH5: 3.6683148 | AI5: 7.513542 | AK5: 3.828656 | AL5: 1.5569136 | AM5: 1.638306 | AN5: 2.3397783 | AO5: 1.2357769 | AP5: 1.726517 | AQ5: 1.1493316 | AR5: 1.0567209 | AS5: 0.56853997 | AT5: 3.6683148 | AU5: 5.5275729 | AW5: 0.32285666 | AY5: =BB345 -> -3 | AZ5: =AX657 | BA5: =AY657 -> -3 | BB5: =AZ657
A6: 21 | B6: 156XXNN | C6: Hong_Kong_Weather_3 | D6: {cloud, mean_wet_bulb_temp, rainfall, rel_humidity} | F6: =F658 -> 0 | G6: =G658 -> 0 | H6: =H658 -> 0 | I6: =I658 -> 0 | J6: =J658 -> 1 | K6: =K658 -> 4 | L6: =L658 -> 0 | M6: 4797310.6 | N6: 2327862 | O6: 2333566.4 | P6: 1475770.8 | Q6: 639802.8 | R6: 1030299.8 | S6: 781966.2 | T6: 4594408.8 | U6: 3608168.8 | V6: 8246724.6 | W6: 1026269.8 | Y6: 4.3051407 | Z6: 2.2448575 | AA6: 2.2267145 | AB6: 2.5700545 | AC6: 1.3296278 | AD6: 2.8279426 | AE6: 1.9226274 | AF6: 1.8526587 | AG6: 1.9668249 | AH6: 5.3781422 | AI6: 3.0659769 | AK6: 4.3051407 | AL6: 0.87471073 | AM6: 0.87191543 | AN6: 2.5700545 | AO6: 0.63183793 | AP6: 2.8279426 | AQ6: 0.74748458 | AR6: 1.0730149 | AS6: 0.53986058 | AT6: 5.3781422 | AU6: 1.910186 | AW6: 0.31912437 | AY6: =BB346 -> 1 | AZ6: =AX658 | BA6: =AY658 | BB6: =AZ658 -> 1
A7: 21 | B7: 156XNXX | C7: Hong_Kong_Weather_3 | D7: {cloud, mean_wet_bulb_temp, rainfall, rel_humidity} | F7: =F659 -> 0 | G7: =G659 -> 1 | H7: =H659 -> 0 | I7: =I659 -> 0 | J7: =J659 -> 1 | K7: =K659 -> 4 | L7: =L659 -> 0 | M7: 1254500 | N7: 8211267.8 | O7: 8385658.4 | P7: 3405256 | Q7: 5392684.4 | R7: 1465331.4 | S7: 11978384 | T7: 4677209.6 | U7: 4016900.4 | V7: 7657925.2 | W7: 7117200.4 | Y7: 1.7459986 | Z7: 6.7369938 | AA7: 6.8520819 | AB7: 3.199273 | AC7: 4.832371 | AD7: 2.892981 | AE7: 10.556205 | AF7: 2.0297543 | AG7: 2.5032138 | AH7: 5.2049517 | AI7: 9.8846658 | AK7: 1.7459986 | AL7: 4.2834749 | AM7: 4.4000099 | AN7: 3.199273 | AO7: 3.0720111 | AP7: 2.892981 | AQ7: 7.730213 | AR7: 1.1097154 | AS7: 0.7778796 | AT7: 5.2049517 | AU7: 8.2927167 | AW7: 0.31720362 | AY7: =BB347 -> 9 | AZ7: =AX659 | BA7: =AY659 | BB7: =AZ659 -> 9
A8: 21 | B8: 156XNXN | C8: Hong_Kong_Weather_3 | D8: {cloud, mean_wet_bulb_temp, rainfall, rel_humidity} | F8: =F660 -> 0 | G8: =G660 -> 0 | H8: =H660 -> 0 | I8: =I660 -> 0 | J8: =J660 -> 1 | K8: =K660 -> 4 | L8: =L660 -> 0 | M8: 4819087.6 | N8: 4932159 | O8: 5277290.8 | P8: 5594837.2 | Q8: 1744670 | R8: 4114032.2 | S8: 4301307.4 | T8: 4018927.8 | U8: 4004214.4 | V8: 24198068 | W8: 2695408.4 | Y8: 5.2910015 | Z8: 4.2471254 | AA8: 4.4392391 | AB8: 6.9649184 | AC8: 2.5508812 | AD8: 6.292094 | AE8: 4.1369936 | AF8: 1.5069674 | AG8: 2.5294473 | AH8: 8.4431713 | AI8: 6.5814194 | AK8: 5.2910015 | AL8: 1.6044603 | AM8: 1.8026691 | AN8: 6.9649184 | AO8: 1.0486424 | AP8: 6.292094 | AQ8: 1.6140749 | AR8: 1.0047482 | AS8: 0.62829525 | AT8: 8.4431713 | AU8: 4.9306731 | AW8: 0.32276495 | AY8: =BB348 -> 1 | AZ8: =AX660 | BA8: =AY660 | BB8: =AZ660 -> 1
A9: 21 | B9: 156XNNX | C9: Hong_Kong_Weather_3 | D9: {cloud, mean_wet_bulb_temp, rainfall, rel_humidity} | F9: =F661 -> 0 | G9: =G661 -> 0 | H9: =H661 -> 0 | I9: =I661 -> 1 | J9: =J661 -> 0 | K9: =K661 -> 4 | L9: =L661 -> 0 | M9: 2186441.2 | N9: 4570545.2 | O9: 4339608.6 | P9: 1589889 | Q9: 2689294.8 | R9: 616867 | S9: 2147966.8 | T9: 4560935.4 | U9: 3691327.6 | V9: 575641.8 | W9: 2539553.2 | Y9: 2.1583616 | Z9: 3.9812017 | AA9: 3.836798 | AB9: 2.0238636 | AC9: 2.9633648 | AD9: 1.6820759 | AE9: 3.1078367 | AF9: 1.8537012 | AG9: 2.0354693 | AH9: 2.9026718 | AI9: 5.0440308 | AK9: 2.1583616 | AL9: 1.9623007 | AM9: 1.8304167 | AN9: 2.0238636 | AO9: 1.4115784 | AP9: 1.6820759 | AQ9: 1.4057721 | AR9: 1.087151 | AS9: 0.60014935 | AT9: 2.9026718 | AU9: 3.6228537 | AW9: 0.31864881 | AY9: =BB349 -> -3 | AZ9: =AX661 | BA9: =AY661 -> -3 | BB9: =AZ661
A10: 21 | B10: 156XNNN | C10: Hong_Kong_Weather_3 | D10: {cloud, mean_wet_bulb_temp, rainfall, rel_humidity} | F10: =F662 -> 0 | G10: =G662 -> 1 | H10: =H662 -> 0 | I10: =I662 -> 1 | J10: =J662 -> 0 | K10: =K662 -> 4 | L10: =L662 -> 0 | M10: 1359597.6 | N10: 3167304.6 | O10: 3404874 | P10: 602084 | Q10: 1300983.6 | R10: 362702.6 | S10: 1474098.6 | T10: 3787607.6 | U10: 3761598.4 | V10: 230918.4 | W10: 2099069.6 | Y10: 1.6504133 | Z10: 2.9586209 | AA10: 3.1068234 | AB10: 1.309188 | AC10: 2.0336399 | AD10: 1.7599426 | AE10: 2.5879828 | AF10: 1.216636 | AG10: 2.187835 | AH10: 1.5905149 | AI10: 4.9674127 | AK10: 1.6504133 | AL10: 1.0622237 | AM10: 1.2209281 | AN10: 1.309188 | AO10: 0.77097515 | AP10: 1.7599426 | AQ10: 0.84869093 | AR10: 0.78808016 | AS10: 0.56963752 | AT10: 1.5905149 | AU10: 3.3881653 | AW10: 0.32476171 | AY10: =BB350 -> -3 | AZ10: =AX662 | BA10: =AY662 -> -3 | BB10: =AZ662
A11: 21 | B11: 156NXXX | C11: Hong_Kong_Weather_3 | D11: {cloud, mean_wet_bulb_temp, rainfall, rel_humidity} | F11: =F663 -> 0 | G11: =G663 -> 1 | H11: =H663 -> 0 | I11: =I663 -> 1 | J11: =J663 -> 0 | K11: =K663 -> 4 | L11: =L663 -> 0 | M11: 6171416.2 | N11: 6805158.4 | O11: 6857539.4 | P11: 8419143.6 | Q11: 2905263.6 | R11: 9256532.2 | S11: 6328932 | T11: 4215910.2 | U11: 4184912 | V11: 19259380 | W11: 3812327.2 | Y11: 6.5145961 | Z11: 5.4953548 | AA11: 5.4963909 | AB11: 10.051685 | AC11: 3.3562829 | AD11: 9.2313233 | AE11: 5.8270503 | AF11: 1.662673 | AG11: 2.7369827 | AH11: 10.641126 | AI11: 8.6416807 | AK11: 6.5145961 | AL11: 2.2705729 | AM11: 2.29022 | AN11: 10.051685 | AO11: 1.5883353 | AP11: 9.2313233 | AQ11: 2.323506 | AR11: 1.0560422 | AS11: 0.65100236 | AT11: 10.641126 | AU11: 6.74493 | AW11: 0.32241962 | AY11: =BB351 -> -3 | AZ11: =AX663 | BA11: =AY663 -> -3 | BB11: =AZ663
A12: 21 | B12: 156NXXN | C12: Hong_Kong_Weather_3 | D12: {cloud, mean_wet_bulb_temp, rainfall, rel_humidity} | F12: =F664 -> 0 | G12: =G664 -> 0 | H12: =H664 -> 0 | I12: =I664 -> 1 | J12: =J664 -> 0 | K12: =K664 -> 4 | L12: =L664 -> 0 | M12: 6077126.4 | N12: 6523186.2 | O12: 6683859.2 | P12: 14297376 | Q12: 2766018.8 | R12: 9345182.6 | S12: 7992747.4 | T12: 4852422.4 | U12: 3966619.4 | V12: 31495539 | W12: 3691529.6 | Y12: 6.1149932 | Z12: 5.2643429 | AA12: 5.3412261 | AB12: 12.623191 | AC12: 3.3510144 | AD12: 10.215354 | AE12: 6.7976655 | AF12: 2.2462109 | AG12: 2.4651819 | AH12: 11.225533 | AI12: 8.0396503 | AK12: 6.1149932 | AL12: 2.6219385 | AM12: 2.6974127 | AN12: 12.623191 | AO12: 1.780658 | AP12: 10.215354 | AQ12: 3.9254723 | AR12: 1.259069 | AS12: 0.6301522 | AT12: 11.225533 | AU12: 6.3221946 | AW12: 0.31969761 | AY12: =BB352 -> -3 | AZ12: =AX664 | BA12: =AY664 -> -3 | BB12: =AZ664
A13: 21 | B13: 156NXNX | C13: Hong_Kong_Weather_3 | D13: {cloud, mean_wet_bulb_temp, rainfall, rel_humidity} | F13: =F665 -> 0 | G13: =G665 -> 0 | H13: =H665 -> 0 | I13: =I665 -> 0 | J13: =J665 -> 1 | K13: =K665 -> 4 | L13: =L665 -> 0 | M13: 4373945.6 | N13: 3525196.8 | O13: 3542716.8 | P13: 4791875 | Q13: 1227249 | R13: 3330299.8 | S13: 1129757.4 | T13: 4221177.6 | U13: 3820898.8 | V13: 5883243.8 | W13: 2247583.4 | Y13: 4.0645885 | Z13: 3.0854349 | AA13: 3.0809418 | AB13: 3.1259433 | AC13: 1.7536643 | AD13: 3.0631603 | AE13: 2.3240296 | AF13: 1.6403528 | AG13: 2.2280405 | AH13: 4.4035068 | AI13: 4.2895956 | AK13: 4.0645885 | AL13: 1.190528 | AM13: 1.1977567 | AN13: 3.1259433 | AO13: 0.77954667 | AP13: 3.0631603 | AQ13: 0.83620563 | AR13: 1.0916918 | AS13: 0.5944944 | AT13: 4.4035068 | AU13: 2.6821506 | AW13: 0.32064945 | AY13: =BB353 -> 1 | AZ13: =AX665 | BA13: =AY665 | BB13: =AZ665 -> 1
A14: 21 | B14: 156NXNN | C14: Hong_Kong_Weather_3 | D14: {cloud, mean_wet_bulb_temp, rainfall, rel_humidity} | F14: =F666 -> 0 | G14: =G666 -> 1 | H14: =H666 -> 0 | I14: =I666 -> 0 | J14: =J666 -> 1 | K14: =K666 -> 4 | L14: =L666 -> 0 | M14: 1743369.2 | N14: 5681416.4 | O14: 5716200.8 | P14: 3424600.8 | Q14: 3042341.4 | R14: 2642237 | S14: 2579986.8 | T14: 4575869 | U14: 3750440.2 | V14: 7388502.4 | W14: 4680236.4 | Y14: 1.9127118 | Z14: 4.7608887 | AA14: 4.7306703 | AB14: 3.1142022 | AC14: 3.0985967 | AD14: 3.3492492 | AE14: 3.4092037 | AF14: 1.8588019 | AG14: 2.130245 | AH14: 4.9357865 | AI14: 7.190099 | AK14: 1.9127118 | AL14: 2.2804257 | AM14: 2.2775786 | AN14: 3.1142022 | AO14: 1.5012025 | AP14: 3.3492492 | AQ14: 1.4923652 | AR14: 1.0765884 | AS14: 0.60571621 | AT14: 4.9357865 | AU14: 5.4135304 | AW14: 0.32582642 | AY14: =BB354 -> 9 | AZ14: =AX666 | BA14: =AY666 | BB14: =AZ666 -> 9
... A58: 24 | B58: 160NNN | C58: AutoMPG8 | D58: {acceleration, displacement, weight} | F58: =F710 -> 0 | G58: =G710 -> 1 | H58: =H710 -> 0 | I58: =I710 -> 1 | J58: =J710 -> 0 | K58: =K710 -> 3 | L58: =L710 -> 0 | M58: 1297565.2 | N58: 5590503.8 | O58: 6221150.2 | P58: 962221.8 | Q58: 5738462.6 | R58: 840370 | S58: 6096867.4 | T58: 3530230 | U58: 3882255 | V58: 3234570.4 | W58: 9972709.6 | Y58: 1.6101251 | Z58: 4.6331242 | AA58: 5.0160113 | AB58: 1.5657117 | AC58: 5.4690294 | AD58: 1.1565653 | AE58: 4.4205508 | AF58: 1.4698553 | AG58: 2.5232849 | AH58: 3.7276117 | AI58: 12.096878 | AK58: 1.6101251 | AL58: 1.8149054 | AM58: 2.2133989 | AN58: 1.5657117 | AO58: 2.49095 | AP58: 1.1565653 | AQ58: 1.8549916 | AR58: 0.76345814 | AS58: 0.56937649 | AT58: 3.7276117 | AU58: 8.8627512 | AW58: 0.31212706 | AY58: =BB398 -> -2 | AZ58: =AX710 | BA58: =AY710 -> -2 | BB58: =AZ710
K292: Mean | L292: =X292 -> 1 | M292: BNL | N292: BNL Causal | O292: BNL Causal HM | P292: SFS | Q292: SFS Causal | R292: SaLSa | S292: SaLSa Causal | T292: D&C | U292: D&C Causal | V292: BBS | W292: BBS Causal | X292: 1 | Y292: BNL | Z292: BNL Causal | AA292: BNL Causal HM | AB292: SFS | AC292: SFS Causal | AD292: SaLSa | AE292: SaLSa Causal | AF292: D&C | AG292: D&C Causal | AH292: BBS | AI292: BBS Causal | AJ292: =X292 -> 1 | AK292: BNL | AL292: BNL Causal | AM292: BNL Causal HM | AN292: SFS | AO292: SFS Causal | AP292: SaLSa | AQ292: SaLSa Causal | AR292: D&C | AS292: D&C Causal | AT292: BBS | AU292: BBS Causal
L293: ALL | M293: =AVERAGE(M3:M290) -> 3187319.7 | N293: =AVERAGE(N3:N290) -> 4089398.8 | O293: =AVERAGE(O3:O290) -> 4207584.7 | P293: =AVERAGE(P3:P290) -> 5860348.5 | Q293: =AVERAGE(Q3:Q290) -> 2753765.1 | R293: =AVERAGE(R3:R290) -> 4327424.1 | S293: =AVERAGE(S3:S290) -> 3714315.2 | T293: =AVERAGE(T3:T290) -> 4984023.3 | ... W293: =AVERAGE(W3:W290) -> 4705796.5 | X293: ALL | Y293: =AVERAGE(Y3:Y290) -> 3.0673271 | Z293: =AVERAGE(Z3:Z290) -> 3.5844848 | AA293: =AVERAGE(AA3:AA290) -> 3.6364212 | AB293: =AVERAGE(AB3:AB290) -> 5.2172672 | AC293: =AVERAGE(AC3:AC290) -> 3.0697117 | AD293: =AVERAGE(AD3:AD290) -> 4.1169042 | AE293: =AVERAGE(AE3:AE290) -> 3.6630055 | AF293: =AVERAGE(AF3:AF290) -> 2.6590545 | ... AI293: =AVERAGE(AI3:AI290) -> 6.9373481 | AJ293: =X293 -> ALL | AK293: =AVERAGE(AK3:AK290) -> 3.0673271 | AL293: =AVERAGE(AL3:AL290) -> 1.5565386 | AM293: =AVERAGE(AM3:AM290) -> 1.6178745 | AN293: =AVERAGE(AN3:AN290) -> 5.2172672 | AO293: =AVERAGE(AO3:AO290) -> 1.4409155 | AP293: =AVERAGE(AP3:AP290) -> 4.1169042 | AQ293: =AVERAGE(AQ3:AQ290) -> 1.6889631 | AR293: =AVERAGE(AR3:AR290) -> 1.4503149 | ... AU293: =AVERAGE(AU3:AU290) -> 5.0648244
L294: ="Target; Gain > "&L292 -> Target; Gain > 1 | M294: =AVERAGEIF($AZ3:$AZ290,">"&$X292,M3:M290) -> 1469812.7 | N294: =AVERAGEIF($AZ3:$AZ290,">"&$X292,N3:N290) -> 6192786.1 | O294: =AVERAGEIF($AZ3:$AZ290,">"&$X292,O3:O290) -> 6195472.5 | P294: =AVERAGEIF($AZ3:$AZ290,">"&$X292,P3:P290) -> 3287460.4 | Q294: =AVERAGEIF($AZ3:$AZ290,">"&$X292,Q3:Q290) -> 6591998.6 | R294: =AVERAGEIF($AZ3:$AZ290,">"&$X292,R3:R290) -> 2539103.2 | S294: =AVERAGEIF($AZ3:$AZ290,">"&$X292,S3:S290) -> 8299081.2 | T294: =AVERAGEIF($AZ3:$AZ290,">"&$X292,T3:T290) -> 6021818.5 | ... W294: =AVERAGEIF($AZ3:$AZ290,">"&$X292,W3:W290) -> 11808698 | X294: ="Target; Gain > "&X292 -> Target; Gain > 1 | Y294: =AVERAGEIF($AZ3:$AZ290,">"&$X292,Y3:Y290) -> 1.5157325 | Z294: =AVERAGEIF($AZ3:$AZ290,">"&$X292,Z3:Z290) -> 4.8092755 | AA294: =AVERAGEIF($AZ3:$AZ290,">"&$X292,AA3:AA290) -> 4.7871693 | AB294: =AVERAGEIF($AZ3:$AZ290,">"&$X292,AB3:AB290) -> 1.9937789 | AC294: =AVERAGEIF($AZ3:$AZ290,">"&$X292,AC3:AC290) -> 5.8020739 | AD294: =AVERAGEIF($AZ3:$AZ290,">"&$X292,AD3:AD290) -> 1.8572223 | AE294: =AVERAGEIF($AZ3:$AZ290,">"&$X292,AE3:AE290) -> 6.1741845 | AF294: =AVERAGEIF($AZ3:$AZ290,">"&$X292,AF3:AF290) -> 3.2812832 | ... AI294: =AVERAGEIF($AZ3:$AZ290,">"&$X292,AI3:AI290) -> 12.154943 | AJ294: =X294 -> Target; Gain > 1 | AK294: =AVERAGEIF($AZ3:$AZ290,">"&$X292,AK3:AK290) -> 1.5157325 | AL294: =AVERAGEIF($AZ3:$AZ290,">"&$X292,AL3:AL290) -> 2.3172761 | AM294: =AVERAGEIF($AZ3:$AZ290,">"&$X292,AM3:AM290) -> 2.3059311 | AN294: =AVERAGEIF($AZ3:$AZ290,">"&$X292,AN3:AN290) -> 1.9937789 | AO294: =AVERAGEIF($AZ3:$AZ290,">"&$X292,AO3:AO290) -> 2.836042 | AP294: =AVERAGEIF($AZ3:$AZ290,">"&$X292,AP3:AP290) -> 1.8572223 | AQ294: =AVERAGEIF($AZ3:$AZ290,">"&$X292,AQ3:AQ290) -> 3.1552397 | AR294: =AVERAGEIF($AZ3:$AZ290,">"&$X292,AR3:AR290) -> 1.780155 | ... AU294: =AVERAGEIF($AZ3:$AZ290,">"&$X292,AU3:AU290) -> 9.2020377
L295: ="Gain > "&L292 -> Gain > 1 | M295: =AVERAGEIF($AY3:$AY290,">"&$X292,M3:M290) -> 1726538.2 | N295: =AVERAGEIF($AY3:$AY290,">"&$X292,N3:N290) -> 5293308.6 | O295: =AVERAGEIF($AY3:$AY290,">"&$X292,O3:O290) -> 5323570.1 | P295: =AVERAGEIF($AY3:$AY290,">"&$X292,P3:P290) -> 4044617.6 | Q295: =AVERAGEIF($AY3:$AY290,">"&$X292,Q3:Q290) -> 4550090.1 | R295: =AVERAGEIF($AY3:$AY290,">"&$X292,R3:R290) -> 2993429.2 | S295: =AVERAGEIF($AY3:$AY290,">"&$X292,S3:S290) -> 6308625 | T295: =AVERAGEIF($AY3:$AY290,">"&$X292,T3:T290) -> 6045623.2 | ... W295: =AVERAGEIF($AY3:$AY290,">"&$X292,W3:W290) -> 7994120.8 | X295: ="Gain > "&X292 -> Gain > 1 | Y295: =AVERAGEIF($AY3:$AY290,">"&$X292,Y3:Y290) -> 1.7971716 | Z295: =AVERAGEIF($AY3:$AY290,">"&$X292,Z3:Z290) -> 4.2985762 | AA295: =AVERAGEIF($AY3:$AY290,">"&$X292,AA3:AA290) -> 4.2961622 | AB295: =AVERAGEIF($AY3:$AY290,">"&$X292,AB3:AB290) -> 2.5982987 | AC295: =AVERAGEIF($AY3:$AY290,">"&$X292,AC3:AC290) -> 4.2465818 | AD295: =AVERAGEIF($AY3:$AY290,">"&$X292,AD3:AD290) -> 2.5450116 | AE295: =AVERAGEIF($AY3:$AY290,">"&$X292,AE3:AE290) -> 5.1904128 | AF295: =AVERAGEIF($AY3:$AY290,">"&$X292,AF3:AF290) -> 3.215095 | ... AI295: =AVERAGEIF($AY3:$AY290,">"&$X292,AI3:AI290) -> 9.0898033 | AJ295: =X295 -> Gain > 1 | AK295: =AVERAGEIF($AY3:$AY290,">"&$X292,AK3:AK290) -> 1.7971716 | AL295: =AVERAGEIF($AY3:$AY290,">"&$X292,AL3:AL290) -> 2.1569308 | AM295: =AVERAGEIF($AY3:$AY290,">"&$X292,AM3:AM290) -> 2.1645694 | AN295: =AVERAGEIF($AY3:$AY290,">"&$X292,AN3:AN290) -> 2.5982987 | AO295: =AVERAGEIF($AY3:$AY290,">"&$X292,AO3:AO290) -> 2.138393 | AP295: =AVERAGEIF($AY3:$AY290,">"&$X292,AP3:AP290) -> 2.5450116 | AQ295: =AVERAGEIF($AY3:$AY290,">"&$X292,AQ3:AQ290) -> 2.8835694 | AR295: =AVERAGEIF($AY3:$AY290,">"&$X292,AR3:AR290) -> 1.7512053 | ... AU295: =AVERAGEIF($AY3:$AY290,">"&$X292,AU3:AU290) -> 6.7866549
L296: Target | M296: =AVERAGEIF($H3:$H290,"=1",M3:M290) -> 1550486.5 | N296: =AVERAGEIF($H3:$H290,"=1",N3:N290) -> 5751692.1 | O296: =AVERAGEIF($H3:$H290,"=1",O3:O290) -> 5891483.2 | P296: =AVERAGEIF($H3:$H290,"=1",P3:P290) -> 2636482.4 | Q296: =AVERAGEIF($H3:$H290,"=1",Q3:Q290) -> 4941919.9 | R296: =AVERAGEIF($H3:$H290,"=1",R3:R290) -> 2019735.1 | S296: =AVERAGEIF($H3:$H290,"=1",S3:S290) -> 6264917.8 | T296: =AVERAGEIF($H3:$H290,"=1",T3:T290) -> 4849319.7 | ... W296: =AVERAGEIF($H3:$H290,"=1",W3:W290) -> 8531370.6 | X296: Target | Y296: =AVERAGEIF($H3:$H290,"=1",Y3:Y290) -> 1.7022202 | Z296: =AVERAGEIF($H3:$H290,"=1",Z3:Z290) -> 4.6641918 | AA296: =AVERAGEIF($H3:$H290,"=1",AA3:AA290) -> 4.7217425 | AB296: =AVERAGEIF($H3:$H290,"=1",AB3:AB290) -> 2.4153377 | AC296: =AVERAGEIF($H3:$H290,"=1",AC3:AC290) -> 4.7364089 | AD296: =AVERAGEIF($H3:$H290,"=1",AD3:AD290) -> 2.1873188 | AE296: =AVERAGEIF($H3:$H290,"=1",AE3:AE290) -> 5.1277424 | AF296: =AVERAGEIF($H3:$H290,"=1",AF3:AF290) -> 2.4714135 | ... AI296: =AVERAGEIF($H3:$H290,"=1",AI3:AI290) -> 10.568009 | AJ296: =X296 -> Target | AK296: =AVERAGEIF($H3:$H290,"=1",AK3:AK290) -> 1.7022202 | AL296: =AVERAGEIF($H3:$H290,"=1",AL3:AL290) -> 1.9874221 | AM296: =AVERAGEIF($H3:$H290,"=1",AM3:AM290) -> 2.0607235 | AN296: =AVERAGEIF($H3:$H290,"=1",AN3:AN290) -> 2.4153377 | AO296: =AVERAGEIF($H3:$H290,"=1",AO3:AO290) -> 2.1920483 | AP296: =AVERAGEIF($H3:$H290,"=1",AP3:AP290) -> 2.1873188 | AQ296: =AVERAGEIF($H3:$H290,"=1",AQ3:AQ290) -> 2.2827596 | AR296: =AVERAGEIF($H3:$H290,"=1",AR3:AR290) -> 1.3446887 | ... AU296: =AVERAGEIF($H3:$H290,"=1",AU3:AU290) -> 7.9627221
L297: =X297 -> Gain > 0 | M297: =AVERAGEIF($J3:$J290,"=1",M3:M290) -> 2619749 | N297: =AVERAGEIF($J3:$J290,"=1",N3:N290) -> 4205254 | O297: =AVERAGEIF($J3:$J290,"=1",O3:O290) -> 4251045.6 | P297: =AVERAGEIF($J3:$J290,"=1",P3:P290) -> 4557446.8 | Q297: =AVERAGEIF($J3:$J290,"=1",Q3:Q290) -> 2703124.2 | R297: =AVERAGEIF($J3:$J290,"=1",R3:R290) -> 3485719.8 | S297: =AVERAGEIF($J3:$J290,"=1",S3:S290) -> 3808435.4 | T297: =AVERAGEIF($J3:$J290,"=1",T3:T290) -> 5254952.8 | ... W297: =AVERAGEIF($J3:$J290,"=1",W3:W290) -> 4398355.5 | X297: Gain > 0 | Y297: =AVERAGEIF($J3:$J290,"=1",Y3:Y290) -> 2.6447883 | Z297: =AVERAGEIF($J3:$J290,"=1",Z3:Z290) -> 3.6782902 | AA297: =AVERAGEIF($J3:$J290,"=1",AA3:AA290) -> 3.6855985 | AB297: =AVERAGEIF($J3:$J290,"=1",AB3:AB290) -> 3.7376188 | AC297: =AVERAGEIF($J3:$J290,"=1",AC3:AC290) -> 2.9653474 | AD297: =AVERAGEIF($J3:$J290,"=1",AD3:AD290) -> 3.8444355 | AE297: =AVERAGEIF($J3:$J290,"=1",AE3:AE290) -> 3.9655292 | AF297: =AVERAGEIF($J3:$J290,"=1",AF3:AF290) -> 2.8726106 | ... AI297: =AVERAGEIF($J3:$J290,"=1",AI3:AI290) -> 6.5886765 | AJ297: =X297 -> Gain > 0 | AK297: =AVERAGEIF($J3:$J290,"=1",AK3:AK290) -> 2.6447883 | AL297: =AVERAGEIF($J3:$J290,"=1",AL3:AL290) -> 1.6224119 | AM297: =AVERAGEIF($J3:$J290,"=1",AM3:AM290) -> 1.6408293 | AN297: =AVERAGEIF($J3:$J290,"=1",AN3:AN290) -> 3.7376188 | AO297: =AVERAGEIF($J3:$J290,"=1",AO3:AO290) -> 1.3850179 | AP297: =AVERAGEIF($J3:$J290,"=1",AP3:AP290) -> 3.8444355 | AQ297: =AVERAGEIF($J3:$J290,"=1",AQ3:AQ290) -> 1.8587407 | AR297: =AVERAGEIF($J3:$J290,"=1",AR3:AR290) -> 1.5614119 | ... AU297: =AVERAGEIF($J3:$J290,"=1",AU3:AU290) -> 4.8029165
L298: =X298 -> Gain <=0 | M298: =AVERAGEIF($I3:$I290,"=1",M3:M290) -> 3554571.3 | N298: =AVERAGEIF($I3:$I290,"=1",N3:N290) -> 4014433.7 | O298: =AVERAGEIF($I3:$I290,"=1",O3:O290) -> 4179463 | P298: =AVERAGEIF($I3:$I290,"=1",P3:P290) -> 6703402.5 | Q298: =AVERAGEIF($I3:$I290,"=1",Q3:Q290) -> 2786532.7 | R298: =AVERAGEIF($I3:$I290,"=1",R3:R290) -> 4872056.3 | S298: =AVERAGEIF($I3:$I290,"=1",S3:S290) -> 3653413.8 | T298: =AVERAGEIF($I3:$I290,"=1",T3:T290) -> 4808715.9 | ... W298: =AVERAGEIF($I3:$I290,"=1",W3:W290) -> 4904729 | X298: Gain <=0 | Y298: =AVERAGEIF($I3:$I290,"=1",Y3:Y290) -> 3.3407346 | Z298: =AVERAGEIF($I3:$I290,"=1",Z3:Z290) -> 3.5237872 | AA298: =AVERAGEIF($I3:$I290,"=1",AA3:AA290) -> 3.6046005 | AB298: =AVERAGEIF($I3:$I290,"=1",AB3:AB290) -> 6.1746867 | AC298: =AVERAGEIF($I3:$I290,"=1",AC3:AC290) -> 3.1372416 | AD298: =AVERAGEIF($I3:$I290,"=1",AD3:AD290) -> 4.2932075 | AE298: =AVERAGEIF($I3:$I290,"=1",AE3:AE290) -> 3.4672549 | AF298: =AVERAGEIF($I3:$I290,"=1",AF3:AF290) -> 2.5208712 | ... AI298: =AVERAGEIF($I3:$I290,"=1",AI3:AI290) -> 7.1629592 | AJ298: =X298 -> Gain <=0 | AK298: =AVERAGEIF($I3:$I290,"=1",AK3:AK290) -> 3.3407346 | AL298: =AVERAGEIF($I3:$I290,"=1",AL3:AL290) -> 1.5139147 | AM298: =AVERAGEIF($I3:$I290,"=1",AM3:AM290) -> 1.6030214 | AN298: =AVERAGEIF($I3:$I290,"=1",AN3:AN290) -> 6.1746867 | AO298: =AVERAGEIF($I3:$I290,"=1",AO3:AO290) -> 1.4770846 | AP298: =AVERAGEIF($I3:$I290,"=1",AP3:AP290) -> 4.2932075 | AQ298: =AVERAGEIF($I3:$I290,"=1",AQ3:AQ290) -> 1.579107 | AR298: =AVERAGEIF($I3:$I290,"=1",AR3:AR290) -> 1.3784285 | ... AU298: =AVERAGEIF($I3:$I290,"=1",AU3:AU290) -> 5.2342942
L299: =X299 -> Target;Gain > 1; #pref=2 | M299: =AVERAGEIFS(M3:M290, $H$3:$H$290, "=1",$K3:$K290,"=2",$AY3:$AY290,">"&$X$292) -> #DIV/0! | N299: =AVERAGEIFS(N3:N290, $H$3:$H$290, "=1",$K3:$K290,"=2",$AY3:$AY290,">"&$X$292) -> #DIV/0! | O299: =AVERAGEIFS(O3:O290, $H$3:$H$290, "=1",$K3:$K290,"=2",$AY3:$AY290,">"&$X$292) -> #DIV/0! | P299: =AVERAGEIFS(P3:P290, $H$3:$H$290, "=1",$K3:$K290,"=2",$AY3:$AY290,">"&$X$292) -> #DIV/0! | Q299: =AVERAGEIFS(Q3:Q290, $H$3:$H$290, "=1",$K3:$K290,"=2",$AY3:$AY290,">"&$X$292) -> #DIV/0! | R299: =AVERAGEIFS(R3:R290, $H$3:$H$290, "=1",$K3:$K290,"=2",$AY3:$AY290,">"&$X$292) -> #DIV/0! | S299: =AVERAGEIFS(S3:S290, $H$3:$H$290, "=1",$K3:$K290,"=2",$AY3:$AY290,">"&$X$292) -> #DIV/0! | T299: =AVERAGEIFS(T3:T290, $H$3:$H$290, "=1",$K3:$K290,"=2",$AY3:$AY290,">"&$X$292) -> #DIV/0! | ... W299: =AVERAGEIFS(W3:W290, $H$3:$H$290, "=1",$K3:$K290,"=2",$AY3:$AY290,">"&$X$292) -> #DIV/0! | X299: ="Target;Gain > "&X292&"; #pref=2" -> Target;Gain > 1; #pref=2 | Y299: =AVERAGEIFS(Y3:Y290, $H$3:$H$290, "=1",$K3:$K290,"=2",$AY3:$AY290,">"&$X$292) -> #DIV/0! | Z299: =AVERAGEIFS(Z3:Z290, $H$3:$H$290, "=1",$K3:$K290,"=2",$AY3:$AY290,">"&$X$292) -> #DIV/0! | AA299: =AVERAGEIFS(AA3:AA290, $H$3:$H$290, "=1",$K3:$K290,"=2",$AY3:$AY290,">"&$X$292) -> #DIV/0! | AB299: =AVERAGEIFS(AB3:AB290, $H$3:$H$290, "=1",$K3:$K290,"=2",$AY3:$AY290,">"&$X$292) -> #DIV/0! | AC299: =AVERAGEIFS(AC3:AC290, $H$3:$H$290, "=1",$K3:$K290,"=2",$AY3:$AY290,">"&$X$292) -> #DIV/0! | AD299: =AVERAGEIFS(AD3:AD290, $H$3:$H$290, "=1",$K3:$K290,"=2",$AY3:$AY290,">"&$X$292) -> #DIV/0! | AE299: =AVERAGEIFS(AE3:AE290, $H$3:$H$290, "=1",$K3:$K290,"=2",$AY3:$AY290,">"&$X$292) -> #DIV/0! | AF299: =AVERAGEIFS(AF3:AF290, $H$3:$H$290, "=1",$K3:$K290,"=2",$AY3:$AY290,">"&$X$292) -> #DIV/0! | ... AI299: =AVERAGEIFS(AI3:AI290, $H$3:$H$290, "=1",$K3:$K290,"=2",$AY3:$AY290,">"&$X$292) -> #DIV/0! | AJ299: =X299 -> Target;Gain > 1; #pref=2 | AK299: =AVERAGEIFS(AK3:AK290, $H$3:$H$290, "=1",$K3:$K290,"=2",$AY3:$AY290,">"&$X$292) -> #DIV/0! | AL299: =AVERAGEIFS(AL3:AL290, $H$3:$H$290, "=1",$K3:$K290,"=2",$AY3:$AY290,">"&$X$292) -> #DIV/0! | AM299: =AVERAGEIFS(AM3:AM290, $H$3:$H$290, "=1",$K3:$K290,"=2",$AY3:$AY290,">"&$X$292) -> #DIV/0! | AN299: =AVERAGEIFS(AN3:AN290, $H$3:$H$290, "=1",$K3:$K290,"=2",$AY3:$AY290,">"&$X$292) -> #DIV/0! | AO299: =AVERAGEIFS(AO3:AO290, $H$3:$H$290, "=1",$K3:$K290,"=2",$AY3:$AY290,">"&$X$292) -> #DIV/0! | AP299: =AVERAGEIFS(AP3:AP290, $H$3:$H$290, "=1",$K3:$K290,"=2",$AY3:$AY290,">"&$X$292) -> #DIV/0! | AQ299: =AVERAGEIFS(AQ3:AQ290, $H$3:$H$290, "=1",$K3:$K290,"=2",$AY3:$AY290,">"&$X$292) -> #DIV/0! | AR299: =AVERAGEIFS(AR3:AR290, $H$3:$H$290, "=1",$K3:$K290,"=2",$AY3:$AY290,">"&$X$292) -> #DIV/0! | ... AU299: =AVERAGEIFS(AU3:AU290, $H$3:$H$290, "=1",$K3:$K290,"=2",$AY3:$AY290,">"&$X$292) -> #DIV/0!
L300: =X300 -> Target; Gain > 1; #pref=3 | M300: =AVERAGEIFS(M3:M290, $H$3:$H$290, "=1",$K3:$K290,"=3",$AY3:$AY290,">"&$X$292) -> 1469812.7 | N300: =AVERAGEIFS(N3:N290, $H$3:$H$290, "=1",$K3:$K290,"=3",$AY3:$AY290,">"&$X$292) -> 6192786.1 | O300: =AVERAGEIFS(O3:O290, $H$3:$H$290, "=1",$K3:$K290,"=3",$AY3:$AY290,">"&$X$292) -> 6195472.5 | P300: =AVERAGEIFS(P3:P290, $H$3:$H$290, "=1",$K3:$K290,"=3",$AY3:$AY290,">"&$X$292) -> 3287460.4 | Q300: =AVERAGEIFS(Q3:Q290, $H$3:$H$290, "=1",$K3:$K290,"=3",$AY3:$AY290,">"&$X$292) -> 6591998.6 | R300: =AVERAGEIFS(R3:R290, $H$3:$H$290, "=1",$K3:$K290,"=3",$AY3:$AY290,">"&$X$292) -> 2539103.2 | S300: =AVERAGEIFS(S3:S290, $H$3:$H$290, "=1",$K3:$K290,"=3",$AY3:$AY290,">"&$X$292) -> 8299081.2 | T300: =AVERAGEIFS(T3:T290, $H$3:$H$290, "=1",$K3:$K290,"=3",$AY3:$AY290,">"&$X$292) -> 6021818.5 | ... W300: =AVERAGEIFS(W3:W290, $H$3:$H$290, "=1",$K3:$K290,"=3",$AY3:$AY290,">"&$X$292) -> 11808698 | X300: ="Target; Gain > "&X292&"; #pref=3" -> Target; Gain > 1; #pref=3 | Y300: =AVERAGEIFS(Y3:Y290, $H$3:$H$290, "=1",$K3:$K290,"=3",$AY3:$AY290,">"&$X$292) -> 1.5157325 | Z300: =AVERAGEIFS(Z3:Z290, $H$3:$H$290, "=1",$K3:$K290,"=3",$AY3:$AY290,">"&$X$292) -> 4.8092755 | AA300: =AVERAGEIFS(AA3:AA290, $H$3:$H$290, "=1",$K3:$K290,"=3",$AY3:$AY290,">"&$X$292) -> 4.7871693 | AB300: =AVERAGEIFS(AB3:AB290, $H$3:$H$290, "=1",$K3:$K290,"=3",$AY3:$AY290,">"&$X$292) -> 1.9937789 | AC300: =AVERAGEIFS(AC3:AC290, $H$3:$H$290, "=1",$K3:$K290,"=3",$AY3:$AY290,">"&$X$292) -> 5.8020739 | AD300: =AVERAGEIFS(AD3:AD290, $H$3:$H$290, "=1",$K3:$K290,"=3",$AY3:$AY290,">"&$X$292) -> 1.8572223 | AE300: =AVERAGEIFS(AE3:AE290, $H$3:$H$290, "=1",$K3:$K290,"=3",$AY3:$AY290,">"&$X$292) -> 6.1741845 | AF300: =AVERAGEIFS(AF3:AF290, $H$3:$H$290, "=1",$K3:$K290,"=3",$AY3:$AY290,">"&$X$292) -> 3.2812832 | ... AI300: =AVERAGEIFS(AI3:AI290, $H$3:$H$290, "=1",$K3:$K290,"=3",$AY3:$AY290,">"&$X$292) -> 12.154943 | AJ300: =X300 -> Target; Gain > 1; #pref=3 | AK300: =AVERAGEIFS(AK3:AK290, $H$3:$H$290, "=1",$K3:$K290,"=3",$AY3:$AY290,">"&$X$292) -> 1.5157325 | AL300: =AVERAGEIFS(AL3:AL290, $H$3:$H$290, "=1",$K3:$K290,"=3",$AY3:$AY290,">"&$X$292) -> 2.3172761 | AM300: =AVERAGEIFS(AM3:AM290, $H$3:$H$290, "=1",$K3:$K290,"=3",$AY3:$AY290,">"&$X$292) -> 2.3059311 | AN300: =AVERAGEIFS(AN3:AN290, $H$3:$H$290, "=1",$K3:$K290,"=3",$AY3:$AY290,">"&$X$292) -> 1.9937789 | AO300: =AVERAGEIFS(AO3:AO290, $H$3:$H$290, "=1",$K3:$K290,"=3",$AY3:$AY290,">"&$X$292) -> 2.836042 | AP300: =AVERAGEIFS(AP3:AP290, $H$3:$H$290, "=1",$K3:$K290,"=3",$AY3:$AY290,">"&$X$292) -> 1.8572223 | AQ300: =AVERAGEIFS(AQ3:AQ290, $H$3:$H$290, "=1",$K3:$K290,"=3",$AY3:$AY290,">"&$X$292) -> 3.1552397 | AR300: =AVERAGEIFS(AR3:AR290, $H$3:$H$290, "=1",$K3:$K290,"=3",$AY3:$AY290,">"&$X$292) -> 1.780155 | ... AU300: =AVERAGEIFS(AU3:AU290, $H$3:$H$290, "=1",$K3:$K290,"=3",$AY3:$AY290,">"&$X$292) -> 9.2020377
L301: =X301 -> Target; Gain > 1; #pref=4 | M301: =AVERAGEIFS(M3:M290, $H$3:$H$290, "=1",$K3:$K290,"=4",$AY3:$AY290,">"&$X$292) -> #DIV/0! | N301: =AVERAGEIFS(N3:N290, $H$3:$H$290, "=1",$K3:$K290,"=4",$AY3:$AY290,">"&$X$292) -> #DIV/0! | O301: =AVERAGEIFS(O3:O290, $H$3:$H$290, "=1",$K3:$K290,"=4",$AY3:$AY290,">"&$X$292) -> #DIV/0! | P301: =AVERAGEIFS(P3:P290, $H$3:$H$290, "=1",$K3:$K290,"=4",$AY3:$AY290,">"&$X$292) -> #DIV/0! | Q301: =AVERAGEIFS(Q3:Q290, $H$3:$H$290, "=1",$K3:$K290,"=4",$AY3:$AY290,">"&$X$292) -> #DIV/0! | R301: =AVERAGEIFS(R3:R290, $H$3:$H$290, "=1",$K3:$K290,"=4",$AY3:$AY290,">"&$X$292) -> #DIV/0! | S301: =AVERAGEIFS(S3:S290, $H$3:$H$290, "=1",$K3:$K290,"=4",$AY3:$AY290,">"&$X$292) -> #DIV/0! | T301: =AVERAGEIFS(T3:T290, $H$3:$H$290, "=1",$K3:$K290,"=4",$AY3:$AY290,">"&$X$292) -> #DIV/0! | ... W301: =AVERAGEIFS(W3:W290, $H$3:$H$290, "=1",$K3:$K290,"=4",$AY3:$AY290,">"&$X$292) -> #DIV/0! | X301: ="Target; Gain > "&X292&"; #pref=4" -> Target; Gain > 1; #pref=4 | Y301: =AVERAGEIFS(Y3:Y290, $H$3:$H$290, "=1",$K3:$K290,"=4",$AY3:$AY290,">"&$X$292) -> #DIV/0! | Z301: =AVERAGEIFS(Z3:Z290, $H$3:$H$290, "=1",$K3:$K290,"=4",$AY3:$AY290,">"&$X$292) -> #DIV/0! | AA301: =AVERAGEIFS(AA3:AA290, $H$3:$H$290, "=1",$K3:$K290,"=4",$AY3:$AY290,">"&$X$292) -> #DIV/0! | AB301: =AVERAGEIFS(AB3:AB290, $H$3:$H$290, "=1",$K3:$K290,"=4",$AY3:$AY290,">"&$X$292) -> #DIV/0! | AC301: =AVERAGEIFS(AC3:AC290, $H$3:$H$290, "=1",$K3:$K290,"=4",$AY3:$AY290,">"&$X$292) -> #DIV/0! | AD301: =AVERAGEIFS(AD3:AD290, $H$3:$H$290, "=1",$K3:$K290,"=4",$AY3:$AY290,">"&$X$292) -> #DIV/0! | AE301: =AVERAGEIFS(AE3:AE290, $H$3:$H$290, "=1",$K3:$K290,"=4",$AY3:$AY290,">"&$X$292) -> #DIV/0! | AF301: =AVERAGEIFS(AF3:AF290, $H$3:$H$290, "=1",$K3:$K290,"=4",$AY3:$AY290,">"&$X$292) -> #DIV/0! | ... AI301: =AVERAGEIFS(AI3:AI290, $H$3:$H$290, "=1",$K3:$K290,"=4",$AY3:$AY290,">"&$X$292) -> #DIV/0! | AJ301: =X301 -> Target; Gain > 1; #pref=4 | AK301: =AVERAGEIFS(AK3:AK290, $H$3:$H$290, "=1",$K3:$K290,"=4",$AY3:$AY290,">"&$X$292) -> #DIV/0! | AL301: =AVERAGEIFS(AL3:AL290, $H$3:$H$290, "=1",$K3:$K290,"=4",$AY3:$AY290,">"&$X$292) -> #DIV/0! | AM301: =AVERAGEIFS(AM3:AM290, $H$3:$H$290, "=1",$K3:$K290,"=4",$AY3:$AY290,">"&$X$292) -> #DIV/0! | AN301: =AVERAGEIFS(AN3:AN290, $H$3:$H$290, "=1",$K3:$K290,"=4",$AY3:$AY290,">"&$X$292) -> #DIV/0! | AO301: =AVERAGEIFS(AO3:AO290, $H$3:$H$290, "=1",$K3:$K290,"=4",$AY3:$AY290,">"&$X$292) -> #DIV/0! | AP301: =AVERAGEIFS(AP3:AP290, $H$3:$H$290, "=1",$K3:$K290,"=4",$AY3:$AY290,">"&$X$292) -> #DIV/0! | AQ301: =AVERAGEIFS(AQ3:AQ290, $H$3:$H$290, "=1",$K3:$K290,"=4",$AY3:$AY290,">"&$X$292) -> #DIV/0! | AR301: =AVERAGEIFS(AR3:AR290, $H$3:$H$290, "=1",$K3:$K290,"=4",$AY3:$AY290,">"&$X$292) -> #DIV/0! | ... AU301: =AVERAGEIFS(AU3:AU290, $H$3:$H$290, "=1",$K3:$K290,"=4",$AY3:$AY290,">"&$X$292) -> #DIV/0!
L302: =X302 -> Target; Gain > 0 | M302: =AVERAGEIFS(M3:M290,$H3:$H290,"=1",$J3:$J290,"=1") -> 1592702.5 | N302: =AVERAGEIFS(N3:N290,$H3:$H290,"=1",$J3:$J290,"=1") -> 5741799.3 | O302: =AVERAGEIFS(O3:O290,$H3:$H290,"=1",$J3:$J290,"=1") -> 5761606.7 | P302: =AVERAGEIFS(P3:P290,$H3:$H290,"=1",$J3:$J290,"=1") -> 2924714.2 | Q302: =AVERAGEIFS(Q3:Q290,$H3:$H290,"=1",$J3:$J290,"=1") -> 4717657 | R302: =AVERAGEIFS(R3:R290,$H3:$H290,"=1",$J3:$J290,"=1") -> 2242817 | S302: =AVERAGEIFS(S3:S290,$H3:$H290,"=1",$J3:$J290,"=1") -> 6244040.1 | T302: =AVERAGEIFS(T3:T290,$H3:$H290,"=1",$J3:$J290,"=1") -> 5196206.4 | ... W302: =AVERAGEIFS(W3:W290,$H3:$H290,"=1",$J3:$J290,"=1") -> 7974979.3 | X302: Target; Gain > 0 | Y302: =AVERAGEIFS(Y3:Y290,$H3:$H290,"=1",$J3:$J290,"=1") -> 1.6984324 | Z302: =AVERAGEIFS(Z3:Z290,$H3:$H290,"=1",$J3:$J290,"=1") -> 4.6291565 | AA302: =AVERAGEIFS(AA3:AA290,$H3:$H290,"=1",$J3:$J290,"=1") -> 4.6101984 | AB302: =AVERAGEIFS(AB3:AB290,$H3:$H290,"=1",$J3:$J290,"=1") -> 2.454108 | AC302: =AVERAGEIFS(AC3:AC290,$H3:$H290,"=1",$J3:$J290,"=1") -> 4.4363186 | AD302: =AVERAGEIFS(AD3:AD290,$H3:$H290,"=1",$J3:$J290,"=1") -> 2.4043747 | AE302: =AVERAGEIFS(AE3:AE290,$H3:$H290,"=1",$J3:$J290,"=1") -> 5.2924865 | AF302: =AVERAGEIFS(AF3:AF290,$H3:$H290,"=1",$J3:$J290,"=1") -> 2.7414597 | ... AI302: =AVERAGEIFS(AI3:AI290,$H3:$H290,"=1",$J3:$J290,"=1") -> 9.9671584 | AJ302: =X302 -> Target; Gain > 0 | AK302: =AVERAGEIFS(AK3:AK290,$H3:$H290,"=1",$J3:$J290,"=1") -> 1.6984324 | AL302: =AVERAGEIFS(AL3:AL290,$H3:$H290,"=1",$J3:$J290,"=1") -> 2.0121656 | AM302: =AVERAGEIFS(AM3:AM290,$H3:$H290,"=1",$J3:$J290,"=1") -> 2.0096655 | AN302: =AVERAGEIFS(AN3:AN290,$H3:$H290,"=1",$J3:$J290,"=1") -> 2.454108 | AO302: =AVERAGEIFS(AO3:AO290,$H3:$H290,"=1",$J3:$J290,"=1") -> 2.0383157 | AP302: =AVERAGEIFS(AP3:AP290,$H3:$H290,"=1",$J3:$J290,"=1") -> 2.4043747 | AQ302: =AVERAGEIFS(AQ3:AQ290,$H3:$H290,"=1",$J3:$J290,"=1") -> 2.4070803 | AR302: =AVERAGEIFS(AR3:AR290,$H3:$H290,"=1",$J3:$J290,"=1") -> 1.5000828 | ... AU302: =AVERAGEIFS(AU3:AU290,$H3:$H290,"=1",$J3:$J290,"=1") -> 7.5752384
L303: =X303 -> Target; Gain <= 0 | M303: =AVERAGEIFS(M3:M290,$H3:$H290,"=1",$J3:$J290,"=0") -> 1381622.7 | N303: =AVERAGEIFS(N3:N290,$H3:$H290,"=1",$J3:$J290,"=0") -> 5791263.1 | O303: =AVERAGEIFS(O3:O290,$H3:$H290,"=1",$J3:$J290,"=0") -> 6410989.6 | P303: =AVERAGEIFS(P3:P290,$H3:$H290,"=1",$J3:$J290,"=0") -> 1483555.3 | Q303: =AVERAGEIFS(Q3:Q290,$H3:$H290,"=1",$J3:$J290,"=0") -> 5838971.6 | R303: =AVERAGEIFS(R3:R290,$H3:$H290,"=1",$J3:$J290,"=0") -> 1127407.6 | S303: =AVERAGEIFS(S3:S290,$H3:$H290,"=1",$J3:$J290,"=0") -> 6348428.6 | T303: =AVERAGEIFS(T3:T290,$H3:$H290,"=1",$J3:$J290,"=0") -> 3461772.8 | ... W303: =AVERAGEIFS(W3:W290,$H3:$H290,"=1",$J3:$J290,"=0") -> 10756936 | X303: Target; Gain <= 0 | Y303: =AVERAGEIFS(Y3:Y290,$H3:$H290,"=1",$J3:$J290,"=0") -> 1.7173715 | Z303: =AVERAGEIFS(Z3:Z290,$H3:$H290,"=1",$J3:$J290,"=0") -> 4.804333 | AA303: =AVERAGEIFS(AA3:AA290,$H3:$H290,"=1",$J3:$J290,"=0") -> 5.1679186 | AB303: =AVERAGEIFS(AB3:AB290,$H3:$H290,"=1",$J3:$J290,"=0") -> 2.2602566 | AC303: =AVERAGEIFS(AC3:AC290,$H3:$H290,"=1",$J3:$J290,"=0") -> 5.93677 | AD303: =AVERAGEIFS(AD3:AD290,$H3:$H290,"=1",$J3:$J290,"=0") -> 1.3190952 | AE303: =AVERAGEIFS(AE3:AE290,$H3:$H290,"=1",$J3:$J290,"=0") -> 4.4687658 | AF303: =AVERAGEIFS(AF3:AF290,$H3:$H290,"=1",$J3:$J290,"=0") -> 1.391229 | ... AI303: =AVERAGEIFS(AI3:AI290,$H3:$H290,"=1",$J3:$J290,"=0") -> 12.97141 | AJ303: =X303 -> Target; Gain <= 0 | AK303: =AVERAGEIFS(AK3:AK290,$H3:$H290,"=1",$J3:$J290,"=0") -> 1.7173715 | AL303: =AVERAGEIFS(AL3:AL290,$H3:$H290,"=1",$J3:$J290,"=0") -> 1.8884481 | AM303: =AVERAGEIFS(AM3:AM290,$H3:$H290,"=1",$J3:$J290,"=0") -> 2.2649555 | AN303: =AVERAGEIFS(AN3:AN290,$H3:$H290,"=1",$J3:$J290,"=0") -> 2.2602566 | AO303: =AVERAGEIFS(AO3:AO290,$H3:$H290,"=1",$J3:$J290,"=0") -> 2.8069785 | AP303: =AVERAGEIFS(AP3:AP290,$H3:$H290,"=1",$J3:$J290,"=0") -> 1.3190952 | AQ303: =AVERAGEIFS(AQ3:AQ290,$H3:$H290,"=1",$J3:$J290,"=0") -> 1.7854772 | AR303: =AVERAGEIFS(AR3:AR290,$H3:$H290,"=1",$J3:$J290,"=0") -> 0.72311219 | ... AU303: =AVERAGEIFS(AU3:AU290,$H3:$H290,"=1",$J3:$J290,"=0") -> 9.5126567
L304: =L292 -> 1 | N304: =N292 -> BNL Causal | O304: =O292 -> BNL Causal HM | P304: =Q292 -> SFS Causal | Q304: =S292 -> SaLSa Causal | R304: =U292 -> D&C Causal | S304: =W292 -> BBS Causal | U304: =X292 -> 1 | V304: =Z292 -> BNL Causal | W304: =AA292 -> BNL Causal HM | X304: =AC292 -> SFS Causal | Y304: =AE292 -> SaLSa Causal | Z304: =AG292 -> D&C Causal | AA304: =AI292 -> BBS Causal | AC304: =AJ292 -> 1 | AD304: =AL292 -> BNL Causal | AE304: =AM292 -> BNL Causal HM | AF304: =AO292 -> SFS Causal | AG304: =AQ292 -> SaLSa Causal | AH304: =AS292 -> D&C Causal | AI304: =AU292 -> BBS Causal
L305: =L293 -> ALL | N305: =N293 -> 4089398.8 | O305: =O293 -> 4207584.7 | P305: =Q293 -> 2753765.1 | Q305: =S293 -> 3714315.2 | R305: =U293 -> 4098146.3 | S305: =W293 -> 4705796.5 | U305: =X293 -> ALL | V305: =Z293 -> 3.5844848 | W305: =AA293 -> 3.6364212 | X305: =AC293 -> 3.0697117 | Y305: =AE293 -> 3.6630055 | Z305: =AG293 -> 2.7685057 | AA305: =AI293 -> 6.9373481 | AC305: =AJ293 -> ALL | AD305: =AL293 -> 1.5565386 | AE305: =AM293 -> 1.6178745 | AF305: =AO293 -> 1.4409155 | AG305: =AQ293 -> 1.6889631 | AH305: =AS293 -> 0.6514477 | AI305: =AU293 -> 5.0648244
L306: =L295 -> Gain > 1 | N306: =N295 -> 5293308.6 | O306: =O295 -> 5323570.1 | P306: =Q295 -> 4550090.1 | Q306: =S295 -> 6308625 | R306: =U295 -> 4202403.5 | S306: =W295 -> 7994120.8 | U306: =X295 -> Gain > 1 | V306: =Z295 -> 4.2985762 | W306: =AA295 -> 4.2961622 | X306: =AC295 -> 4.2465818 | Y306: =AE295 -> 5.1904128 | Z306: =AG295 -> 2.6457152 | AA306: =AI295 -> 9.0898033 | AC306: =AJ295 -> Gain > 1 | AD306: =AL295 -> 2.1569308 | AE306: =AM295 -> 2.1645694 | AF306: =AO295 -> 2.138393 | AG306: =AQ295 -> 2.8835694 | AH306: =AS295 -> 0.63328844 | AI306: =AU295 -> 6.7866549
L307: =L296 -> Target | N307: =N296 -> 5751692.1 | O307: =O296 -> 5891483.2 | P307: =Q296 -> 4941919.9 | Q307: =S296 -> 6264917.8 | R307: =U296 -> 4167436.2 | S307: =W296 -> 8531370.6 | U307: =X296 -> Target | V307: =Z296 -> 4.6641918 | W307: =AA296 -> 4.7217425 | X307: =AC296 -> 4.7364089 | Y307: =AE296 -> 5.1277424 | Z307: =AG296 -> 2.7783098 | AA307: =AI296 -> 10.568009 | AC307: =AJ296 -> Target | AD307: =AL296 -> 1.9874221 | AE307: =AM296 -> 2.0607235 | AF307: =AO296 -> 2.1920483 | AG307: =AQ296 -> 2.2827596 | AH307: =AS296 -> 0.64424928 | AI307: =AU296 -> 7.9627221
L308: =L297 -> Gain > 0 | N308: =N297 -> 4205254 | O308: =O297 -> 4251045.6 | P308: =Q297 -> 2703124.2 | Q308: =S297 -> 3808435.4 | R308: =U297 -> 4145313.5 | S308: =W297 -> 4398355.5 | U308: =X297 -> Gain > 0 | V308: =Z297 -> 3.6782902 | W308: =AA297 -> 3.6855985 | X308: =AC297 -> 2.9653474 | Y308: =AE297 -> 3.9655292 | Z308: =AG297 -> 2.8306854 | AA308: =AI297 -> 6.5886765 | AC308: =AJ297 -> Gain > 0 | AD308: =AL297 -> 1.6224119 | AE308: =AM297 -> 1.6408293 | AF308: =AO297 -> 1.3850179 | AG308: =AQ297 -> 1.8587407 | AH308: =AS297 -> 0.67807267 | AI308: =AU297 -> 4.8029165
L309: =L298 -> Gain <=0 | N309: =N298 -> 4014433.7 | O309: =O298 -> 4179463 | P309: =Q298 -> 2786532.7 | Q309: =S298 -> 3653413.8 | R309: =U298 -> 4067626.4 | S309: =W298 -> 4904729 | U309: =X298 -> Gain <=0 | V309: =Z298 -> 3.5237872 | W309: =AA298 -> 3.6046005 | X309: =AC298 -> 3.1372416 | Y309: =AE298 -> 3.4672549 | Z309: =AG298 -> 2.7282717 | AA309: =AI298 -> 7.1629592 | AC309: =AJ298 -> Gain <=0 | AD309: =AL298 -> 1.5139147 | AE309: =AM298 -> 1.6030214 | AF309: =AO298 -> 1.4770846 | AG309: =AQ298 -> 1.579107 | AH309: =AS298 -> 0.63421979 | AI309: =AU298 -> 5.2342942
L310: =L299 -> Target;Gain > 1; #pref=2 | N310: =N299 -> #DIV/0! | O310: =O299 -> #DIV/0! | P310: =Q299 -> #DIV/0! | Q310: =S299 -> #DIV/0! | R310: =U299 -> #DIV/0! | S310: =W299 -> #DIV/0! | U310: =X299 -> Target;Gain > 1; #pref=2 | V310: =Z299 -> #DIV/0! | W310: =AA299 -> #DIV/0! | X310: =AC299 -> #DIV/0! | Y310: =AE299 -> #DIV/0! | Z310: =AG299 -> #DIV/0! | AA310: =AI299 -> #DIV/0! | AC310: =AJ299 -> Target;Gain > 1; #pref=2 | AD310: =AL299 -> #DIV/0! | AE310: =AM299 -> #DIV/0! | AF310: =AO299 -> #DIV/0! | AG310: =AQ299 -> #DIV/0! | AH310: =AS299 -> #DIV/0! | AI310: =AU299 -> #DIV/0!
L311: =L300 -> Target; Gain > 1; #pref=3 | N311: =N300 -> 6192786.1 | O311: =O300 -> 6195472.5 | P311: =Q300 -> 6591998.6 | Q311: =S300 -> 8299081.2 | R311: =U300 -> 4301928.3 | S311: =W300 -> 11808698 | U311: =X300 -> Target; Gain > 1; #pref=3 | V311: =Z300 -> 4.8092755 | W311: =AA300 -> 4.7871693 | X311: =AC300 -> 5.8020739 | Y311: =AE300 -> 6.1741845 | Z311: =AG300 -> 2.7521729 | AA311: =AI300 -> 12.154943 | AC311: =AJ300 -> Target; Gain > 1; #pref=3 | AD311: =AL300 -> 2.3172761 | AE311: =AM300 -> 2.3059311 | AF311: =AO300 -> 2.836042 | AG311: =AQ300 -> 3.1552397 | AH311: =AS300 -> 0.63259933 | AI311: =AU300 -> 9.2020377
L312: =L301 -> Target; Gain > 1; #pref=4 | N312: =N301 -> #DIV/0! | O312: =O301 -> #DIV/0! | P312: =Q301 -> #DIV/0! | Q312: =S301 -> #DIV/0! | R312: =U301 -> #DIV/0! | S312: =W301 -> #DIV/0! | U312: =X301 -> Target; Gain > 1; #pref=4 | V312: =Z301 -> #DIV/0! | W312: =AA301 -> #DIV/0! | X312: =AC301 -> #DIV/0! | Y312: =AE301 -> #DIV/0! | Z312: =AG301 -> #DIV/0! | AA312: =AI301 -> #DIV/0! | AC312: =AJ301 -> Target; Gain > 1; #pref=4 | AD312: =AL301 -> #DIV/0! | AE312: =AM301 -> #DIV/0! | AF312: =AO301 -> #DIV/0! | AG312: =AQ301 -> #DIV/0! | AH312: =AS301 -> #DIV/0! | AI312: =AU301 -> #DIV/0!
L313: =L302 -> Target; Gain > 0 | N313: =N302 -> 5741799.3 | O313: =O302 -> 5761606.7 | P313: =Q302 -> 4717657 | Q313: =S302 -> 6244040.1 | R313: =U302 -> 4240417.5 | S313: =W302 -> 7974979.3 | U313: =X302 -> Target; Gain > 0 | V313: =Z302 -> 4.6291565 | W313: =AA302 -> 4.6101984 | X313: =AC302 -> 4.4363186 | Y313: =AE302 -> 5.2924865 | Z313: =AG302 -> 2.8473697 | AA313: =AI302 -> 9.9671584 | AC313: =AJ302 -> Target; Gain > 0 | AD313: =AL302 -> 2.0121656 | AE313: =AM302 -> 2.0096655 | AF313: =AO302 -> 2.0383157 | AG313: =AQ302 -> 2.4070803 | AH313: =AS302 -> 0.66396901 | AI313: =AU302 -> 7.5752384
L314: =L303 -> Target; Gain <= 0 | N314: =N303 -> 5791263.1 | O314: =O303 -> 6410989.6 | P314: =Q303 -> 5838971.6 | Q314: =S303 -> 6348428.6 | R314: =U303 -> 3875510.9 | S314: =W303 -> 10756936 | U314: =X303 -> Target; Gain <= 0 | V314: =Z303 -> 4.804333 | W314: =AA303 -> 5.1679186 | X314: =AC303 -> 5.93677 | Y314: =AE303 -> 4.4687658 | Z314: =AG303 -> 2.5020702 | AA314: =AI303 -> 12.97141 | AC314: =AJ303 -> Target; Gain <= 0 | AD314: =AL303 -> 1.8884481 | AE314: =AM303 -> 2.2649555 | AF314: =AO303 -> 2.8069785 | AG314: =AQ303 -> 1.7854772 | AH314: =AS303 -> 0.56537033 | AI314: =AU303 -> 9.5126567
K316: Median | L316: =X316 -> 1 | M316: BNL | N316: BNL Causal | O316: BNL Causal HM | P316: SFS | Q316: SFS Causal | R316: SaLSa | S316: SaLSa Causal | T316: D&C | U316: D&C Causal | V316: BBS | W316: BBS Causal | X316: =X292 -> 1 | Y316: BNL | Z316: BNL Causal | AA316: BNL Causal HM | AB316: SFS | AC316: SFS Causal | AD316: SaLSa | AE316: SaLSa Causal | AF316: D&C | AG316: D&C Causal | AH316: BBS | AI316: BBS Causal | AJ316: =X316 -> 1 | AK316: BNL | AL316: BNL Causal | AM316: BNL Causal HM | AN316: SFS | AO316: SFS Causal | AP316: SaLSa | AQ316: SaLSa Causal | AR316: D&C | AS316: D&C Causal | AT316: BBS | AU316: BBS Causal
L317: ALL | M317: =MEDIAN(M3:M290) -> 2180548 | N317: =MEDIAN(N3:N290) -> 3060343.4 | O317: =MEDIAN(O3:O290) -> 3211864.2 | P317: =MEDIAN(P3:P290) -> 2559623.8 | Q317: =MEDIAN(Q3:Q290) -> 1386496.5 | R317: =MEDIAN(R3:R290) -> 1762039.3 | S317: =MEDIAN(S3:S290) -> 2207585.9 | T317: =MEDIAN(T3:T290) -> 4576408.6 | ... W317: =MEDIAN(W3:W290) -> 2662738.6 | X317: ALL | Y317: =MEDIAN(Y3:Y290) -> 2.1405852 | Z317: =MEDIAN(Z3:Z290) -> 2.9889093 | AA317: =MEDIAN(AA3:AA290) -> 3.0582395 | AB317: =MEDIAN(AB3:AB290) -> 3.0161237 | AC317: =MEDIAN(AC3:AC290) -> 2.1178034 | AD317: =MEDIAN(AD3:AD290) -> 2.8067755 | AE317: =MEDIAN(AE3:AE290) -> 3.0346673 | AF317: =MEDIAN(AF3:AF290) -> 2.1076149 | ... AI317: =MEDIAN(AI3:AI290) -> 4.9519443 | AJ317: =X317 -> ALL | AK317: =MEDIAN(AK3:AK290) -> 2.1405852 | AL317: =MEDIAN(AL3:AL290) -> 1.219462 | AM317: =MEDIAN(AM3:AM290) -> 1.2424446 | AN317: =MEDIAN(AN3:AN290) -> 3.0161237 | AO317: =MEDIAN(AO3:AO290) -> 0.98297487 | AP317: =MEDIAN(AP3:AP290) -> 2.8067755 | AQ317: =MEDIAN(AQ3:AQ290) -> 1.2459795 | AR317: =MEDIAN(AR3:AR290) -> 1.1960808 | ... AU317: =MEDIAN(AU3:AU290) -> 3.3701771
...

Sheet ddSky
M1: Average Benchmark (results) | Y1: Average Benchmark (sequential timing) | AK1: Average Benchmark (parallel timing) | AW1: Average Benchmark (cluster_time)
F2: =F654 -> TargetN | G2: =G654 -> #N | H2: =H654 -> Target (or sym) | I2: =I654 -> Gain <=0 | J2: =J654 -> Gain > 0 | K2: =K654 -> Pref | L2: =L654 -> Pref&Target | M2: BNL | N2: BNL Causal | O2: BNL Causal HM | P2: SFS | Q2: SFS Causal | R2: SaLSa | S2: SaLSa Causal | T2: D&C | U2: D&C Causal | V2: BBS | W2: BBS Causal | Y2: BNL | Z2: BNL Causal | AA2: BNL Causal HM | AB2: SFS | AC2: SFS Causal | AD2: SaLSa | AE2: SaLSa Causal | AF2: D&C | AG2: D&C Causal | AH2: BBS | AI2: BBS Causal | AK2: BNL | AL2: BNL Causal | AM2: BNL Causal HM | AN2: SFS | AO2: SFS Causal | AP2: SaLSa | AQ2: SaLSa Causal | AR2: D&C | AS2: D&C Causal | AT2: BBS | AU2: BBS Causal | AW2: KMeans Time (seconds) | AY2: Gain | AZ2: =AX654 -> Target (or sym) ; Gain | BA2: =AY654 -> Gain<=0 | BB2: =AZ654 -> Gain>0
A3: 21 | B3: 156XXXX | C3: Hong_Kong_Weather_3 | D3: {cloud, mean_wet_bulb_temp, rainfall, rel_humidity} | F3: =F655 -> 0 | G3: =G655 -> 0 | H3: =H655 -> 1 | I3: =I655 -> 0 | J3: =J655 -> 1 | K3: =K655 -> 4 | L3: =L655 -> 4 | M3: 984737.8 | N3: 960358.2 | O3: 966104.4 | P3: 1004122.8 | Q3: 526322.4 | R3: 881239.4 | S3: 498280.6 | T3: 4185627.2 | U3: 3248337 | V3: 1396199.2 | W3: 683000.6 | Y3: 1.3606764 | Z3: 1.2250381 | AA3: 1.2279604 | AB3: 1.5873544 | AC3: 1.1102329 | AD3: 1.0896572 | AE3: 0.99696266 | AF3: 1.5469538 | AG3: 1.7846374 | AH3: 3.0141519 | AI3: 2.1209856 | AK3: 1.3606764 | AL3: 0.47553392 | AM3: 0.47491337 | AN3: 1.5873544 | AO3: 0.44433777 | AP3: 1.0896572 | AQ3: 0.47247157 | AR3: 0.99082058 | AS3: 0.41631974 | AT3: 3.0141519 | AU3: 1.233718 | AW3: 0.23467779 | AY3: =BB343 -> 1.2118474 | AZ3: =AX655 -> 1.2118474 | BA3: =AY655 | BB3: =AZ655 -> 1.2118474
A4: 21 | B4: 156XXXN | C4: Hong_Kong_Weather_3 | D4: {cloud, mean_wet_bulb_temp, rainfall, rel_humidity} | F4: =F656 -> 0 | G4: =G656 -> 1 | H4: =H656 -> 0 | I4: =I656 -> 0 | J4: =J656 -> 1 | K4: =K656 -> 4 | L4: =L656 -> 0 | M4: 9774060 | N4: 13818161 | O4: 14137645 | P4: 14747945 | Q4: 9570418.2 | R4: 16571915 | S4: 13698325 | T4: 4907318.2 | U4: 5798741.8 | V4: 21091677 | W4: 11917550 | Y4: 8.3166493 | Z4: 8.7507995 | AA4: 8.9644208 | AB4: 7.8668887 | AC4: 4.9311816 | AD4: 11.400884 | AE4: 8.1417487 | AF4: 2.228114 | AG4: 4.3242318 | AH4: 8.3582562 | AI4: 14.399415 | AK4: 8.3166493 | AL4: 2.3210219 | AM4: 2.4852839 | AN4: 7.8668887 | AO4: 1.3239221 | AP4: 11.400884 | AQ4: 1.8852352 | AR4: 1.2550528 | AS4: 0.67594495 | AT4: 8.3582562 | AU4: 10.698788 | AW4: 0.23589923 | AY4: =BB344 -> 0.23396082 | AZ4: =AX656 | BA4: =AY656 | BB4: =AZ656 -> 0.23396082
A5: 21 | B5: 156XXNX | C5: Hong_Kong_Weather_3 | D5: {cloud, mean_wet_bulb_temp, rainfall, rel_humidity} | F5: =F657 -> 0 | G5: =G657 -> 1 | H5: =H657 -> 0 | I5: =I657 -> 0 | J5: =J657 -> 1 | K5: =K657 -> 4 | L5: =L657 -> 0 | M5: 4329316.4 | N5: 2706492.4 | O5: 2732101.4 | P5: 1278792.2 | Q5: 783558.6 | R5: 616378.2 | S5: 549719.2 | T5: 4215981.4 | U5: 3282981.6 | V5: 2636300 | W5: 600531.8 | Y5: 3.8467037 | Z5: 2.4386925 | AA5: 2.4347142 | AB5: 2.3330707 | AC5: 1.4544381 | AD5: 1.7481598 | AE5: 1.6602619 | AF5: 1.5988485 | AG5: 1.7857571 | AH5: 3.7020388 | AI5: 2.6315229 | AK5: 3.8467037 | AL5: 0.86808971 | AM5: 0.87342877 | AN5: 2.3330707 | AO5: 0.58530431 | AP5: 1.7481598 | AQ5: 0.53801226 | AR5: 1.0649457 | AS5: 0.45575978 | AT5: 3.7020388 | AU5: 1.5730527 | AW5: 0.24421336 | AY5: =BB345 -> 1.0668666 | AZ5: =AX657 | BA5: =AY657 | BB5: =AZ657 -> 1.0668666
A6: 21 | B6: 156XXNN | C6: Hong_Kong_Weather_3 | D6: {cloud, mean_wet_bulb_temp, rainfall, rel_humidity} | F6: =F658 -> 0 | G6: =G658 -> 0 | H6: =H658 -> 0 | I6: =I658 -> 0 | J6: =J658 -> 1 | K6: =K658 -> 4 | L6: =L658 -> 0 | M6: 4797310.6 | N6: 6517156.2 | O6: 6577411.8 | P6: 1475770.8 | Q6: 1418254.6 | R6: 1030299.8 | S6: 1117629.8 | T6: 4594408.8 | U6: 4516951.2 | V6: 8246724.6 | W6: 4301999.2 | Y6: 4.3530284 | Z6: 4.7136611 | AA6: 4.7428218 | AB6: 2.51759 | AC6: 1.8231812 | AD6: 2.8940736 | AE6: 2.4286538 | AF6: 1.9072744 | AG6: 2.8799568 | AH6: 5.031402 | AI6: 6.1716871 | AK6: 4.3530284 | AL6: 1.1457925 | AM6: 1.1723754 | AN6: 2.51759 | AO6: 0.55218356 | AP6: 2.8940736 | AQ6: 0.66336001 | AR6: 1.1041729 | AS6: 0.49349949 | AT6: 5.031402 | AU6: 3.8655231 | AW6: 0.25057071 | AY6: =BB346 -> 0.15008488 | AZ6: =AX658 | BA6: =AY658 | BB6: =AZ658 -> 0.15008488
A7: 21 | B7: 156XNXX | C7: Hong_Kong_Weather_3 | D7: {cloud, mean_wet_bulb_temp, rainfall, rel_humidity} | F7: =F659 -> 0 | G7: =G659 -> 1 | H7: =H659 -> 0 | I7: =I659 -> 1 | J7: =J659 -> 0 | K7: =K659 -> 4 | L7: =L659 -> 0 | M7: 1254500 | N7: 4194657.4 | O7: 4240017.8 | P7: 3405256 | Q7: 2681040.6 | R7: 1465331.4 | S7: 4095508.6 | T7: 4677209.6 | U7: 4804340 | V7: 7657925.2 | W7: 4063479 | Y7: 1.7552848 | Z7: 3.323337 | AA7: 3.3194965 | AB7: 3.1507828 | AC7: 2.5773797 | AD7: 2.9151649 | AE7: 4.3183333 | AF7: 2.0637685 | AG7: 3.3959963 | AH7: 4.8552003 | AI7: 5.6056174 | AK7: 1.7552848 | AL7: 0.81439 | AM7: 0.83055091 | AN7: 3.1507828 | AO7: 0.66399413 | AP7: 2.9151649 | AQ7: 0.90207905 | AR7: 1.1283326 | AS7: 0.50088019 | AT7: 4.8552003 | AU7: 3.4933647 | AW7: 0.25176607 | AY7: =BB347 -> -1.1557795 | AZ7: =AX659 | BA7: =AY659 -> -1.1557795 | BB7: =AZ659
A8: 21 | B8: 156XNXN | C8: Hong_Kong_Weather_3 | D8: {cloud, mean_wet_bulb_temp, rainfall, rel_humidity} | F8: =F660 -> 0 | G8: =G660 -> 0 | H8: =H660 -> 0 | I8: =I660 -> 1 | J8: =J660 -> 0 | K8: =K660 -> 4 | L8: =L660 -> 0 | M8: 4819087.6 | N8: 5450944.2 | O8: 5544944 | P8: 5594837.2 | Q8: 2864563.8 | R8: 4114032.2 | S8: 5660653 | T8: 4018927.8 | U8: 3529746.4 | V8: 24198068 | W8: 7084215 | Y8: 5.2069667 | Z8: 4.6305844 | AA8: 4.7021961 | AB8: 6.9428629 | AC8: 3.3019372 | AD8: 6.1810706 | AE8: 5.3897378 | AF8: 1.5304061 | AG8: 2.2399321 | AH8: 8.3824086 | AI8: 7.7129901 | AK8: 5.2069667 | AL8: 1.3758105 | AM8: 1.4300516 | AN8: 6.9428629 | AO8: 0.98707478 | AP8: 6.1810706 | AQ8: 1.2373323 | AR8: 1.0210891 | AS8: 0.54048041 | AT8: 8.3824086 | AU8: 5.0434339 | AW8: 0.25131255 | AY8: =BB348 -> -0.30306973 | AZ8: =AX660 | BA8: =AY660 -> -0.30306973 | BB8: =AZ660
A9: 21 | B9: 156XNNX | C9: Hong_Kong_Weather_3 | D9: {cloud, mean_wet_bulb_temp, rainfall, rel_humidity} | F9: =F661 -> 0 | G9: =G661 -> 0 | H9: =H661 -> 0 | I9: =I661 -> 1 | J9: =J661 -> 0 | K9: =K661 -> 4 | L9: =L661 -> 0 | M9: 2186441.2 | N9: 5310295.8 | O9: 5320319.8 | P9: 1589889 | Q9: 1402039.8 | R9: 616867 | S9: 944250 | T9: 4560935.4 | U9: 4477973.4 | V9: 575641.8 | W9: 2817974.8 | Y9: 2.2020973 | Z9: 4.0032414 | AA9: 3.9855122 | AB9: 1.9998268 | AC9: 1.8920274 | AD9: 1.7088414 | AE9: 2.2042948 | AF9: 1.91775 | AG9: 2.8707653 | AH9: 3.1649295 | AI9: 5.197716 | AK9: 2.2020973 | AL9: 0.98012631 | AM9: 0.97660551 | AN9: 1.9998268 | AO9: 0.58466858 | AP9: 1.7088414 | AQ9: 0.62538676 | AR9: 1.1227429 | AS9: 0.50939978 | AT9: 3.1649295 | AU9: 3.1793333 | AW9: 0.2588718 | AY9: =BB349 -> -1.0588625 | AZ9: =AX661 | BA9: =AY661 -> -1.0588625 | BB9: =AZ661
A10: 21 | B10: 156XNNN | C10: Hong_Kong_Weather_3 | D10: {cloud, mean_wet_bulb_temp, rainfall, rel_humidity} | F10: =F662 -> 0 | G10: =G662 -> 1 | H10: =H662 -> 0 | I10: =I662 -> 1 | J10: =J662 -> 0 | K10: =K662 -> 4 | L10: =L662 -> 0 | M10: 1359597.6 | N10: 1838324.8 | O10: 1844210.8 | P10: 602084 | Q10: 986201.6 | R10: 362702.6 | S10: 703084.4 | T10: 3787607.6 | U10: 2856871.4 | V10: 230918.4 | W10: 536091.2 | Y10: 1.6554917 | Z10: 1.9663486 | AA10: 1.9786704 | AB10: 1.3230066 | AC10: 1.6508731 | AD10: 1.7679748 | AE10: 2.1254846 | AF10: 1.2253399 | AG10: 1.34988 | AH10: 1.4726344 | AI10: 2.5684903 | AK10: 1.6554917 | AL10: 0.57880919 | AM10: 0.59014516 | AN10: 1.3230066 | AO10: 0.56986011 | AP10: 1.7679748 | AQ10: 0.66744739 | AR10: 0.79360221 | AS10: 0.37278133 | AT10: 1.4726344 | AU10: 1.2097622 | AW10: 0.24780089 | AY10: =BB350 -> -0.14504788 | AZ10: =AX662 | BA10: =AY662 -> -0.14504788 | BB10: =AZ662
A11: 21 | B11: 156NXXX | C11: Hong_Kong_Weather_3 | D11: {cloud, mean_wet_bulb_temp, rainfall, rel_humidity} | F11: =F663 -> 0 | G11: =G663 -> 1 | H11: =H663 -> 0 | I11: =I663 -> 1 | J11: =J663 -> 0 | K11: =K663 -> 4 | L11: =L663 -> 0 | M11: 6171416.2 | N11: 6658128.2 | O11: 6754017.6 | P11: 8419143.6 | Q11: 4522421.4 | R11: 9256532.2 | S11: 6531999.4 | T11: 4215910.2 | U11: 3413126.6 | V11: 19259380 | W11: 7335462 | Y11: 6.4930125 | Z11: 5.7753662 | AA11: 5.815125 | AB11: 9.9067312 | AC11: 5.6033944 | AD11: 9.1519723 | AE11: 7.6283453 | AF11: 1.6885323 | AG11: 2.0887844 | AH11: 10.680113 | AI11: 9.8778993 | AK11: 6.4930125 | AL11: 1.7501897 | AM11: 1.799003 | AN11: 9.9067312 | AO11: 1.4998593 | AP11: 9.1519723 | AQ11: 2.3179647 | AR11: 1.071444 | AS11: 0.49375936 | AT11: 10.680113 | AU11: 6.6051459 | AW11: 0.25452099 | AY11: =BB351 -> -0.14504788 | AZ11: =AX663 | BA11: =AY663 -> -0.14504788 | BB11: =AZ663
A12: 21 | B12: 156NXXN | C12: Hong_Kong_Weather_3 | D12: {cloud, mean_wet_bulb_temp, rainfall, rel_humidity} | F12: =F664 -> 0 | G12: =G664 -> 0 | H12: =H664 -> 0 | I12: =I664 -> 1 | J12: =J664 -> 0 | K12: =K664 -> 4 | L12: =L664 -> 0 | M12: 6077126.4 | N12: 13131158 | O12: 13266173 | P12: 14297376 | Q12: 10875460 | R12: 9345182.6 | S12: 10715155 | T12: 4852422.4 | U12: 5620632 | V12: 31495539 | W12: 18506134 | Y12: 6.0501889 | Z12: 8.8482824 | AA12: 8.9103521 | AB12: 12.521033 | AC12: 8.512113 | AD12: 10.021675 | AE12: 9.1760971 | AF12: 2.2595135 | AG12: 4.3528365 | AH12: 11.668549 | AI12: 16.600063 | AK12: 6.0501889 | AL12: 2.2282989 | AM12: 2.2857356 | AN12: 12.521033 | AO12: 2.6182663 | AP12: 10.021675 | AQ12: 2.2521139 | AR12: 1.266939 | AS12: 0.63879154 | AT12: 11.668549 | AU12: 11.140776 | AW12: 0.2480093 | AY12: =BB352 -> -1.0588625 | AZ12: =AX664 | BA12: =AY664 -> -1.0588625 | BB12: =AZ664
A13: 21 | B13: 156NXNX | C13: Hong_Kong_Weather_3 | D13: {cloud, mean_wet_bulb_temp, rainfall, rel_humidity} | F13: =F665 -> 0 | G13: =G665 -> 0 | H13: =H665 -> 0 | I13: =I665 -> 1 | J13: =J665 -> 0 | K13: =K665 -> 4 | L13: =L665 -> 0 | M13: 4373945.6 | N13: 4127747.8 | O13: 4157740.6 | P13: 4791875 | Q13: 2153268.4 | R13: 3330299.8 | S13: 1623636 | T13: 4221177.6 | U13: 3321482.6 | V13: 5883243.8 | W13: 3761910.2 | Y13: 4.0551146 | Z13: 3.6435278 | AA13: 3.653689 | AB13: 3.0649491 | AC13: 1.8549211 | AD13: 3.0638115 | AE13: 2.3318364 | AF13: 1.6649422 | AG13: 1.9082581 | AH13: 4.5901308 | AI13: 4.6694084 | AK13: 4.0551146 | AL13: 0.97673359 | AM13: 0.98815359 | AN13: 3.0649491 | AO13: 0.56563739 | AP13: 3.0638115 | AQ13: 0.6543028 | AR13: 1.1075694 | AS13: 0.48324303 | AT13: 4.5901308 | AU13: 2.6800185 | AW13: 0.25609155 | AY13: =BB353 -> -0.30306973 | AZ13: =AX665 | BA13: =AY665 -> -0.30306973 | BB13: =AZ665
