Workbook

Sheet Summary
A1: # Dominance [mean] | M1: Sequential Time [mean]
A2: Target or symm.; Gain <= 0 | B2: Leakage | E2: Name | F2: Algorithm | M2: Target or symm.; Gain <= 0 | N2: Leakage | Q2: Name | R2: Algorithm
B3: Open | C3: Closed | F3: BNL | G3: BNL HM | H3: SFS | I3: SaLSa | J3: D&C | K3: BBS | N3: Open | O3: Closed | R3: BNL | S3: BNL HM | T3: SFS | U3: SaLSa | V3: D&C | W3: BBS
A4: Non-Causal | E4: Non-Causal | F4: ='Pure Decorrelation'!$M$765 -> 13369038 | G4: ='Pure Decorrelation'!$M$765 -> 13369038 | H4: ='Pure Decorrelation'!$P$765 -> 11598037 | I4: ='Pure Decorrelation'!$R$765 -> 40102255 | J4: ='Pure Decorrelation'!$T$765 -> 6445481.3 | K4: ='Pure Decorrelation'!$V$765 -> 11751730 | M4: Non-Causal | Q4: Non-Causal | R4: ='Pure Decorrelation'!$Y$765 -> 11.024039 | S4: ='Pure Decorrelation'!$Y$765 -> 11.024039 | T4: ='Pure Decorrelation'!$AB$765 -> 12.924622 | U4: ='Pure Decorrelation'!$AD$765 -> 25.602229 | V4: ='Pure Decorrelation'!$AF$765 -> 4.5333497 | W4: ='Pure Decorrelation'!$AH$765 -> 5.7112249
A5: Pref. Decor. | E5: Pref. Decor. | F5: ='Pure Decorrelation'!M770 -> 9296022.8 | G5: ='Pure Decorrelation'!N770 -> 9595734.3 | H5: ='Pure Decorrelation'!O770 -> 5549486.9 | I5: ='Pure Decorrelation'!P770 -> 7086008.9 | J5: ='Pure Decorrelation'!Q770 -> 5350749 | K5: ='Pure Decorrelation'!R770 -> 5687261.6 | M5: Pref. Decor. | Q5: Pref. Decor. | R5: ='Pure Decorrelation'!T770 -> 6.8874324 | S5: ='Pure Decorrelation'!U770 -> 7.012927 | T5: ='Pure Decorrelation'!V770 -> 5.9856222 | U5: ='Pure Decorrelation'!W770 -> 5.6013167 | V5: ='Pure Decorrelation'!X770 -> 4.2682704 | W5: ='Pure Decorrelation'!Y770 -> 10.488216
A6: ddSky. | E6: ddSky. | F6: =ddSky!M770 -> 3730776.6 | G6: =ddSky!N770 -> 3790797.2 | H6: =ddSky!O770 -> 1468855.4 | I6: =ddSky!P770 -> 2006071 | J6: =ddSky!Q770 -> 4543643.2 | K6: =ddSky!R770 -> 1310436.1 | M6: ddSky. | Q6: ddSky. | R6: =ddSky!T770 -> 2.8335152 | S6: =ddSky!U770 -> 2.8260668 | T6: =ddSky!V770 -> 1.548857 | U6: =ddSky!W770 -> 1.8760986 | V6: =ddSky!X770 -> 3.1993464 | W6: =ddSky!Y770 -> 2.8939865
A7: gnSky. | E7: gnSky. | F7: =gnSky!M770 -> 6203751 | G7: =gnSky!N770 -> 6269581.4 | H7: =gnSky!O770 -> 1857583.3 | I7: =gnSky!P770 -> 4588586 | J7: =gnSky!Q770 -> 4900224.9 | K7: =gnSky!R770 -> 2449709.8 | M7: gnSky. | Q7: gnSky. | R7: =gnSky!T770 -> 4.2429241 | S7: =gnSky!U770 -> 4.2304476 | T7: =gnSky!V770 -> 2.1803836 | U7: =gnSky!W770 -> 3.496958 | V7: =gnSky!X770 -> 3.3931628 | W7: =gnSky!Y770 -> 4.5786631
A8: lnSky. (0.9, 0.1) | B8: 0.9 | C8: 0.1 | E8: lnSky. (0.9, 0.1) | F8: ='lnSky (0.9, 0.1)'!M770 -> 6184493 | G8: ='lnSky (0.9, 0.1)'!N770 -> 6278668.6 | H8: ='lnSky (0.9, 0.1)'!O770 -> 1852494.4 | I8: ='lnSky (0.9, 0.1)'!P770 -> 4572989.9 | J8: ='lnSky (0.9, 0.1)'!Q770 -> 4893345.8 | K8: ='lnSky (0.9, 0.1)'!R770 -> 2428187 | M8: lnSky. (0.9, 0.1) | N8: 0.9 | O8: 0.1 | Q8: lnSky. (0.9, 0.1) | R8: ='lnSky (0.9, 0.1)'!T770 -> 4.311411 | S8: ='lnSky (0.9, 0.1)'!U770 -> 4.2836933 | T8: ='lnSky (0.9, 0.1)'!V770 -> 2.2093242 | U8: ='lnSky (0.9, 0.1)'!W770 -> 3.5391371 | V8: ='lnSky (0.9, 0.1)'!X770 -> 3.439601 | W8: ='lnSky (0.9, 0.1)'!Y770 -> 4.5854992
A9: lnSky. (0.8, 0.2) | B9: 0.8 | C9: 0.2 | E9: lnSky. (0.8, 0.2) | F9: ='lnSky (0.8, 0.2)'!M770 -> 3760386.8 | G9: ='lnSky (0.8, 0.2)'!N770 -> 3779140 | H9: ='lnSky (0.8, 0.2)'!O770 -> 1398140.5 | I9: ='lnSky (0.8, 0.2)'!P770 -> 2108615 | J9: ='lnSky (0.8, 0.2)'!Q770 -> 4699453.4 | K9: ='lnSky (0.8, 0.2)'!R770 -> 1847066.7 | M9: lnSky. (0.8, 0.2) | N9: 0.8 | O9: 0.2 | Q9: lnSky. (0.8, 0.2) | R9: ='lnSky (0.8, 0.2)'!T770 -> 2.8441831 | S9: ='lnSky (0.8, 0.2)'!U770 -> 2.8122658 | T9: ='lnSky (0.8, 0.2)'!V770 -> 1.7318672 | U9: ='lnSky (0.8, 0.2)'!W770 -> 1.9372863 | V9: ='lnSky (0.8, 0.2)'!X770 -> 3.2102756 | W9: ='lnSky (0.8, 0.2)'!Y770 -> 3.1908609
A10: lnSky. (0.7, 0.3) | B10: 0.7 | C10: 0.3 | E10: lnSky. (0.7, 0.3) | F10: ='lnSky (0.7, 0.3)'!M770 -> 3710917.2 | G10: ='lnSky (0.7, 0.3)'!N770 -> 3728814.5 | H10: ='lnSky (0.7, 0.3)'!O770 -> 1388324.1 | I10: ='lnSky (0.7, 0.3)'!P770 -> 2059934.2 | J10: ='lnSky (0.7, 0.3)'!Q770 -> 4656418.1 | K10: ='lnSky (0.7, 0.3)'!R770 -> 1760377.6 | M10: lnSky. (0.7, 0.3) | N10: 0.7 | O10: 0.3 | Q10: lnSky. (0.7, 0.3) | R10: ='lnSky (0.7, 0.3)'!T770 -> 2.8904639 | S10: ='lnSky (0.7, 0.3)'!U770 -> 2.8500199 | T10: ='lnSky (0.7, 0.3)'!V770 -> 1.7591374 | U10: ='lnSky (0.7, 0.3)'!W770 -> 1.9089046 | V10: ='lnSky (0.7, 0.3)'!X770 -> 3.2242124 | W10: ='lnSky (0.7, 0.3)'!Y770 -> 3.1783655
A11: lnSky. (0.6, 0.4) | B11: 0.6 | C11: 0.4 | E11: lnSky. (0.6, 0.4) | F11: ='lnSky (0.6, 0.4)'!M770 -> 3504189.4 | G11: ='lnSky (0.6, 0.4)'!N770 -> 3511674.7 | H11: ='lnSky (0.6, 0.4)'!O770 -> 1289362.9 | I11: ='lnSky (0.6, 0.4)'!P770 -> 1847651 | J11: ='lnSky (0.6, 0.4)'!Q770 -> 4498338.6 | K11: ='lnSky (0.6, 0.4)'!R770 -> 1383613.8 | M11: lnSky. (0.6, 0.4) | N11: 0.6 | O11: 0.4 | Q11: lnSky. (0.6, 0.4) | R11: ='lnSky (0.6, 0.4)'!T770 -> 2.6967089 | S11: ='lnSky (0.6, 0.4)'!U770 -> 2.670126 | T11: ='lnSky (0.6, 0.4)'!V770 -> 1.6140554 | U11: ='lnSky (0.6, 0.4)'!W770 -> 1.7338202 | V11: ='lnSky (0.6, 0.4)'!X770 -> 3.0644979 | W11: ='lnSky (0.6, 0.4)'!Y770 -> 2.8838404

Sheet Pure Decorrelation
M1: Average Benchmark (results) | Y1: Average Benchmark (sequential timing) | AK1: Average Benchmark (parallel timing) | AW1: Average Benchmark (cluster_time)
F2: TargetN | G2: #N | H2: Target (or sym) | I2: Gain <=0 | J2: Gain > 0 | K2: Pref | L2: Pref&Target | M2: BNL | N2: BNL Causal | O2: BNL Causal HM | P2: SFS | Q2: SFS Causal | R2: SaLSa | S2: SaLSa Causal | T2: D&C | U2: D&C Causal | V2: BBS | W2: BBS Causal | Y2: BNL | Z2: BNL Causal | AA2: BNL Causal HM | AB2: SFS | AC2: SFS Causal | AD2: SaLSa | AE2: SaLSa Causal | AF2: D&C | AG2: D&C Causal | AH2: BBS | AI2: BBS Causal | AK2: BNL | AL2: BNL Causal | AM2: BNL Causal HM | AN2: SFS | AO2: SFS Causal | AP2: SaLSa | AQ2: SaLSa Causal | AR2: D&C | AS2: D&C Causal | AT2: BBS | AU2: BBS Causal | AW2: KMeans Time (seconds) | AY2: Gain
A3: 16 | B3: 140XXXX | C3: XYZW_CDE_1 | D3: {W, X, Y, Z} | F3: 0 | G3: 0 | H3: 1 | I3: =1 - J3 -> 0 | J3: =IF(AY3 > 0, 1, 0) -> 1 | K3: 4 | L3: 4 | M3: 8651928.8 | N3: 7175309 | O3: 7265352.8 | P3: 42301553 | Q3: 2130744 | R3: 30213745 | S3: 4655122.2 | T3: 12092496 | U3: 8260899.8 | V3: 42235243 | W3: 2123550.6 | Y3: 6.9127715 | Z3: 5.4913555 | AA3: 5.4497448 | AB3: 29.881814 | AC3: 3.0443996 | AD3: 19.094261 | AE3: 3.9344142 | AF3: 10.955225 | AG3: 7.5007471 | AH3: 15.870598 | AI3: 7.5277185 | AK3: 6.9127715 | AL3: 2.1573216 | AM3: 2.1550311 | AN3: 29.881814 | AO3: 1.29531 | AP3: 19.094261 | AQ3: 1.6534768 | AR3: 5.5103225 | AS3: 1.0471913 | AT3: 15.870598 | AU3: 5.9251536 | AW3: 0.33311186 | AY3: 1
A4: 16 | B4: 140XXXN | C4: XYZW_CDE_1 | D4: {W, X, Y, Z} | F4: 0 | G4: 1 | H4: 0 | I4: =1 - J4 -> 0 | J4: =IF(AY4 > 0, 1, 0) -> 1 | K4: 4 | L4: 0 | M4: 55059286 | N4: 13698389 | O4: 13799235 | P4: 7914061.6 | Q4: 4441002.6 | R4: 1.7730778e+08 | S4: 7738113 | T4: 12368258 | U4: 8421792.6 | V4: 7611280.2 | W4: 4436241.2 | Y4: 39.132717 | Z4: 9.0067899 | AA4: 9.0797269 | AB4: 19.354822 | AC4: 4.4720013 | AD4: 104.87839 | AE4: 5.991895 | AF4: 11.435494 | AG4: 7.6678378 | AH4: 5.7546879 | AI4: 9.2841116 | AK4: 39.132717 | AL4: 4.538587 | AM4: 4.573744 | AN4: 19.354822 | AO4: 2.6236659 | AP4: 104.87839 | AQ4: 3.0442767 | AR4: 5.7712263 | AS4: 1.1506157 | AT4: 5.7546879 | AU4: 7.7860163 | AW4: 0.34906262 | AY4: 1
A5: 16 | B5: 140XXNX | C5: XYZW_CDE_1 | D5: {W, X, Y, Z} | F5: 0 | G5: 1 | H5: 0 | I5: =1 - J5 -> 0 | J5: =IF(AY5 > 0, 1, 0) -> 1 | K5: 4 | L5: 0 | M5: 201664.6 | N5: 75319201 | O5: 75334770 | P5: 200058.8 | Q5: 57742359 | R5: 92.2 | S5: 68311490 | T5: 4811088.6 | U5: 11075915 | V5: 1040 | W5: 57535383 | Y5: 0.39074291 | Z5: 53.820617 | AA5: 54.036034 | AB5: 0.47795823 | AC5: 56.365902 | AD5: 0.093760519 | AE5: 50.923994 | AF5: 3.0819292 | AG5: 10.846907 | AH5: 0.0095443826 | AI5: 79.164308 | AK5: 0.39074291 | AL5: 16.203612 | AM5: 16.05944 | AN5: 0.47795823 | AO5: 18.002718 | AP5: 0.093760519 | AQ5: 15.472079 | AR5: 1.5593727 | AS5: 1.9501714 | AT5: 0.0095443826 | AU5: 63.289142 | AW5: 0.3459881 | AY5: 1
A6: 16 | B6: 140XXNN | C6: XYZW_CDE_1 | D6: {W, X, Y, Z} | F6: 0 | G6: 0 | H6: 0 | I6: =1 - J6 -> 0 | J6: =IF(AY6 > 0, 1, 0) -> 1 | K6: 4 | L6: 0 | M6: 8924700.4 | N6: 7409128.2 | O6: 8008403.4 | P6: 45866083 | Q6: 2391983.6 | R6: 32861528 | S6: 4941932.8 | T6: 6992038.2 | U6: 6557177.2 | V6: 45628441 | W6: 2389275.2 | Y6: 8.3352197 | Z6: 6.0984463 | AA6: 6.4174577 | AB6: 45.814646 | AC6: 3.8918628 | AD6: 28.794683 | AE6: 4.6747125 | AF6: 5.3608775 | AG6: 5.9139982 | AH6: 20.268796 | AI6: 7.9222033 | AK6: 8.3352197 | AL6: 2.355918 | AM6: 2.7064176 | AN6: 45.814646 | AO6: 1.6734524 | AP6: 28.794683 | AQ6: 1.8495526 | AR6: 2.6965437 | AS6: 1.0172913 | AT6: 20.268796 | AU6: 6.2464678 | AW6: 0.33245461 | AY6: 1
A7: 16 | B7: 140XNXX | C7: XYZW_CDE_1 | D7: {W, X, Y, Z} | F7: 0 | G7: 1 | H7: 0 | I7: =1 - J7 -> 0 | J7: =IF(AY7 > 0, 1, 0) -> 1 | K7: 4 | L7: 0 | M7: 5158435.4 | N7: 14680450 | O7: 14940966 | P7: 1107525.2 | Q7: 6531484.6 | R7: 15828999 | S7: 9867056.8 | T7: 6997933 | U7: 6746446 | V7: 995651.4 | W7: 6365591.6 | Y7: 5.2934131 | Z7: 10.369151 | AA7: 10.636605 | AB7: 3.1010016 | AC7: 6.9747482 | AD7: 11.252564 | AE7: 7.3901065 | AF7: 5.3459433 | AG7: 6.0193059 | AH7: 3.3616486 | AI7: 12.230784 | AK7: 5.2934131 | AL7: 7.2439255 | AM7: 7.4596666 | AN7: 3.1010016 | AO7: 4.548577 | AP7: 11.252564 | AQ7: 5.0335068 | AR7: 2.6907736 | AS7: 1.1611942 | AT7: 3.3616486 | AU7: 10.530713 | AW7: 0.36817572 | AY7: 1
A8: 16 | B8: 140XNXN | C8: XYZW_CDE_1 | D8: {W, X, Y, Z} | F8: 0 | G8: 0 | H8: 0 | I8: =1 - J8 -> 0 | J8: =IF(AY8 > 0, 1, 0) -> 1 | K8: 4 | L8: 0 | M8: 8193988.8 | N8: 7572577.8 | O8: 7799412.2 | P8: 43487441 | Q8: 2447008.4 | R8: 33722231 | S8: 4764328.4 | T8: 4863915.2 | U8: 9015117 | V8: 43754360 | W8: 2451575.6 | Y8: 8.718803 | Z8: 6.2436512 | AA8: 6.4057397 | AB8: 57.035831 | AC8: 3.9566089 | AD8: 33.487222 | AE8: 4.5003273 | AF8: 3.1851477 | AG8: 8.8742746 | AH8: 23.498301 | AI8: 8.0344333 | AK8: 8.718803 | AL8: 2.8248618 | AM8: 2.98238 | AN8: 57.035831 | AO8: 1.8182945 | AP8: 33.487222 | AQ8: 1.971674 | AR8: 1.6033238 | AS8: 1.3793309 | AT8: 23.498301 | AU8: 6.3653759 | AW8: 0.34653842 | AY8: 1
A9: 16 | B9: 140XNNX | C9: XYZW_CDE_1 | D9: {W, X, Y, Z} | F9: 0 | G9: 0 | H9: 0 | I9: =1 - J9 -> 0 | J9: =IF(AY9 > 0, 1, 0) -> 1 | K9: 4 | L9: 0 | M9: 8554688.4 | N9: 6983115.6 | O9: 7069681.6 | P9: 44846503 | Q9: 2174907.6 | R9: 29785647 | S9: 4689817.4 | T9: 12226433 | U9: 8231681.2 | V9: 44907346 | W9: 2176271 | Y9: 6.8759735 | Z9: 5.3561867 | AA9: 5.4034892 | AB9: 16.397998 | AC9: 2.9147033 | AD9: 14.730603 | AE9: 4.2048363 | AF9: 11.196082 | AG9: 7.399013 | AH9: 13.141907 | AI9: 7.3212978 | AK9: 6.8759735 | AL9: 2.074127 | AM9: 2.1092932 | AN9: 16.397998 | AO9: 1.1238348 | AP9: 14.730603 | AQ9: 1.6821303 | AR9: 5.6279324 | AS9: 1.030098 | AT9: 13.141907 | AU9: 5.7618104 | AW9: 0.33248337 | AY9: 1
A10: 16 | B10: 140XNNN | C10: XYZW_CDE_1 | D10: {W, X, Y, Z} | F10: 0 | G10: 1 | H10: 0 | I10: =1 - J10 -> 0 | J10: =IF(AY10 > 0, 1, 0) -> 1 | K10: 4 | L10: 0 | M10: 56319775 | N10: 13746114 | O10: 13826027 | P10: 8126486.2 | Q10: 4466444.6 | R10: 1.7335886e+08 | S10: 7820700.6 | T10: 12243896 | U10: 8430593.6 | V10: 7475389.2 | W10: 4447037.6 | Y10: 40.000053 | Z10: 9.0232293 | AA10: 9.0743813 | AB10: 18.426652 | AC10: 4.398745 | AD10: 98.789366 | AE10: 5.9889844 | AF10: 11.160405 | AG10: 7.6981045 | AH10: 5.7611584 | AI10: 9.3660966 | AK10: 40.000053 | AL10: 4.6186065 | AM10: 4.6548278 | AN10: 18.426652 | AO10: 2.5702454 | AP10: 98.789366 | AQ10: 3.02659 | AR10: 5.6154052 | AS10: 1.1594838 | AT10: 5.7611584 | AU10: 7.8717986 | AW10: 0.34364019 | AY10: 1
A11: 16 | B11: 140NXXX | C11: XYZW_CDE_1 | D11: {W, X, Y, Z} | F11: 0 | G11: 1 | H11: 0 | I11: =1 - J11 -> 0 | J11: =IF(AY11 > 0, 1, 0) -> 1 | K11: 4 | L11: 0 | M11: 55796751 | N11: 13726864 | O11: 13821888 | P11: 8533125.2 | Q11: 4460185.6 | R11: 1.8483866e+08 | S11: 7855858.8 | T11: 12277478 | U11: 8441799.6 | V11: 8112431.4 | W11: 4445249.6 | Y11: 39.339939 | Z11: 9.0385466 | AA11: 9.0318456 | AB11: 21.128127 | AC11: 4.2889346 | AD11: 106.89758 | AE11: 5.9901159 | AF11: 11.134629 | AG11: 7.6585643 | AH11: 6.0555398 | AI11: 9.2760553 | AK11: 39.339939 | AL11: 4.6513705 | AM11: 4.6417304 | AN11: 21.128127 | AO11: 2.5462631 | AP11: 106.89758 | AQ11: 3.0045074 | AR11: 5.6129122 | AS11: 1.1325233 | AT11: 6.0555398 | AU11: 7.7788019 | AW11: 0.33172699 | AY11: 1
A12: 16 | B12: 140NXXN | C12: XYZW_CDE_1 | D12: {W, X, Y, Z} | F12: 0 | G12: 0 | H12: 0 | I12: =1 - J12 -> 0 | J12: =IF(AY12 > 0, 1, 0) -> 1 | K12: 4 | L12: 0 | M12: 8492168.2 | N12: 7088759.6 | O12: 7497002.4 | P12: 42293061 | Q12: 2448847 | R12: 33533661 | S12: 4796724 | T12: 12208411 | U12: 8227841.6 | V12: 42352359 | W12: 2413346.8 | Y12: 6.8997929 | Z12: 5.4792542 | AA12: 5.6427513 | AB12: 15.954466 | AC12: 3.1530935 | AD12: 17.62848 | AE12: 4.399916 | AF12: 11.249559 | AG12: 7.4536045 | AH12: 13.032308 | AI12: 7.6959233 | AK12: 6.8997929 | AL12: 1.9253941 | AM12: 2.102224 | AN12: 15.954466 | AO12: 1.1451233 | AP12: 17.62848 | AQ12: 1.5998279 | AR12: 5.6642394 | AS12: 1.0535307 | AT12: 13.032308 | AU12: 6.0133742 | AW12: 0.34497049 | AY12: 1
A13: 16 | B13: 140NXNX | C13: XYZW_CDE_1 | D13: {W, X, Y, Z} | F13: 0 | G13: 0 | H13: 0 | I13: =1 - J13 -> 0 | J13: =IF(AY13 > 0, 1, 0) -> 1 | K13: 4 | L13: 0 | M13: 8699537.4 | N13: 7320627.4 | O13: 7835053.6 | P13: 40600807 | Q13: 2182263.8 | R13: 29943482 | S13: 4675099.8 | T13: 4874009.8 | U13: 8955103.4 | V13: 40872901 | W13: 2204938 | Y13: 9.1724837 | Z13: 6.0100012 | AA13: 6.3982213 | AB13: 52.514124 | AC13: 3.7071955 | AD13: 31.588085 | AE13: 4.3888467 | AF13: 3.1648169 | AG13: 8.8130048 | AH13: 22.22063 | AI13: 7.565635 | AK13: 9.1724837 | AL13: 2.4404086 | AM13: 2.8214012 | AN13: 52.514124 | AO13: 1.739686 | AP13: 31.588085 | AQ13: 1.8771214 | AR13: 1.594012 | AS13: 1.378379 | AT13: 22.22063 | AU13: 5.946122 | AW13: 0.33606968 | AY13: 1
A14: 16 | B14: 140NXNN | C14: XYZW_CDE_1 | D14: {W, X, Y, Z} | F14: 0 | G14: 1 | H14: 0 | I14: =1 - J14 -> 0 | J14: =IF(AY14 > 0, 1, 0) -> 1 | K14: 4 | L14: 0 | M14: 4988107.6 | N14: 11904907 | O14: 13019785 | P14: 925137.4 | Q14: 5874640 | R14: 14797049 | S14: 9694202.4 | T14: 6991416 | U14: 6661674.4 | V14: 910615 | W14: 5826628.6 | Y14: 5.1237474 | Z14: 8.5741391 | AA14: 9.2550602 | AB14: 3.1918146 | AC14: 6.5925752 | AD14: 11.68775 | AE14: 7.3581684 | AF14: 5.3411736 | AG14: 5.9728484 | AH14: 3.3252139 | AI14: 12.494886 | AK14: 5.1237474 | AL14: 5.4301673 | AM14: 6.0952462 | AN14: 3.1918146 | AO14: 4.1413953 | AP14: 11.68775 | AQ14: 5.1534886 | AR14: 2.687886 | AS14: 1.1590046 | AT14: 3.3252139 | AU14: 10.793377 | AW14: 0.33852315 | AY14: 1
... A378: 3 | B378: 121NN | C378: XYZ_C_1_j | D378: {X, Z} | F378: 0 | G378: 0 | H378: 0 | I378: =1 - J378 -> 0 | J378: =IF(AY378 > 0, 1, 0) -> 1 | K378: 2 | L378: 0 | M378: 200049.4 | N378: 1263909.8 | O378: 1264389.4 | P378: 199999.4 | Q378: 3028225.6 | R378: 2.4 | S378: 1766585.8 | T378: 2917511.4 | U378: 2338051.8 | V378: 287 | W378: 4993232.8 | Y378: 0.26880861 | Z378: 1.4875847 | AA378: 1.4593282 | AB378: 0.28692743 | AC378: 2.5370245 | AD378: 0.086515733 | AE378: 1.4366914 | AF378: 0.59808919 | AG378: 0.85012241 | AH378: 0.006017534 | AI378: 4.1640872 | AK378: 0.26880861 | AL378: 0.5193468 | AM378: 0.49975418 | AN378: 0.28692743 | AO378: 0.79595701 | AP378: 0.086515733 | AQ378: 0.51856978 | AR378: 0.30278843 | AS378: 0.3125567 | AT378: 0.006017534 | AU378: 2.1368226 | AW378: 0.270082 | AY378: 1
M382: Average Benchmark (results) | Y382: Average Benchmark (sequential timing) | AK382: Average Benchmark (parallel timing)
F383: TargetN | G383: #N | H383: Target (or sym) | I383: Gain <=0 | J383: Gain > 0 | K383: Pref | L383: Pref&Target | M383: BNL | N383: BNL Causal | O383: BNL Causal HM | P383: SFS | Q383: SFS Causal | R383: SaLSa | S383: SaLSa Causal | T383: D&C | U383: D&C Causal | V383: BBS | W383: BBS Causal | Y383: BNL | Z383: BNL Causal | AA383: BNL Causal HM | AB383: SFS | AC383: SFS Causal | AD383: SaLSa | AE383: SaLSa Causal | AF383: D&C | AG383: D&C Causal | AH383: BBS | AI383: BBS Causal | AK383: BNL | AL383: BNL Causal | AM383: BNL Causal HM | AN383: SFS | AO383: SFS Causal | AP383: SaLSa | AQ383: SaLSa Causal | AR383: D&C | AS383: D&C Causal | AT383: BBS | AU383: BBS Causal
A384: 16 | B384: 140XXXX | C384: XYZW_CDE_1 | D384: {W, X, Y, Z} | F384: 0 | G384: 0 | H384: 1 | I384: =I3 -> 0 | J384: =J3 -> 1 | K384: 4 | L384: 4 | M384: =IF($AY3 > 0, M3, M3) -> 8651928.8 | N384: =IF($AY3 > 0, N3, M3) -> 7175309 | O384: =IF($AY3 > 0, O3, M3) -> 7265352.8 | P384: =IF($AY3 > 0, P3, P3) -> 42301553 | Q384: =IF($AY3 > 0, Q3, P3) -> 2130744 | R384: =IF($AY3 > 0, R3, R3) -> 30213745 | S384: =IF($AY3 > 0, S3, R3) -> 4655122.2 | T384: =IF($AY3 > 0, T3, T3) -> 12092496 | U384: =IF($AY3 > 0, U3, T3) -> 8260899.8 | V384: =IF($AY3 > 0, V3, V3) -> 42235243 | W384: =IF($AY3 > 0, W3, V3) -> 2123550.6 | Y384: =IF($AY3 > 0, Y3, Y3) -> 6.9127715 | Z384: =IF($AY3 > 0, Z3, Y3) -> 5.4913555 | AA384: =IF($AY3 > 0, AA3, Y3) -> 5.4497448 | AB384: =IF($AY3 > 0, AB3, AB3) -> 29.881814 | AC384: =IF($AY3 > 0, AC3, AB3) -> 3.0443996 | AD384: =IF($AY3 > 0, AD3, AD3) -> 19.094261 | AE384: =IF($AY3 > 0, AE3, AD3) -> 3.9344142 | AF384: =IF($AY3 > 0, AF3, AF3) -> 10.955225 | AG384: =IF($AY3 > 0, AG3, AF3) -> 7.5007471 | AH384: =IF($AY3 > 0, AH3, AH3) -> 15.870598 | AI384: =IF($AY3 > 0, AI3, AH3) -> 7.5277185 | AK384: =IF($AY3 > 0, AK3, AK3) -> 6.9127715 | AL384: =IF($AY3 > 0, AL3, AK3) -> 2.1573216 | AM384: =IF($AY3 > 0, AM3, AK3) -> 2.1550311 | AN384: =IF($AY3 > 0, AN3, AN3) -> 29.881814 | AO384: =IF($AY3 > 0, AO3, AN3) -> 1.29531 | AP384: =IF($AY3 > 0, AP3, AP3) -> 19.094261 | AQ384: =IF($AY3 > 0, AQ3, AP3) -> 1.6534768 | AR384: =IF($AY3 > 0, AR3, AR3) -> 5.5103225 | AS384: =IF($AY3 > 0, AS3, AR3) -> 1.0471913 | AT384: =IF($AY3 > 0, AT3, AT3) -> 15.870598 | AU384: =IF($AY3 > 0, AU3, AT3) -> 5.9251536
A385: 16 | B385: 140XXXN | C385: XYZW_CDE_1 | D385: {W, X, Y, Z} | F385: 0 | G385: 1 | H385: 0 | I385: =I4 -> 0 | J385: =J4 -> 1 | K385: 4 | L385: 0 | M385: =IF($AY4 > 0, M4, M4) -> 55059286 | N385: =IF($AY4 > 0, N4, M4) -> 13698389 | O385: =IF($AY4 > 0, O4, M4) -> 13799235 | P385: =IF($AY4 > 0, P4, P4) -> 7914061.6 | Q385: =IF($AY4 > 0, Q4, P4) -> 4441002.6 | R385: =IF($AY4 > 0, R4, R4) -> 1.7730778e+08 | S385: =IF($AY4 > 0, S4, R4) -> 7738113 | T385: =IF($AY4 > 0, T4, T4) -> 12368258 | U385: =IF($AY4 > 0, U4, T4) -> 8421792.6 | V385: =IF($AY4 > 0, V4, V4) -> 7611280.2 | W385: =IF($AY4 > 0, W4, V4) -> 4436241.2 | Y385: =IF($AY4 > 0, Y4, Y4) -> 39.132717 | Z385: =IF($AY4 > 0, Z4, Y4) -> 9.0067899 | AA385: =IF($AY4 > 0, AA4, Y4) -> 9.0797269 | AB385: =IF($AY4 > 0, AB4, AB4) -> 19.354822 | AC385: =IF($AY4 > 0, AC4, AB4) -> 4.4720013 | AD385: =IF($AY4 > 0, AD4, AD4) -> 104.87839 | AE385: =IF($AY4 > 0, AE4, AD4) -> 5.991895 | AF385: =IF($AY4 > 0, AF4, AF4) -> 11.435494 | AG385: =IF($AY4 > 0, AG4, AF4) -> 7.6678378 | AH385: =IF($AY4 > 0, AH4, AH4) -> 5.7546879 | AI385: =IF($AY4 > 0, AI4, AH4) -> 9.2841116 | AK385: =IF($AY4 > 0, AK4, AK4) -> 39.132717 | AL385: =IF($AY4 > 0, AL4, AK4) -> 4.538587 | AM385: =IF($AY4 > 0, AM4, AK4) -> 4.573744 | AN385: =IF($AY4 > 0, AN4, AN4) -> 19.354822 | AO385: =IF($AY4 > 0, AO4, AN4) -> 2.6236659 | AP385: =IF($AY4 > 0, AP4, AP4) -> 104.87839 | AQ385: =IF($AY4 > 0, AQ4, AP4) -> 3.0442767 | AR385: =IF($AY4 > 0, AR4, AR4) -> 5.7712263 | AS385: =IF($AY4 > 0, AS4, AR4) -> 1.1506157 | AT385: =IF($AY4 > 0, AT4, AT4) -> 5.7546879 | AU385: =IF($AY4 > 0, AU4, AT4) -> 7.7860163
A386: 16 | B386: 140XXNX | C386: XYZW_CDE_1 | D386: {W, X, Y, Z} | F386: 0 | G386: 1 | H386: 0 | I386: =I5 -> 0 | J386: =J5 -> 1 | K386: 4 | L386: 0 | M386: =IF($AY5 > 0, M5, M5) -> 201664.6 | N386: =IF($AY5 > 0, N5, M5) -> 75319201 | O386: =IF($AY5 > 0, O5, M5) -> 75334770 | P386: =IF($AY5 > 0, P5, P5) -> 200058.8 | Q386: =IF($AY5 > 0, Q5, P5) -> 57742359 | R386: =IF($AY5 > 0, R5, R5) -> 92.2 | S386: =IF($AY5 > 0, S5, R5) -> 68311490 | T386: =IF($AY5 > 0, T5, T5) -> 4811088.6 | U386: =IF($AY5 > 0, U5, T5) -> 11075915 | V386: =IF($AY5 > 0, V5, V5) -> 1040 | W386: =IF($AY5 > 0, W5, V5) -> 57535383 | Y386: =IF($AY5 > 0, Y5, Y5) -> 0.39074291 | Z386: =IF($AY5 > 0, Z5, Y5) -> 53.820617 | AA386: =IF($AY5 > 0, AA5, Y5) -> 54.036034 | AB386: =IF($AY5 > 0, AB5, AB5) -> 0.47795823 | AC386: =IF($AY5 > 0, AC5, AB5) -> 56.365902 | AD386: =IF($AY5 > 0, AD5, AD5) -> 0.093760519 | AE386: =IF($AY5 > 0, AE5, AD5) -> 50.923994 | AF386: =IF($AY5 > 0, AF5, AF5) -> 3.0819292 | AG386: =IF($AY5 > 0, AG5, AF5) -> 10.846907 | AH386: =IF($AY5 > 0, AH5, AH5) -> 0.0095443826 | AI386: =IF($AY5 > 0, AI5, AH5) -> 79.164308 | AK386: =IF($AY5 > 0, AK5, AK5) -> 0.39074291 | AL386: =IF($AY5 > 0, AL5, AK5) -> 16.203612 | AM386: =IF($AY5 > 0, AM5, AK5) -> 16.05944 | AN386: =IF($AY5 > 0, AN5, AN5) -> 0.47795823 | AO386: =IF($AY5 > 0, AO5, AN5) -> 18.002718 | AP386: =IF($AY5 > 0, AP5, AP5) -> 0.093760519 | AQ386: =IF($AY5 > 0, AQ5, AP5) -> 15.472079 | AR386: =IF($AY5 > 0, AR5, AR5) -> 1.5593727 | AS386: =IF($AY5 > 0, AS5, AR5) -> 1.9501714 | AT386: =IF($AY5 > 0, AT5, AT5) -> 0.0095443826 | AU386: =IF($AY5 > 0, AU5, AT5) -> 63.289142
A387: 16 | B387: 140XXNN | C387: XYZW_CDE_1 | D387: {W, X, Y, Z} | F387: 0 | G387: 0 | H387: 0 | I387: =I6 -> 0 | J387: =J6 -> 1 | K387: 4 | L387: 0 | M387: =IF($AY6 > 0, M6, M6) -> 8924700.4 | N387: =IF($AY6 > 0, N6, M6) -> 7409128.2 | O387: =IF($AY6 > 0, O6, M6) -> 8008403.4 | P387: =IF($AY6 > 0, P6, P6) -> 45866083 | Q387: =IF($AY6 > 0, Q6, P6) -> 2391983.6 | R387: =IF($AY6 > 0, R6, R6) -> 32861528 | S387: =IF($AY6 > 0, S6, R6) -> 4941932.8 | T387: =IF($AY6 > 0, T6, T6) -> 6992038.2 | U387: =IF($AY6 > 0, U6, T6) -> 6557177.2 | V387: =IF($AY6 > 0, V6, V6) -> 45628441 | W387: =IF($AY6 > 0, W6, V6) -> 2389275.2 | Y387: =IF($AY6 > 0, Y6, Y6) -> 8.3352197 | Z387: =IF($AY6 > 0, Z6, Y6) -> 6.0984463 | AA387: =IF($AY6 > 0, AA6, Y6) -> 6.4174577 | AB387: =IF($AY6 > 0, AB6, AB6) -> 45.814646 | AC387: =IF($AY6 > 0, AC6, AB6) -> 3.8918628 | AD387: =IF($AY6 > 0, AD6, AD6) -> 28.794683 | AE387: =IF($AY6 > 0, AE6, AD6) -> 4.6747125 | AF387: =IF($AY6 > 0, AF6, AF6) -> 5.3608775 | AG387: =IF($AY6 > 0, AG6, AF6) -> 5.9139982 | AH387: =IF($AY6 > 0, AH6, AH6) -> 20.268796 | AI387: =IF($AY6 > 0, AI6, AH6) -> 7.9222033 | AK387: =IF($AY6 > 0, AK6, AK6) -> 8.3352197 | AL387: =IF($AY6 > 0, AL6, AK6) -> 2.355918 | AM387: =IF($AY6 > 0, AM6, AK6) -> 2.7064176 | AN387: =IF($AY6 > 0, AN6, AN6) -> 45.814646 | AO387: =IF($AY6 > 0, AO6, AN6) -> 1.6734524 | AP387: =IF($AY6 > 0, AP6, AP6) -> 28.794683 | AQ387: =IF($AY6 > 0, AQ6, AP6) -> 1.8495526 | AR387: =IF($AY6 > 0, AR6, AR6) -> 2.6965437 | AS387: =IF($AY6 > 0, AS6, AR6) -> 1.0172913 | AT387: =IF($AY6 > 0, AT6, AT6) -> 20.268796 | AU387: =IF($AY6 > 0, AU6, AT6) -> 6.2464678
A388: 16 | B388: 140XNXX | C388: XYZW_CDE_1 | D388: {W, X, Y, Z} | F388: 0 | G388: 1 | H388: 0 | I388: =I7 -> 0 | J388: =J7 -> 1 | K388: 4 | L388: 0 | M388: =IF($AY7 > 0, M7, M7) -> 5158435.4 | N388: =IF($AY7 > 0, N7, M7) -> 14680450 | O388: =IF($AY7 > 0, O7, M7) -> 14940966 | P388: =IF($AY7 > 0, P7, P7) -> 1107525.2 | Q388: =IF($AY7 > 0, Q7, P7) -> 6531484.6 | R388: =IF($AY7 > 0, R7, R7) -> 15828999 | S388: =IF($AY7 > 0, S7, R7) -> 9867056.8 | T388: =IF($AY7 > 0, T7, T7) -> 6997933 | U388: =IF($AY7 > 0, U7, T7) -> 6746446 | V388: =IF($AY7 > 0, V7, V7) -> 995651.4 | W388: =IF($AY7 > 0, W7, V7) -> 6365591.6 | Y388: =IF($AY7 > 0, Y7, Y7) -> 5.2934131 | Z388: =IF($AY7 > 0, Z7, Y7) -> 10.369151 | AA388: =IF($AY7 > 0, AA7, Y7) -> 10.636605 | AB388: =IF($AY7 > 0, AB7, AB7) -> 3.1010016 | AC388: =IF($AY7 > 0, AC7, AB7) -> 6.9747482 | AD388: =IF($AY7 > 0, AD7, AD7) -> 11.252564 | AE388: =IF($AY7 > 0, AE7, AD7) -> 7.3901065 | AF388: =IF($AY7 > 0, AF7, AF7) -> 5.3459433 | AG388: =IF($AY7 > 0, AG7, AF7) -> 6.0193059 | AH388: =IF($AY7 > 0, AH7, AH7) -> 3.3616486 | AI388: =IF($AY7 > 0, AI7, AH7) -> 12.230784 | AK388: =IF($AY7 > 0, AK7, AK7) -> 5.2934131 | AL388: =IF($AY7 > 0, AL7, AK7) -> 7.2439255 | AM388: =IF($AY7 > 0, AM7, AK7) -> 7.4596666 | AN388: =IF($AY7 > 0, AN7, AN7) -> 3.1010016 | AO388: =IF($AY7 > 0, AO7, AN7) -> 4.548577 | AP388: =IF($AY7 > 0, AP7, AP7) -> 11.252564 | AQ388: =IF($AY7 > 0, AQ7, AP7) -> 5.0335068 | AR388: =IF($AY7 > 0, AR7, AR7) -> 2.6907736 | AS388: =IF($AY7 > 0, AS7, AR7) -> 1.1611942 | AT388: =IF($AY7 > 0, AT7, AT7) -> 3.3616486 | AU388: =IF($AY7 > 0, AU7, AT7) -> 10.530713
A389: 16 | B389: 140XNXN | C389: XYZW_CDE_1 | D389: {W, X, Y, Z} | F389: 0 | G389: 0 | H389: 0 | I389: =I8 -> 0 | J389: =J8 -> 1 | K389: 4 | L389: 0 | M389: =IF($AY8 > 0, M8, M8) -> 8193988.8 | N389: =IF($AY8 > 0, N8, M8) -> 7572577.8 | O389: =IF($AY8 > 0, O8, M8) -> 7799412.2 | P389: =IF($AY8 > 0, P8, P8) -> 43487441 | Q389: =IF($AY8 > 0, Q8, P8) -> 2447008.4 | R389: =IF($AY8 > 0, R8, R8) -> 33722231 | S389: =IF($AY8 > 0, S8, R8) -> 4764328.4 | T389: =IF($AY8 > 0, T8, T8) -> 4863915.2 | U389: =IF($AY8 > 0, U8, T8) -> 9015117 | V389: =IF($AY8 > 0, V8, V8) -> 43754360 | W389: =IF($AY8 > 0, W8, V8) -> 2451575.6 | Y389: =IF($AY8 > 0, Y8, Y8) -> 8.718803 | Z389: =IF($AY8 > 0, Z8, Y8) -> 6.2436512 | AA389: =IF($AY8 > 0, AA8, Y8) -> 6.4057397 | AB389: =IF($AY8 > 0, AB8, AB8) -> 57.035831 | AC389: =IF($AY8 > 0, AC8, AB8) -> 3.9566089 | AD389: =IF($AY8 > 0, AD8, AD8) -> 33.487222 | AE389: =IF($AY8 > 0, AE8, AD8) -> 4.5003273 | AF389: =IF($AY8 > 0, AF8, AF8) -> 3.1851477 | AG389: =IF($AY8 > 0, AG8, AF8) -> 8.8742746 | AH389: =IF($AY8 > 0, AH8, AH8) -> 23.498301 | AI389: =IF($AY8 > 0, AI8, AH8) -> 8.0344333 | AK389: =IF($AY8 > 0, AK8, AK8) -> 8.718803 | AL389: =IF($AY8 > 0, AL8, AK8) -> 2.8248618 | AM389: =IF($AY8 > 0, AM8, AK8) -> 2.98238 | AN389: =IF($AY8 > 0, AN8, AN8) -> 57.035831 | AO389: =IF($AY8 > 0, AO8, AN8) -> 1.8182945 | AP389: =IF($AY8 > 0, AP8, AP8) -> 33.487222 | AQ389: =IF($AY8 > 0, AQ8, AP8) -> 1.971674 | AR389: =IF($AY8 > 0, AR8, AR8) -> 1.6033238 | AS389: =IF($AY8 > 0, AS8, AR8) -> 1.3793309 | AT389: =IF($AY8 > 0, AT8, AT8) -> 23.498301 | AU389: =IF($AY8 > 0, AU8, AT8) -> 6.3653759
A390: 16 | B390: 140XNNX | C390: XYZW_CDE_1 | D390: {W, X, Y, Z} | F390: 0 | G390: 0 | H390: 0 | I390: =I9 -> 0 | J390: =J9 -> 1 | K390: 4 | L390: 0 | M390: =IF($AY9 > 0, M9, M9) -> 8554688.4 | N390: =IF($AY9 > 0, N9, M9) -> 6983115.6 | O390: =IF($AY9 > 0, O9, M9) -> 7069681.6 | P390: =IF($AY9 > 0, P9, P9) -> 44846503 | Q390: =IF($AY9 > 0, Q9, P9) -> 2174907.6 | R390: =IF($AY9 > 0, R9, R9) -> 29785647 | S390: =IF($AY9 > 0, S9, R9) -> 4689817.4 | T390: =IF($AY9 > 0, T9, T9) -> 12226433 | U390: =IF($AY9 > 0, U9, T9) -> 8231681.2 | V390: =IF($AY9 > 0, V9, V9) -> 44907346 | W390: =IF($AY9 > 0, W9, V9) -> 2176271 | Y390: =IF($AY9 > 0, Y9, Y9) -> 6.8759735 | Z390: =IF($AY9 > 0, Z9, Y9) -> 5.3561867 | AA390: =IF($AY9 > 0, AA9, Y9) -> 5.4034892 | AB390: =IF($AY9 > 0, AB9, AB9) -> 16.397998 | AC390: =IF($AY9 > 0, AC9, AB9) -> 2.9147033 | AD390: =IF($AY9 > 0, AD9, AD9) -> 14.730603 | AE390: =IF($AY9 > 0, AE9, AD9) -> 4.2048363 | AF390: =IF($AY9 > 0, AF9, AF9) -> 11.196082 | AG390: =IF($AY9 > 0, AG9, AF9) -> 7.399013 | AH390: =IF($AY9 > 0, AH9, AH9) -> 13.141907 | AI390: =IF($AY9 > 0, AI9, AH9) -> 7.3212978 | AK390: =IF($AY9 > 0, AK9, AK9) -> 6.8759735 | AL390: =IF($AY9 > 0, AL9, AK9) -> 2.074127 | AM390: =IF($AY9 > 0, AM9, AK9) -> 2.1092932 | AN390: =IF($AY9 > 0, AN9, AN9) -> 16.397998 | AO390: =IF($AY9 > 0, AO9, AN9) -> 1.1238348 | AP390: =IF($AY9 > 0, AP9, AP9) -> 14.730603 | AQ390: =IF($AY9 > 0, AQ9, AP9) -> 1.6821303 | AR390: =IF($AY9 > 0, AR9, AR9) -> 5.6279324 | AS390: =IF($AY9 > 0, AS9, AR9) -> 1.030098 | AT390: =IF($AY9 > 0, AT9, AT9) -> 13.141907 | AU390: =IF($AY9 > 0, AU9, AT9) -> 5.7618104
A391: 16 | B391: 140XNNN | C391: XYZW_CDE_1 | D391: {W, X, Y, Z} | F391: 0 | G391: 1 | H391: 0 | I391: =I10 -> 0 | J391: =J10 -> 1 | K391: 4 | L391: 0 | M391: =IF($AY10 > 0, M10, M10) -> 56319775 | N391: =IF($AY10 > 0, N10, M10) -> 13746114 | O391: =IF($AY10 > 0, O10, M10) -> 13826027 | P391: =IF($AY10 > 0, P10, P10) -> 8126486.2 | Q391: =IF($AY10 > 0, Q10, P10) -> 4466444.6 | R391: =IF($AY10 > 0, R10, R10) -> 1.7335886e+08 | S391: =IF($AY10 > 0, S10, R10) -> 7820700.6 | T391: =IF($AY10 > 0, T10, T10) -> 12243896 | U391: =IF($AY10 > 0, U10, T10) -> 8430593.6 | V391: =IF($AY10 > 0, V10, V10) -> 7475389.2 | W391: =IF($AY10 > 0, W10, V10) -> 4447037.6 | Y391: =IF($AY10 > 0, Y10, Y10) -> 40.000053 | Z391: =IF($AY10 > 0, Z10, Y10) -> 9.0232293 | AA391: =IF($AY10 > 0, AA10, Y10) -> 9.0743813 | AB391: =IF($AY10 > 0, AB10, AB10) -> 18.426652 | AC391: =IF($AY10 > 0, AC10, AB10) -> 4.398745 | AD391: =IF($AY10 > 0, AD10, AD10) -> 98.789366 | AE391: =IF($AY10 > 0, AE10, AD10) -> 5.9889844 | AF391: =IF($AY10 > 0, AF10, AF10) -> 11.160405 | AG391: =IF($AY10 > 0, AG10, AF10) -> 7.6981045 | AH391: =IF($AY10 > 0, AH10, AH10) -> 5.7611584 | AI391: =IF($AY10 > 0, AI10, AH10) -> 9.3660966 | AK391: =IF($AY10 > 0, AK10, AK10) -> 40.000053 | AL391: =IF($AY10 > 0, AL10, AK10) -> 4.6186065 | AM391: =IF($AY10 > 0, AM10, AK10) -> 4.6548278 | AN391: =IF($AY10 > 0, AN10, AN10) -> 18.426652 | AO391: =IF($AY10 > 0, AO10, AN10) -> 2.5702454 | AP391: =IF($AY10 > 0, AP10, AP10) -> 98.789366 | AQ391: =IF($AY10 > 0, AQ10, AP10) -> 3.02659 | AR391: =IF($AY10 > 0, AR10, AR10) -> 5.6154052 | AS391: =IF($AY10 > 0, AS10, AR10) -> 1.1594838 | AT391: =IF($AY10 > 0, AT10, AT10) -> 5.7611584 | AU391: =IF($AY10 > 0, AU10, AT10) -> 7.8717986
A392: 16 | B392: 140NXXX | C392: XYZW_CDE_1 | D392: {W, X, Y, Z} | F392: 0 | G392: 1 | H392: 0 | I392: =I11 -> 0 | J392: =J11 -> 1 | K392: 4 | L392: 0 | M392: =IF($AY11 > 0, M11, M11) -> 55796751 | N392: =IF($AY11 > 0, N11, M11) -> 13726864 | O392: =IF($AY11 > 0, O11, M11) -> 13821888 | P392: =IF($AY11 > 0, P11, P11) -> 8533125.2 | Q392: =IF($AY11 > 0, Q11, P11) -> 4460185.6 | R392: =IF($AY11 > 0, R11, R11) -> 1.8483866e+08 | S392: =IF($AY11 > 0, S11, R11) -> 7855858.8 | T392: =IF($AY11 > 0, T11, T11) -> 12277478 | U392: =IF($AY11 > 0, U11, T11) -> 8441799.6 | V392: =IF($AY11 > 0, V11, V11) -> 8112431.4 | W392: =IF($AY11 > 0, W11, V11) -> 4445249.6 | Y392: =IF($AY11 > 0, Y11, Y11) -> 39.339939 | Z392: =IF($AY11 > 0, Z11, Y11) -> 9.0385466 | AA392: =IF($AY11 > 0, AA11, Y11) -> 9.0318456 | AB392: =IF($AY11 > 0, AB11, AB11) -> 21.128127 | AC392: =IF($AY11 > 0, AC11, AB11) -> 4.2889346 | AD392: =IF($AY11 > 0, AD11, AD11) -> 106.89758 | AE392: =IF($AY11 > 0, AE11, AD11) -> 5.9901159 | AF392: =IF($AY11 > 0, AF11, AF11) -> 11.134629 | AG392: =IF($AY11 > 0, AG11, AF11) -> 7.6585643 | AH392: =IF($AY11 > 0, AH11, AH11) -> 6.0555398 | AI392: =IF($AY11 > 0, AI11, AH11) -> 9.2760553 | AK392: =IF($AY11 > 0, AK11, AK11) -> 39.339939 | AL392: =IF($AY11 > 0, AL11, AK11) -> 4.6513705 | AM392: =IF($AY11 > 0, AM11, AK11) -> 4.6417304 | AN392: =IF($AY11 > 0, AN11, AN11) -> 21.128127 | AO392: =IF($AY11 > 0, AO11, AN11) -> 2.5462631 | AP392: =IF($AY11 > 0, AP11, AP11) -> 106.89758 | AQ392: =IF($AY11 > 0, AQ11, AP11) -> 3.0045074 | AR392: =IF($AY11 > 0, AR11, AR11) -> 5.6129122 | AS392: =IF($AY11 > 0, AS11, AR11) -> 1.1325233 | AT392: =IF($AY11 > 0, AT11, AT11) -> 6.0555398 | AU392: =IF($AY11 > 0, AU11, AT11) -> 7.7788019
A393: 16 | B393: 140NXXN | C393: XYZW_CDE_1 | D393: {W, X, Y, Z} | F393: 0 | G393: 0 | H393: 0 | I393: =I12 -> 0 | J393: =J12 -> 1 | K393: 4 | L393: 0 | M393: =IF($AY12 > 0, M12, M12) -> 8492168.2 | N393: =IF($AY12 > 0, N12, M12) -> 7088759.6 | O393: =IF($AY12 > 0, O12, M12) -> 7497002.4 | P393: =IF($AY12 > 0, P12, P12) -> 42293061 | Q393: =IF($AY12 > 0, Q12, P12) -> 2448847 | R393: =IF($AY12 > 0, R12, R12) -> 33533661 | S393: =IF($AY12 > 0, S12, R12) -> 4796724 | T393: =IF($AY12 > 0, T12, T12) -> 12208411 | U393: =IF($AY12 > 0, U12, T12) -> 8227841.6 | V393: =IF($AY12 > 0, V12, V12) -> 42352359 | W393: =IF($AY12 > 0, W12, V12) -> 2413346.8 | Y393: =IF($AY12 > 0, Y12, Y12) -> 6.8997929 | Z393: =IF($AY12 > 0, Z12, Y12) -> 5.4792542 | AA393: =IF($AY12 > 0, AA12, Y12) -> 5.6427513 | AB393: =IF($AY12 > 0, AB12, AB12) -> 15.954466 | AC393: =IF($AY12 > 0, AC12, AB12) -> 3.1530935 | AD393: =IF($AY12 > 0, AD12, AD12) -> 17.62848 | AE393: =IF($AY12 > 0, AE12, AD12) -> 4.399916 | AF393: =IF($AY12 > 0, AF12, AF12) -> 11.249559 | AG393: =IF($AY12 > 0, AG12, AF12) -> 7.4536045 | AH393: =IF($AY12 > 0, AH12, AH12) -> 13.032308 | AI393: =IF($AY12 > 0, AI12, AH12) -> 7.6959233 | AK393: =IF($AY12 > 0, AK12, AK12) -> 6.8997929 | AL393: =IF($AY12 > 0, AL12, AK12) -> 1.9253941 | AM393: =IF($AY12 > 0, AM12, AK12) -> 2.102224 | AN393: =IF($AY12 > 0, AN12, AN12) -> 15.954466 | AO393: =IF($AY12 > 0, AO12, AN12) -> 1.1451233 | AP393: =IF($AY12 > 0, AP12, AP12) -> 17.62848 | AQ393: =IF($AY12 > 0, AQ12, AP12) -> 1.5998279 | AR393: =IF($AY12 > 0, AR12, AR12) -> 5.6642394 | AS393: =IF($AY12 > 0, AS12, AR12) -> 1.0535307 | AT393: =IF($AY12 > 0, AT12, AT12) -> 13.032308 | AU393: =IF($AY12 > 0, AU12, AT12) -> 6.0133742
A394: 16 | B394: 140NXNX | C394: XYZW_CDE_1 | D394: {W, X, Y, Z} | F394: 0 | G394: 0 | H394: 0 | I394: =I13 -> 0 | J394: =J13 -> 1 | K394: 4 | L394: 0 | M394: =IF($AY13 > 0, M13, M13) -> 8699537.4 | N394: =IF($AY13 > 0, N13, M13) -> 7320627.4 | O394: =IF($AY13 > 0, O13, M13) -> 7835053.6 | P394: =IF($AY13 > 0, P13, P13) -> 40600807 | Q394: =IF($AY13 > 0, Q13, P13) -> 2182263.8 | R394: =IF($AY13 > 0, R13, R13) -> 29943482 | S394: =IF($AY13 > 0, S13, R13) -> 4675099.8 | T394: =IF($AY13 > 0, T13, T13) -> 4874009.8 | U394: =IF($AY13 > 0, U13, T13) -> 8955103.4 | V394: =IF($AY13 > 0, V13, V13) -> 40872901 | W394: =IF($AY13 > 0, W13, V13) -> 2204938 | Y394: =IF($AY13 > 0, Y13, Y13) -> 9.1724837 | Z394: =IF($AY13 > 0, Z13, Y13) -> 6.0100012 | AA394: =IF($AY13 > 0, AA13, Y13) -> 6.3982213 | AB394: =IF($AY13 > 0, AB13, AB13) -> 52.514124 | AC394: =IF($AY13 > 0, AC13, AB13) -> 3.7071955 | AD394: =IF($AY13 > 0, AD13, AD13) -> 31.588085 | AE394: =IF($AY13 > 0, AE13, AD13) -> 4.3888467 | AF394: =IF($AY13 > 0, AF13, AF13) -> 3.1648169 | AG394: =IF($AY13 > 0, AG13, AF13) -> 8.8130048 | AH394: =IF($AY13 > 0, AH13, AH13) -> 22.22063 | AI394: =IF($AY13 > 0, AI13, AH13) -> 7.565635 | AK394: =IF($AY13 > 0, AK13, AK13) -> 9.1724837 | AL394: =IF($AY13 > 0, AL13, AK13) -> 2.4404086 | AM394: =IF($AY13 > 0, AM13, AK13) -> 2.8214012 | AN394: =IF($AY13 > 0, AN13, AN13) -> 52.514124 | AO394: =IF($AY13 > 0, AO13, AN13) -> 1.739686 | AP394: =IF($AY13 > 0, AP13, AP13) -> 31.588085 | AQ394: =IF($AY13 > 0, AQ13, AP13) -> 1.8771214 | AR394: =IF($AY13 > 0, AR13, AR13) -> 1.594012 | AS394: =IF($AY13 > 0, AS13, AR13) -> 1.378379 | AT394: =IF($AY13 > 0, AT13, AT13) -> 22.22063 | AU394: =IF($AY13 > 0, AU13, AT13) -> 5.946122
A395: 16 | B395: 140NXNN | C395: XYZW_CDE_1 | D395: {W, X, Y, Z} | F395: 0 | G395: 1 | H395: 0 | I395: =I14 -> 0 | J395: =J14 -> 1 | K395: 4 | L395: 0 | M395: =IF($AY14 > 0, M14, M14) -> 4988107.6 | N395: =IF($AY14 > 0, N14, M14) -> 11904907 | O395: =IF($AY14 > 0, O14, M14) -> 13019785 | P395: =IF($AY14 > 0, P14, P14) -> 925137.4 | Q395: =IF($AY14 > 0, Q14, P14) -> 5874640 | R395: =IF($AY14 > 0, R14, R14) -> 14797049 | S395: =IF($AY14 > 0, S14, R14) -> 9694202.4 | T395: =IF($AY14 > 0, T14, T14) -> 6991416 | U395: =IF($AY14 > 0, U14, T14) -> 6661674.4 | V395: =IF($AY14 > 0, V14, V14) -> 910615 | W395: =IF($AY14 > 0, W14, V14) -> 5826628.6 | Y395: =IF($AY14 > 0, Y14, Y14) -> 5.1237474 | Z395: =IF($AY14 > 0, Z14, Y14) -> 8.5741391 | AA395: =IF($AY14 > 0, AA14, Y14) -> 9.2550602 | AB395: =IF($AY14 > 0, AB14, AB14) -> 3.1918146 | AC395: =IF($AY14 > 0, AC14, AB14) -> 6.5925752 | AD395: =IF($AY14 > 0, AD14, AD14) -> 11.68775 | AE395: =IF($AY14 > 0, AE14, AD14) -> 7.3581684 | AF395: =IF($AY14 > 0, AF14, AF14) -> 5.3411736 | AG395: =IF($AY14 > 0, AG14, AF14) -> 5.9728484 | AH395: =IF($AY14 > 0, AH14, AH14) -> 3.3252139 | AI395: =IF($AY14 > 0, AI14, AH14) -> 12.494886 | AK395: =IF($AY14 > 0, AK14, AK14) -> 5.1237474 | AL395: =IF($AY14 > 0, AL14, AK14) -> 5.4301673 | AM395: =IF($AY14 > 0, AM14, AK14) -> 6.0952462 | AN395: =IF($AY14 > 0, AN14, AN14) -> 3.1918146 | AO395: =IF($AY14 > 0, AO14, AN14) -> 4.1413953 | AP395: =IF($AY14 > 0, AP14, AP14) -> 11.68775 | AQ395: =IF($AY14 > 0, AQ14, AP14) -> 5.1534886 | AR395: =IF($AY14 > 0, AR14, AR14) -> 2.687886 | AS395: =IF($AY14 > 0, AS14, AR14) -> 1.1590046 | AT395: =IF($AY14 > 0, AT14, AT14) -> 3.3252139 | AU395: =IF($AY14 > 0, AU14, AT14) -> 10.793377
... A759: 3 | B759: 121NN | C759: XYZ_C_1_j | D759: {X, Z} | F759: 0 | G759: 0 | H759: 0 | I759: =I378 -> 0 | J759: =J378 -> 1 | K759: 2 | L759: 0 | M759: =IF($AY378 > 0, M378, M378) -> 200049.4 | N759: =IF($AY378 > 0, N378, M378) -> 1263909.8 | O759: =IF($AY378 > 0, O378, M378) -> 1264389.4 | P759: =IF($AY378 > 0, P378, P378) -> 199999.4 | Q759: =IF($AY378 > 0, Q378, P378) -> 3028225.6 | R759: =IF($AY378 > 0, R378, R378) -> 2.4 | S759: =IF($AY378 > 0, S378, R378) -> 1766585.8 | T759: =IF($AY378 > 0, T378, T378) -> 2917511.4 | U759: =IF($AY378 > 0, U378, T378) -> 2338051.8 | V759: =IF($AY378 > 0, V378, V378) -> 287 | W759: =IF($AY378 > 0, W378, V378) -> 4993232.8 | Y759: =IF($AY378 > 0, Y378, Y378) -> 0.26880861 | Z759: =IF($AY378 > 0, Z378, Y378) -> 1.4875847 | AA759: =IF($AY378 > 0, AA378, Y378) -> 1.4593282 | AB759: =IF($AY378 > 0, AB378, AB378) -> 0.28692743 | AC759: =IF($AY378 > 0, AC378, AB378) -> 2.5370245 | AD759: =IF($AY378 > 0, AD378, AD378) -> 0.086515733 | AE759: =IF($AY378 > 0, AE378, AD378) -> 1.4366914 | AF759: =IF($AY378 > 0, AF378, AF378) -> 0.59808919 | AG759: =IF($AY378 > 0, AG378, AF378) -> 0.85012241 | AH759: =IF($AY378 > 0, AH378, AH378) -> 0.006017534 | AI759: =IF($AY378 > 0, AI378, AH378) -> 4.1640872 | AK759: =IF($AY378 > 0, AK378, AK378) -> 0.26880861 | AL759: =IF($AY378 > 0, AL378, AK378) -> 0.5193468 | AM759: =IF($AY378 > 0, AM378, AK378) -> 0.49975418 | AN759: =IF($AY378 > 0, AN378, AN378) -> 0.28692743 | AO759: =IF($AY378 > 0, AO378, AN378) -> 0.79595701 | AP759: =IF($AY378 > 0, AP378, AP378) -> 0.086515733 | AQ759: =IF($AY378 > 0, AQ378, AP378) -> 0.51856978 | AR759: =IF($AY378 > 0, AR378, AR378) -> 0.30278843 | AS759: =IF($AY378 > 0, AS378, AR378) -> 0.3125567 | AT759: =IF($AY378 > 0, AT378, AT378) -> 0.006017534 | AU759: =IF($AY378 > 0, AU378, AT378) -> 2.1368226
M764: BNL | N764: BNL Causal | O764: BNL Causal HM | P764: SFS | Q764: SFS Causal | R764: SaLSa | S764: SaLSa Causal | T764: D&C | U764: D&C Causal | V764: BBS | W764: BBS Causal | Y764: BNL | Z764: BNL Causal | AA764: BNL Causal HM | AB764: SFS | AC764: SFS Causal | AD764: SaLSa | AE764: SaLSa Causal | AF764: D&C | AG764: D&C Causal | AH764: BBS | AI764: BBS Causal | AK764: BNL | AL764: BNL Causal | AM764: BNL Causal HM | AN764: SFS | AO764: SFS Causal | AP764: SaLSa | AQ764: SaLSa Causal | AR764: D&C | AS764: D&C Causal | AT764: BBS | AU764: BBS Causal
L765: Mean | M765: =AVERAGEIF($H$384:$H$759, "=1", M384:M759) -> 13369038 | N765: =AVERAGEIF($H$384:$H$759, "=1", N384:N759) -> 9296022.8 | O765: =AVERAGEIF($H$384:$H$759, "=1", O384:O759) -> 9595734.3 | P765: =AVERAGEIF($H$384:$H$759, "=1", P384:P759) -> 11598037 | Q765: =AVERAGEIF($H$384:$H$759, "=1", Q384:Q759) -> 5549486.9 | R765: =AVERAGEIF($H$384:$H$759, "=1", R384:R759) -> 40102255 | S765: =AVERAGEIF($H$384:$H$759, "=1", S384:S759) -> 7086008.9 | T765: =AVERAGEIF($H$384:$H$759, "=1", T384:T759) -> 6445481.3 | ... W765: =AVERAGEIF($H$384:$H$759, "=1", W384:W759) -> 5687261.6 | X765: Mean | Y765: =AVERAGEIF($H$384:$H$759, "=1", Y384:Y759) -> 11.024039 | Z765: =AVERAGEIF($H$384:$H$759, "=1", Z384:Z759) -> 6.8874324 | AA765: =AVERAGEIF($H$384:$H$759, "=1", AA384:AA759) -> 7.012927 | AB765: =AVERAGEIF($H$384:$H$759, "=1", AB384:AB759) -> 12.924622 | AC765: =AVERAGEIF($H$384:$H$759, "=1", AC384:AC759) -> 5.9856222 | AD765: =AVERAGEIF($H$384:$H$759, "=1", AD384:AD759) -> 25.602229 | AE765: =AVERAGEIF($H$384:$H$759, "=1", AE384:AE759) -> 5.6013167 | AF765: =AVERAGEIF($H$384:$H$759, "=1", AF384:AF759) -> 4.5333497 | ... AI765: =AVERAGEIF($H$384:$H$759, "=1", AI384:AI759) -> 10.488216 | AJ765: Mean | AK765: =AVERAGEIF($H$384:$H$759, "=1", AK384:AK759) -> 11.024039 | AL765: =AVERAGEIF($H$384:$H$759, "=1", AL384:AL759) -> 2.7120447 | AM765: =AVERAGEIF($H$384:$H$759, "=1", AM384:AM759) -> 2.8573355 | AN765: =AVERAGEIF($H$384:$H$759, "=1", AN384:AN759) -> 12.924622 | AO765: =AVERAGEIF($H$384:$H$759, "=1", AO384:AO759) -> 2.3026816 | AP765: =AVERAGEIF($H$384:$H$759, "=1", AP384:AP759) -> 25.602229 | AQ765: =AVERAGEIF($H$384:$H$759, "=1", AQ384:AQ759) -> 2.0705794 | AR765: =AVERAGEIF($H$384:$H$759, "=1", AR384:AR759) -> 2.2830626 | ... AU765: =AVERAGEIF($H$384:$H$759, "=1", AU384:AU759) -> 8.222373
L766: Median | M766: {=MEDIAN(_xlfn._xlws.FILTER(M384:M759, $H$384:$H$759=1))} -> 5790166.2 | N766: {=MEDIAN(_xlfn._xlws.FILTER(N384:N759, $H$384:$H$759=1))} -> 5062379.8 | O766: {=MEDIAN(_xlfn._xlws.FILTER(O384:O759, $H$384:$H$759=1))} -> 5105462.5 | P766: {=MEDIAN(_xlfn._xlws.FILTER(P384:P759, $H$384:$H$759=1))} -> 2151958 | Q766: {=MEDIAN(_xlfn._xlws.FILTER(Q384:Q759, $H$384:$H$759=1))} -> 2403913.2 | R766: {=MEDIAN(_xlfn._xlws.FILTER(R384:R759, $H$384:$H$759=1))} -> 9606697.2 | S766: {=MEDIAN(_xlfn._xlws.FILTER(S384:S759, $H$384:$H$759=1))} -> 3230430.7 | T766: {=MEDIAN(_xlfn._xlws.FILTER(T384:T759, $H$384:$H$759=1))} -> 4841202 | ... W766: {=MEDIAN(_xlfn._xlws.FILTER(W384:W759, $H$384:$H$759=1))} -> 2394278.5 | X766: Median | Y766: {=MEDIAN(_xlfn._xlws.FILTER(Y384:Y759, $H$384:$H$759=1))} -> 4.3248346 | Z766: {=MEDIAN(_xlfn._xlws.FILTER(Z384:Z759, $H$384:$H$759=1))} -> 4.2917365 | AA766: {=MEDIAN(_xlfn._xlws.FILTER(AA384:AA759, $H$384:$H$759=1))} -> 4.1655599 | AB766: {=MEDIAN(_xlfn._xlws.FILTER(AB384:AB759, $H$384:$H$759=1))} -> 2.9697615 | AC766: {=MEDIAN(_xlfn._xlws.FILTER(AC384:AC759, $H$384:$H$759=1))} -> 2.8401679 | AD766: {=MEDIAN(_xlfn._xlws.FILTER(AD384:AD759, $H$384:$H$759=1))} -> 7.9228538 | AE766: {=MEDIAN(_xlfn._xlws.FILTER(AE384:AE759, $H$384:$H$759=1))} -> 2.9022839 | AF766: {=MEDIAN(_xlfn._xlws.FILTER(AF384:AF759, $H$384:$H$759=1))} -> 3.1197747 | ... AI766: {=MEDIAN(_xlfn._xlws.FILTER(AI384:AI759, $H$384:$H$759=1))} -> 5.8732832 | AJ766: Median | AK766: {=MEDIAN(_xlfn._xlws.FILTER(AK384:AK759, $H$384:$H$759=1))} -> 4.3248346 | AL766: {=MEDIAN(_xlfn._xlws.FILTER(AL384:AL759, $H$384:$H$759=1))} -> 1.4749515 | AM766: {=MEDIAN(_xlfn._xlws.FILTER(AM384:AM759, $H$384:$H$759=1))} -> 1.4280732 | AN766: {=MEDIAN(_xlfn._xlws.FILTER(AN384:AN759, $H$384:$H$759=1))} -> 2.9697615 | AO766: {=MEDIAN(_xlfn._xlws.FILTER(AO384:AO759, $H$384:$H$759=1))} -> 1.0805846 | AP766: {=MEDIAN(_xlfn._xlws.FILTER(AP384:AP759, $H$384:$H$759=1))} -> 7.9228538 | AQ766: {=MEDIAN(_xlfn._xlws.FILTER(AQ384:AQ759, $H$384:$H$759=1))} -> 1.2046911 | AR766: {=MEDIAN(_xlfn._xlws.FILTER(AR384:AR759, $H$384:$H$759=1))} -> 1.5726851 | ... AU766: {=MEDIAN(_xlfn._xlws.FILTER(AU384:AU759, $H$384:$H$759=1))} -> 3.9873482
M769: BNL Causal | N769: BNL Causal HM | O769: SFS Causal | P769: SaLSa Causal | Q769: D&C Causal | R769: BBS Causal | T769: BNL Causal | U769: BNL Causal HM | V769: SFS Causal | W769: SaLSa Causal | X769: D&C Causal | Y769: BBS Causal | AA769: BNL Causal | AB769: BNL Causal HM | AC769: SFS Causal | AD769: SaLSa Causal | AE769: D&C Causal | AF769: BBS Causal
L770: Mean | M770: =N765 -> 9296022.8 | N770: =O765 -> 9595734.3 | O770: =Q765 -> 5549486.9 | P770: =S765 -> 7086008.9 | Q770: =U765 -> 5350749 | R770: =W765 -> 5687261.6 | S770: Mean | T770: =Z765 -> 6.8874324 | U770: =AA765 -> 7.012927 | V770: =AC765 -> 5.9856222 | W770: =AE765 -> 5.6013167 | X770: =AG765 -> 4.2682704 | Y770: =AI765 -> 10.488216 | Z770: Mean | AA770: =AL765 -> 2.7120447 | AB770: =AM765 -> 2.8573355 | AC770: =AO765 -> 2.3026816 | AD770: =AQ765 -> 2.0705794 | AE770: =AS765 -> 0.77009955 | AF770: =AU765 -> 8.222373
L771: Median | M771: =N766 -> 5062379.8 | N771: =O766 -> 5105462.5 | O771: =Q766 -> 2403913.2 | P771: =S766 -> 3230430.7 | Q771: =U766 -> 4338669.7 | R771: =W766 -> 2394278.5 | S771: Median | T771: =Z766 -> 4.2917365 | U771: =AA766 -> 4.1655599 | V771: =AC766 -> 2.8401679 | W771: =AE766 -> 2.9022839 | X771: =AG766 -> 2.8458391 | Y771: =AI766 -> 5.8732832 | Z771: Median | AA771: =AL766 -> 1.4749515 | AB771: =AM766 -> 1.4280732 | AC771: =AO766 -> 1.0805846 | AD771: =AQ766 -> 1.2046911 | AE771: =AS766 -> 0.57783384 | AF771: =AU766 -> 3.9873482

Sheet ddSky
M1: Average Benchmark (results) | Y1: Average Benchmark (sequential timing) | AK1: Average Benchmark (parallel timing) | AW1: Average Benchmark (cluster_time)
F2: TargetN | G2: #N | H2: Target (or sym) | I2: Gain <=0 | J2: Gain > 0 | K2: Pref | L2: Pref&Target | M2: BNL | N2: BNL Causal | O2: BNL Causal HM | P2: SFS | Q2: SFS Causal | R2: SaLSa | S2: SaLSa Causal | T2: D&C | U2: D&C Causal | V2: BBS | W2: BBS Causal | Y2: BNL | Z2: BNL Causal | AA2: BNL Causal HM | AB2: SFS | AC2: SFS Causal | AD2: SaLSa | AE2: SaLSa Causal | AF2: D&C | AG2: D&C Causal | AH2: BBS | AI2: BBS Causal | AK2: BNL | AL2: BNL Causal | AM2: BNL Causal HM | AN2: SFS | AO2: SFS Causal | AP2: SaLSa | AQ2: SaLSa Causal | AR2: D&C | AS2: D&C Causal | AT2: BBS | AU2: BBS Causal | AW2: KMeans Time (seconds) | AY2: Gain
A3: 16 | B3: 140XXXX | C3: XYZW_CDE_1 | D3: {W, X, Y, Z} | F3: 0 | G3: 0 | H3: 1 | I3: =1 - J3 -> 0 | J3: =IF(AY3 > 0, 1, 0) -> 1 | K3: 4 | L3: 4 | M3: 8651928.8 | N3: 1939638.8 | O3: 1979103.2 | P3: 42301553 | Q3: 676220.4 | R3: 30213745 | S3: 620102 | T3: 12092496 | U3: 6999253.4 | V3: 42235243 | W3: 911304.2 | Y3: 7.0029691 | Z3: 1.8646784 | AA3: 1.8852114 | AB3: 26.626281 | AC3: 1.1990045 | AD3: 19.140483 | AE3: 0.8820702 | AF3: 11.034486 | AG3: 6.2040017 | AH3: 17.233339 | AI3: 2.9734621 | AK3: 7.0029691 | AL3: 0.75306083 | AM3: 0.76777357 | AN3: 26.626281 | AO3: 0.53748923 | AP3: 19.140483 | AQ3: 0.50697361 | AR3: 5.5581718 | AS3: 0.80067531 | AT3: 17.233339 | AU3: 1.6044766 | AW3: 0.24731838 | AY3: 1.8292315
A4: 16 | B4: 140XXXN | C4: XYZW_CDE_1 | D4: {W, X, Y, Z} | F4: 0 | G4: 1 | H4: 0 | I4: =1 - J4 -> 0 | J4: =IF(AY4 > 0, 1, 0) -> 1 | K4: 4 | L4: 0 | M4: 55059286 | N4: 19870315 | O4: 20564047 | P4: 7914061.6 | Q4: 5789603.4 | R4: 1.7730778e+08 | S4: 12289819 | T4: 12368258 | U4: 8071990.6 | V4: 7611280.2 | W4: 5309479.8 | Y4: 40.289084 | Z4: 13.531542 | AA4: 13.768658 | AB4: 16.49666 | AC4: 5.5121838 | AD4: 109.80864 | AE4: 10.374894 | AF4: 12.101945 | AG4: 7.6646285 | AH4: 6.4325647 | AI4: 12.885179 | AK4: 40.289084 | AL4: 6.4762061 | AM4: 6.747376 | AN4: 16.49666 | AO4: 2.6998221 | AP4: 109.80864 | AQ4: 4.5908101 | AR4: 6.1050322 | AS4: 1.1244617 | AT4: 6.4325647 | AU4: 10.941839 | AW4: 0.269484 | AY4: 2.0252728
A5: 16 | B5: 140XXNX | C5: XYZW_CDE_1 | D5: {W, X, Y, Z} | F5: 0 | G5: 1 | H5: 0 | I5: =1 - J5 -> 1 | J5: =IF(AY5 > 0, 1, 0) -> 0 | K5: 4 | L5: 0 | M5: 201664.6 | N5: 2121193.2 | O5: 2121661.2 | P5: 200058.8 | Q5: 661809.2 | R5: 92.2 | S5: 858791.4 | T5: 4811088.6 | U5: 7062555.2 | V5: 1040 | W5: 1296294.4 | Y5: 0.41026625 | Z5: 2.2983697 | AA5: 2.2756128 | AB5: 0.40855898 | AC5: 1.4410402 | AD5: 0.10713515 | AE5: 1.1377476 | AF5: 3.2429071 | AG5: 6.613531 | AH5: 0.010177862 | AI5: 3.9971569 | AK5: 0.41026625 | AL5: 0.66193203 | AM5: 0.65393671 | AN5: 0.40855898 | AO5: 0.4795372 | AP5: 0.10713515 | AQ5: 0.4623781 | AR5: 1.6386077 | AS5: 0.88541532 | AT5: 0.010177862 | AU5: 2.4588408 | AW5: 0.27673442 | AY5: -7.4532494
A6: 16 | B6: 140XXNN | C6: XYZW_CDE_1 | D6: {W, X, Y, Z} | F6: 0 | G6: 0 | H6: 0 | I6: =1 - J6 -> 1 | J6: =IF(AY6 > 0, 1, 0) -> 0 | K6: 4 | L6: 0 | M6: 8924700.4 | N6: 14082969 | O6: 14721485 | P6: 45866083 | Q6: 3704201 | R6: 32861528 | S6: 10907250 | T6: 6992038.2 | U6: 7833971.8 | V6: 45628441 | W6: 3652176.8 | Y6: 8.4352457 | Z6: 10.571183 | AA6: 11.017402 | AB6: 41.603434 | AC6: 5.0989575 | AD6: 30.069197 | AE6: 9.5054344 | AF6: 5.6150096 | AG6: 7.4259171 | AH6: 21.805303 | AI6: 13.498563 | AK6: 8.4352457 | AL6: 3.156691 | AM6: 3.5583671 | AN6: 41.603434 | AO6: 2.0504008 | AP6: 30.069197 | AQ6: 3.0729869 | AR6: 2.8258224 | AS6: 0.98074899 | AT6: 21.805303 | AU6: 11.50422 | AW6: 0.27356971 | AY6: -1.1796417
A7: 16 | B7: 140XNXX | C7: XYZW_CDE_1 | D7: {W, X, Y, Z} | F7: 0 | G7: 1 | H7: 0 | I7: =1 - J7 -> 0 | J7: =IF(AY7 > 0, 1, 0) -> 1 | K7: 4 | L7: 0 | M7: 5158435.4 | N7: 2914997.2 | O7: 3022361.6 | P7: 1107525.2 | Q7: 716613.6 | R7: 15828999 | S7: 1493797.4 | T7: 6997933 | U7: 7600664 | V7: 995651.4 | W7: 1188106.6 | Y7: 5.4194259 | Z7: 2.8063731 | AA7: 2.8408096 | AB7: 2.8009719 | AC7: 1.4421585 | AD7: 11.527678 | AE7: 1.5443718 | AF7: 5.5164533 | AG7: 7.0572001 | AH7: 3.5554399 | AI7: 4.1863003 | AK7: 5.4194259 | AL7: 1.0300458 | AM7: 1.0744855 | AN7: 2.8009719 | AO7: 0.54824263 | AP7: 11.527678 | AQ7: 0.66036091 | AR7: 2.7755525 | AS7: 0.91471051 | AT7: 3.5554399 | AU7: 2.700941 | AW7: 0.28151554 | AY7: 3.4072685
A8: 16 | B8: 140XNXN | C8: XYZW_CDE_1 | D8: {W, X, Y, Z} | F8: 0 | G8: 0 | H8: 0 | I8: =1 - J8 -> 1 | J8: =IF(AY8 > 0, 1, 0) -> 0 | K8: 4 | L8: 0 | M8: 8193988.8 | N8: 14811271 | O8: 15478715 | P8: 43487441 | Q8: 3495525.8 | R8: 33722231 | S8: 11053510 | T8: 4863915.2 | U8: 7367021.2 | V8: 43754360 | W8: 3483728.6 | Y8: 9.1867372 | Z8: 11.787643 | AA8: 12.291397 | AB8: 51.541268 | AC8: 5.3053468 | AD8: 35.374924 | AE8: 10.218099 | AF8: 3.3895687 | AG8: 7.0535144 | AH8: 25.535806 | AI8: 13.793102 | AK8: 9.1867372 | AL8: 3.7746083 | AM8: 4.2961292 | AN8: 51.541268 | AO8: 2.2286103 | AP8: 35.374924 | AQ8: 3.260802 | AR8: 1.7121658 | AS8: 0.95861108 | AT8: 25.535806 | AU8: 11.654354 | AW8: 0.28875604 | AY8: -1.1806375
A9: 16 | B9: 140XNNX | C9: XYZW_CDE_1 | D9: {W, X, Y, Z} | F9: 0 | G9: 0 | H9: 0 | I9: =1 - J9 -> 0 | J9: =IF(AY9 > 0, 1, 0) -> 1 | K9: 4 | L9: 0 | M9: 8554688.4 | N9: 3180884.2 | O9: 3297747.8 | P9: 44846503 | Q9: 1030295.4 | R9: 29785647 | S9: 1442464.2 | T9: 12226433 | U9: 7604471.2 | V9: 44907346 | W9: 1503923.8 | Y9: 7.334938 | Z9: 2.9278881 | AA9: 2.973089 | AB9: 14.957823 | AC9: 1.4390909 | AD9: 15.303657 | AE9: 1.5547275 | AF9: 11.869911 | AG9: 7.1327083 | AH9: 14.246105 | AI9: 4.0018811 | AK9: 7.334938 | AL9: 1.0585077 | AM9: 1.1108996 | AN9: 14.957823 | AO9: 0.56030369 | AP9: 15.303657 | AQ9: 0.66494147 | AR9: 5.9862453 | AS9: 0.91807111 | AT9: 14.246105 | AU9: 2.5071536 | AW9: 0.26896659 | AY9: 0.53104772
A10: 16 | B10: 140XNNN | C10: XYZW_CDE_1 | D10: {W, X, Y, Z} | F10: 0 | G10: 1 | H10: 0 | I10: =1 - J10 -> 0 | J10: =IF(AY10 > 0, 1, 0) -> 1 | K10: 4 | L10: 0 | M10: 56319775 | N10: 20004909 | O10: 20761634 | P10: 8126486.2 | Q10: 5833708.4 | R10: 1.7335886e+08 | S10: 11908000 | T10: 12243896 | U10: 7564706.6 | V10: 7475389.2 | W10: 5400598.2 | Y10: 43.278951 | Z10: 14.166911 | AA10: 14.447504 | AB10: 16.433304 | AC10: 5.610944 | AD10: 103.74747 | AE10: 10.405091 | AF10: 11.775143 | AG10: 7.1078341 | AH10: 6.0812038 | AI10: 13.093567 | AK10: 43.278951 | AL10: 6.6603668 | AM10: 6.974035 | AN10: 16.433304 | AO10: 2.6582309 | AP10: 103.74747 | AQ10: 4.494225 | AR10: 5.9332025 | AS10: 1.0732562 | AT10: 6.0812038 | AU10: 11.150235 | AW10: 0.26872637 | AY10: 2.0207082
A11: 16 | B11: 140NXXX | C11: XYZW_CDE_1 | D11: {W, X, Y, Z} | F11: 0 | G11: 1 | H11: 0 | I11: =1 - J11 -> 0 | J11: =IF(AY11 > 0, 1, 0) -> 1 | K11: 4 | L11: 0 | M11: 55796751 | N11: 20172344 | O11: 20835276 | P11: 8533125.2 | Q11: 5768474.8 | R11: 1.8483866e+08 | S11: 12369421 | T11: 12277478 | U11: 7567634.8 | V11: 8112431.4 | W11: 5362125 | Y11: 39.438538 | Z11: 13.062266 | AA11: 13.304214 | AB11: 18.800706 | AC11: 5.5252327 | AD11: 106.93264 | AE11: 9.9042607 | AF11: 10.999578 | AG11: 6.6307382 | AH11: 6.1462695 | AI11: 12.601976 | AK11: 39.438538 | AL11: 6.2135369 | AM11: 6.4903294 | AN11: 18.800706 | AO11: 2.6558211 | AP11: 106.93264 | AQ11: 4.2301014 | AR11: 5.5441715 | AS11: 0.98879937 | AT11: 6.1462695 | AU11: 10.74736 | AW11: 0.26228744 | AY11: 2.0207082
A12: 16 | B12: 140NXXN | C12: XYZW_CDE_1 | D12: {W, X, Y, Z} | F12: 0 | G12: 0 | H12: 0 | I12: =1 - J12 -> 0 | J12: =IF(AY12 > 0, 1, 0) -> 1 | K12: 4 | L12: 0 | M12: 8492168.2 | N12: 3208136.6 | O12: 3322308.6 | P12: 42293061 | Q12: 1012464.8 | R12: 33533661 | S12: 1551788 | T12: 12208411 | U12: 7648585.6 | V12: 42352359 | W12: 1625399 | Y12: 6.7989793 | Z12: 2.8340678 | AA12: 2.8622481 | AB12: 14.42941 | AC12: 1.4878159 | AD12: 17.425529 | AE12: 1.6337341 | AF12: 11.21789 | AG12: 6.8128898 | AH12: 13.233151 | AI12: 4.3586461 | AK12: 6.7989793 | AL12: 1.0631905 | AM12: 1.1049379 | AN12: 14.42941 | AO12: 0.58499143 | AP12: 17.425529 | AQ12: 0.73232248 | AR12: 5.66137 | AS12: 0.89767542 | AT12: 13.233151 | AU12: 2.7980251 | AW12: 0.2764356 | AY12: 0.53104772
A13: 16 | B13: 140NXNX | C13: XYZW_CDE_1 | D13: {W, X, Y, Z} | F13: 0 | G13: 0 | H13: 0 | I13: =1 - J13 -> 1 | J13: =IF(AY13 > 0, 1, 0) -> 0 | K13: 4 | L13: 0 | M13: 8699537.4 | N13: 13799988 | O13: 14545280 | P13: 40600807 | Q13: 3345237.2 | R13: 29943482 | S13: 10479119 | T13: 4874009.8 | U13: 7304764.6 | V13: 40872901 | W13: 3407266.4 | Y13: 9.090468 | Z13: 10.520727 | AA13: 11.105571 | AB13: 48.055193 | AC13: 5.1749952 | AD13: 31.689363 | AE13: 9.2384854 | AF13: 3.2759401 | AG13: 6.7167581 | AH13: 23.407847 | AI13: 12.676815 | AK13: 9.090468 | AL13: 3.1740196 | AM13: 3.7539653 | AN13: 48.055193 | AO13: 2.1862434 | AP13: 31.689363 | AQ13: 2.9083814 | AR13: 1.6501281 | AS13: 0.93803589 | AT13: 23.407847 | AU13: 10.707462 | AW13: 0.27872168 | AY13: -1.1806375
A14: 16 | B14: 140NXNN | C14: XYZW_CDE_1 | D14: {W, X, Y, Z} | F14: 0 | G14: 1 | H14: 0 | I14: =1 - J14 -> 0 | J14: =IF(AY14 > 0, 1, 0) -> 1 | K14: 4 | L14: 0 | M14: 4988107.6 | N14: 3011112.4 | O14: 3104492.8 | P14: 925137.4 | Q14: 668207.2 | R14: 14797049 | S14: 1369358 | T14: 6991416 | U14: 7599381 | V14: 910615 | W14: 1192125.8 | Y14: 5.1359704 | Z14: 2.7704902 | AA14: 2.8155791 | AB14: 2.7547982 | AC14: 1.4394112 | AD14: 11.71711 | AE14: 1.4492678 | AF14: 5.3904662 | AG14: 6.8598695 | AH14: 3.5726434 | AI14: 4.1111547 | AK14: 5.1359704 | AL14: 0.99247234 | AM14: 1.0483397 | AN14: 2.7547982 | AO14: 0.54375379 | AP14: 11.71711 | AQ14: 0.65695117 | AR14: 2.7117043 | AS14: 0.89045122 | AT14: 3.5726434 | AU14: 2.5069552 | AW14: 0.26019078 | AY14: 3.4072685
... A378: 3 | B378: 121NN | C378: XYZ_C_1_j | D378: {X, Z} | F378: 0 | G378: 0 | H378: 0 | I378: =1 - J378 -> 1 | J378: =IF(AY378 > 0, 1, 0) -> 0 | K378: 2 | L378: 0 | M378: 200049.4 | N378: 635380.4 | O378: 635578 | P378: 199999.4 | Q378: 1069775.2 | R378: 2.4 | S378: 444872.6 | T378: 2917511.4 | U378: 2275149.6 | V378: 287 | W378: 1387370.8 | Y378: 0.25231981 | Z378: 0.90740661 | AA378: 0.88149665 | AB378: 0.27086409 | AC378: 1.0780698 | AD378: 0.088723228 | AE378: 0.66027926 | AF378: 0.59646091 | AG378: 0.85140506 | AH378: 0.0045602284 | AI378: 2.0400037 | AK378: 0.25231981 | AL378: 0.40526868 | AM378: 0.38103558 | AN378: 0.27086409 | AO378: 0.43406295 | AP378: 0.088723228 | AQ378: 0.3414601 | AR378: 0.30141886 | AS378: 0.31910398 | AT378: 0.0045602284 | AU378: 0.85282497 | AW378: 0.29804127 | AY378: -1.3163817
M382: Average Benchmark (results) | Y382: Average Benchmark (sequential timing) | AK382: Average Benchmark (parallel timing)
F383: TargetN | G383: #N | H383: Target (or sym) | I383: Gain <=0 | J383: Gain > 0 | K383: Pref | L383: Pref&Target | M383: BNL | N383: BNL Causal | O383: BNL Causal HM | P383: SFS | Q383: SFS Causal | R383: SaLSa | S383: SaLSa Causal | T383: D&C | U383: D&C Causal | V383: BBS | W383: BBS Causal | Y383: BNL | Z383: BNL Causal | AA383: BNL Causal HM | AB383: SFS | AC383: SFS Causal | AD383: SaLSa | AE383: SaLSa Causal | AF383: D&C | AG383: D&C Causal | AH383: BBS | AI383: BBS Causal | AK383: BNL | AL383: BNL Causal | AM383: BNL Causal HM | AN383: SFS | AO383: SFS Causal | AP383: SaLSa | AQ383: SaLSa Causal | AR383: D&C | AS383: D&C Causal | AT383: BBS | AU383: BBS Causal
A384: 16 | B384: 140XXXX | C384: XYZW_CDE_1 | D384: {W, X, Y, Z} | F384: 0 | G384: 0 | H384: 1 | I384: =I3 -> 0 | J384: =J3 -> 1 | K384: 4 | L384: 4 | M384: =IF($AY3 > 0, M3, M3) -> 8651928.8 | N384: =IF($AY3 > 0, N3, M3) -> 1939638.8 | O384: =IF($AY3 > 0, O3, M3) -> 1979103.2 | P384: =IF($AY3 > 0, P3, P3) -> 42301553 | Q384: =IF($AY3 > 0, Q3, P3) -> 676220.4 | R384: =IF($AY3 > 0, R3, R3) -> 30213745 | S384: =IF($AY3 > 0, S3, R3) -> 620102 | T384: =IF($AY3 > 0, T3, T3) -> 12092496 | U384: =IF($AY3 > 0, U3, T3) -> 6999253.4 | V384: =IF($AY3 > 0, V3, V3) -> 42235243 | W384: =IF($AY3 > 0, W3, V3) -> 911304.2 | Y384: =IF($AY3 > 0, Y3, Y3) -> 7.0029691 | Z384: =IF($AY3 > 0, Z3, Y3) -> 1.8646784 | AA384: =IF($AY3 > 0, AA3, Y3) -> 1.8852114 | AB384: =IF($AY3 > 0, AB3, AB3) -> 26.626281 | AC384: =IF($AY3 > 0, AC3, AB3) -> 1.1990045 | AD384: =IF($AY3 > 0, AD3, AD3) -> 19.140483 | AE384: =IF($AY3 > 0, AE3, AD3) -> 0.8820702 | AF384: =IF($AY3 > 0, AF3, AF3) -> 11.034486 | AG384: =IF($AY3 > 0, AG3, AF3) -> 6.2040017 | AH384: =IF($AY3 > 0, AH3, AH3) -> 17.233339 | AI384: =IF($AY3 > 0, AI3, AH3) -> 2.9734621 | AK384: =IF($AY3 > 0, AK3, AK3) -> 7.0029691 | AL384: =IF($AY3 > 0, AL3, AK3) -> 0.75306083 | AM384: =IF($AY3 > 0, AM3, AK3) -> 0.76777357 | AN384: =IF($AY3 > 0, AN3, AN3) -> 26.626281 | AO384: =IF($AY3 > 0, AO3, AN3) -> 0.53748923 | AP384: =IF($AY3 > 0, AP3, AP3) -> 19.140483 | AQ384: =IF($AY3 > 0, AQ3, AP3) -> 0.50697361 | AR384: =IF($AY3 > 0, AR3, AR3) -> 5.5581718 | AS384: =IF($AY3 > 0, AS3, AR3) -> 0.80067531 | AT384: =IF($AY3 > 0, AT3, AT3) -> 17.233339 | AU384: =IF($AY3 > 0, AU3, AT3) -> 1.6044766
A385: 16 | B385: 140XXXN | C385: XYZW_CDE_1 | D385: {W, X, Y, Z} | F385: 0 | G385: 1 | H385: 0 | I385: =I4 -> 0 | J385: =J4 -> 1 | K385: 4 | L385: 0 | M385: =IF($AY4 > 0, M4, M4) -> 55059286 | N385: =IF($AY4 > 0, N4, M4) -> 19870315 | O385: =IF($AY4 > 0, O4, M4) -> 20564047 | P385: =IF($AY4 > 0, P4, P4) -> 7914061.6 | Q385: =IF($AY4 > 0, Q4, P4) -> 5789603.4 | R385: =IF($AY4 > 0, R4, R4) -> 1.7730778e+08 | S385: =IF($AY4 > 0, S4, R4) -> 12289819 | T385: =IF($AY4 > 0, T4, T4) -> 12368258 | U385: =IF($AY4 > 0, U4, T4) -> 8071990.6 | V385: =IF($AY4 > 0, V4, V4) -> 7611280.2 | W385: =IF($AY4 > 0, W4, V4) -> 5309479.8 | Y385: =IF($AY4 > 0, Y4, Y4) -> 40.289084 | Z385: =IF($AY4 > 0, Z4, Y4) -> 13.531542 | AA385: =IF($AY4 > 0, AA4, Y4) -> 13.768658 | AB385: =IF($AY4 > 0, AB4, AB4) -> 16.49666 | AC385: =IF($AY4 > 0, AC4, AB4) -> 5.5121838 | AD385: =IF($AY4 > 0, AD4, AD4) -> 109.80864 | AE385: =IF($AY4 > 0, AE4, AD4) -> 10.374894 | AF385: =IF($AY4 > 0, AF4, AF4) -> 12.101945 | AG385: =IF($AY4 > 0, AG4, AF4) -> 7.6646285 | AH385: =IF($AY4 > 0, AH4, AH4) -> 6.4325647 | AI385: =IF($AY4 > 0, AI4, AH4) -> 12.885179 | AK385: =IF($AY4 > 0, AK4, AK4) -> 40.289084 | AL385: =IF($AY4 > 0, AL4, AK4) -> 6.4762061 | AM385: =IF($AY4 > 0, AM4, AK4) -> 6.747376 | AN385: =IF($AY4 > 0, AN4, AN4) -> 16.49666 | AO385: =IF($AY4 > 0, AO4, AN4) -> 2.6998221 | AP385: =IF($AY4 > 0, AP4, AP4) -> 109.80864 | AQ385: =IF($AY4 > 0, AQ4, AP4) -> 4.5908101 | AR385: =IF($AY4 > 0, AR4, AR4) -> 6.1050322 | AS385: =IF($AY4 > 0, AS4, AR4) -> 1.1244617 | AT385: =IF($AY4 > 0, AT4, AT4) -> 6.4325647 | AU385: =IF($AY4 > 0, AU4, AT4) -> 10.941839
