Workbook

Sheet Summary
A1: Mean | B1: Dominance Checks | H1: Mean | I1: Execution Time
B2: BNL | C2: SFS | D2: SaLSa | E2: D&C | F2: BBS | I2: BNL | J2: SFS | K2: SaLSa | L2: D&C | M2: BBS
A3: Non-Causal | B3: ='Pure Decorrelation'!$M$765 -> 2408467.9 | C3: ='Pure Decorrelation'!$P$765 -> 3929169.3 | D3: ='Pure Decorrelation'!$R$765 -> 4556204.5 | E3: ='Pure Decorrelation'!$T$765 -> 4656147.5 | F3: ='Pure Decorrelation'!$V$765 -> 7453565.3 | H3: Non-Causal | I3: ='Pure Decorrelation'!$Y$765 -> 2.1598267 | J3: ='Pure Decorrelation'!$AB$765 -> 2.9966933 | K3: ='Pure Decorrelation'!$AD$765 -> 3.7183701 | L3: ='Pure Decorrelation'!$AF$765 -> 2.2138696 | M3: ='Pure Decorrelation'!$AH$765 -> 4.2239395
A4: lnSky. (0.6, 0.4) | B4: ='Provided DAG'!$N$765 -> 1628461.7 | C4: ='Provided DAG'!$Q$765 -> 1170930.5 | D4: ='Provided DAG'!$S$765 -> 1368880.1 | E4: ='Provided DAG'!$U$765 -> 3588291.7 | F4: ='Provided DAG'!$W$765 -> 1923083.6 | H4: lnSky. (0.6, 0.4) | I4: ='Provided DAG'!$Z$765 -> 1.6059582 | J4: ='Provided DAG'!$AC$765 -> 1.2655061 | K4: ='Provided DAG'!$AE$765 -> 1.6692292 | L4: ='Provided DAG'!$AG$765 -> 2.074686 | M4: ='Provided DAG'!$AI$765 -> 2.5518904
A5: lnSky. w/ inf. DAG | B5: ='Inferred DAG'!$G$383 -> 1277765.3 | C5: ='Inferred DAG'!$J$383 -> 1135011.6 | D5: ='Inferred DAG'!$N$383 -> 1037503.2 | E5: ='Inferred DAG'!$P$383 -> 3603658.6 | F5: ='Inferred DAG'!$R$383 -> 2026629.4 | H5: lnSky. w/ inf. DAG | I5: ='Inferred DAG'!$U$383 -> 1.3750872 | J5: ='Inferred DAG'!$X$383 -> 1.4811653 | K5: ='Inferred DAG'!$AB$383 -> 1.5150469 | L5: ='Inferred DAG'!$AD$383 -> 1.9301612 | M5: ='Inferred DAG'!$AF$383 -> 2.3498893

Sheet Pure Decorrelation
M1: Average Benchmark (results) | Y1: Average Benchmark (sequential timing) | AK1: Average Benchmark (parallel timing) | AW1: Average Benchmark (cluster_time)
F2: TargetN | G2: #N | H2: Target (or sym) | I2: Gain <=0 | J2: Gain > 0 | K2: Pref | L2: Pref&Target | M2: BNL | N2: BNL Causal | O2: BNL Causal HM | P2: SFS | Q2: SFS Causal | R2: SaLSa | S2: SaLSa Causal | T2: D&C | U2: D&C Causal | V2: BBS | W2: BBS Causal | Y2: BNL | Z2: BNL Causal | AA2: BNL Causal HM | AB2: SFS | AC2: SFS Causal | AD2: SaLSa | AE2: SaLSa Causal | AF2: D&C | AG2: D&C Causal | AH2: BBS | AI2: BBS Causal | AK2: BNL | AL2: BNL Causal | AM2: BNL Causal HM | AN2: SFS | AO2: SFS Causal | AP2: SaLSa | AQ2: SaLSa Causal | AR2: D&C | AS2: D&C Causal | AT2: BBS | AU2: BBS Causal | AW2: KMeans Time (seconds) | AY2: Gain
A3: 21 | B3: 156XXXX | C3: Hong_Kong_Weather_3 | D3: {cloud, mean_wet_bulb_temp, rainfall, rel_humidity} | F3: 0 | G3: 0 | H3: 1 | I3: =1 - J3 -> 0 | J3: =IF(AY3 > 0, 1, 0) -> 1 | K3: 4 | L3: 4 | M3: 984737.8 | N3: 10022863 | O3: 10082711 | P3: 1004122.8 | Q3: 5817876.8 | R3: 881239.4 | S3: 10274494 | T3: 4185627.2 | U3: 4336446.8 | V3: 1396199.2 | W3: 8664971.6 | Y3: 1.3718655 | Z3: 7.3616699 | AA3: 7.3149721 | AB3: 1.6075157 | AC3: 5.2482228 | AD3: 1.0902543 | AE3: 8.100779 | AF3: 1.5241145 | AG3: 2.7269407 | AH3: 2.9582296 | AI3: 14.576076 | AK3: 1.3718655 | AL3: 2.5448769 | AM3: 2.5492649 | AN3: 1.6075157 | AO3: 1.8831961 | AP3: 1.0902543 | AQ3: 2.9239906 | AR3: 0.9750971 | AS3: 0.64183103 | AT3: 2.9582296 | AU3: 11.772234 | AW3: 0.31142347 | AY3: 1
A4: 21 | B4: 156XXXN | C4: Hong_Kong_Weather_3 | D4: {cloud, mean_wet_bulb_temp, rainfall, rel_humidity} | F4: 0 | G4: 1 | H4: 0 | I4: =1 - J4 -> 0 | J4: =IF(AY4 > 0, 1, 0) -> 1 | K4: 4 | L4: 0 | M4: 9774060 | N4: 4768147.6 | O4: 4743320.2 | P4: 14747945 | Q4: 1555096.6 | R4: 16571915 | S4: 3159799.4 | T4: 4907318.2 | U4: 3939126.4 | V4: 21091677 | W4: 2550318.6 | Y4: 8.385313 | Z4: 3.8032576 | AA4: 3.7796306 | AB4: 7.9825207 | AC4: 2.2019668 | AD4: 11.337875 | AE4: 3.3661471 | AF4: 2.1943271 | AG4: 2.3247525 | AH4: 7.9510913 | AI4: 5.5401984 | AK4: 8.385313 | AL4: 1.646166 | AM4: 1.6287097 | AN4: 7.9825207 | AO4: 0.97883885 | AP4: 11.337875 | AQ4: 1.2861934 | AR4: 1.2434555 | AS4: 0.63097686 | AT4: 7.9510913 | AU4: 3.9433181 | AW4: 0.31174662 | AY4: 1
A5: 21 | B5: 156XXNX | C5: Hong_Kong_Weather_3 | D5: {cloud, mean_wet_bulb_temp, rainfall, rel_humidity} | F5: 0 | G5: 1 | H5: 0 | I5: =1 - J5 -> 0 | J5: =IF(AY5 > 0, 1, 0) -> 1 | K5: 4 | L5: 0 | M5: 4329316.4 | N5: 5708330.4 | O5: 5876682.4 | P5: 1278792.2 | Q5: 2762314.2 | R5: 616378.2 | S5: 2267205 | T5: 4215981.4 | U5: 3916185.8 | V5: 2636300 | W5: 3949562.8 | Y5: 3.828656 | Z5: 4.4432907 | AA5: 4.5239025 | AB5: 2.3397783 | AC5: 2.714684 | AD5: 1.726517 | AE5: 2.9614979 | AF5: 1.5807121 | AG5: 2.216917 | AH5: 3.6683148 | AI5: 7.513542 | AK5: 3.828656 | AL5: 1.5569136 | AM5: 1.638306 | AN5: 2.3397783 | AO5: 1.2357769 | AP5: 1.726517 | AQ5: 1.1493316 | AR5: 1.0567209 | AS5: 0.56853997 | AT5: 3.6683148 | AU5: 5.5275729 | AW5: 0.32285666 | AY5: 1
A6: 21 | B6: 156XXNN | C6: Hong_Kong_Weather_3 | D6: {cloud, mean_wet_bulb_temp, rainfall, rel_humidity} | F6: 0 | G6: 0 | H6: 0 | I6: =1 - J6 -> 0 | J6: =IF(AY6 > 0, 1, 0) -> 1 | K6: 4 | L6: 0 | M6: 4797310.6 | N6: 2327862 | O6: 2333566.4 | P6: 1475770.8 | Q6: 639802.8 | R6: 1030299.8 | S6: 781966.2 | T6: 4594408.8 | U6: 3608168.8 | V6: 8246724.6 | W6: 1026269.8 | Y6: 4.3051407 | Z6: 2.2448575 | AA6: 2.2267145 | AB6: 2.5700545 | AC6: 1.3296278 | AD6: 2.8279426 | AE6: 1.9226274 | AF6: 1.8526587 | AG6: 1.9668249 | AH6: 5.3781422 | AI6: 3.0659769 | AK6: 4.3051407 | AL6: 0.87471073 | AM6: 0.87191543 | AN6: 2.5700545 | AO6: 0.63183793 | AP6: 2.8279426 | AQ6: 0.74748458 | AR6: 1.0730149 | AS6: 0.53986058 | AT6: 5.3781422 | AU6: 1.910186 | AW6: 0.31912437 | AY6: 1
A7: 21 | B7: 156XNXX | C7: Hong_Kong_Weather_3 | D7: {cloud, mean_wet_bulb_temp, rainfall, rel_humidity} | F7: 0 | G7: 1 | H7: 0 | I7: =1 - J7 -> 0 | J7: =IF(AY7 > 0, 1, 0) -> 1 | K7: 4 | L7: 0 | M7: 1254500 | N7: 8211267.8 | O7: 8385658.4 | P7: 3405256 | Q7: 5392684.4 | R7: 1465331.4 | S7: 11978384 | T7: 4677209.6 | U7: 4016900.4 | V7: 7657925.2 | W7: 7117200.4 | Y7: 1.7459986 | Z7: 6.7369938 | AA7: 6.8520819 | AB7: 3.199273 | AC7: 4.832371 | AD7: 2.892981 | AE7: 10.556205 | AF7: 2.0297543 | AG7: 2.5032138 | AH7: 5.2049517 | AI7: 9.8846658 | AK7: 1.7459986 | AL7: 4.2834749 | AM7: 4.4000099 | AN7: 3.199273 | AO7: 3.0720111 | AP7: 2.892981 | AQ7: 7.730213 | AR7: 1.1097154 | AS7: 0.7778796 | AT7: 5.2049517 | AU7: 8.2927167 | AW7: 0.31720362 | AY7: 1
A8: 21 | B8: 156XNXN | C8: Hong_Kong_Weather_3 | D8: {cloud, mean_wet_bulb_temp, rainfall, rel_humidity} | F8: 0 | G8: 0 | H8: 0 | I8: =1 - J8 -> 0 | J8: =IF(AY8 > 0, 1, 0) -> 1 | K8: 4 | L8: 0 | M8: 4819087.6 | N8: 4932159 | O8: 5277290.8 | P8: 5594837.2 | Q8: 1744670 | R8: 4114032.2 | S8: 4301307.4 | T8: 4018927.8 | U8: 4004214.4 | V8: 24198068 | W8: 2695408.4 | Y8: 5.2910015 | Z8: 4.2471254 | AA8: 4.4392391 | AB8: 6.9649184 | AC8: 2.5508812 | AD8: 6.292094 | AE8: 4.1369936 | AF8: 1.5069674 | AG8: 2.5294473 | AH8: 8.4431713 | AI8: 6.5814194 | AK8: 5.2910015 | AL8: 1.6044603 | AM8: 1.8026691 | AN8: 6.9649184 | AO8: 1.0486424 | AP8: 6.292094 | AQ8: 1.6140749 | AR8: 1.0047482 | AS8: 0.62829525 | AT8: 8.4431713 | AU8: 4.9306731 | AW8: 0.32276495 | AY8: 1
A9: 21 | B9: 156XNNX | C9: Hong_Kong_Weather_3 | D9: {cloud, mean_wet_bulb_temp, rainfall, rel_humidity} | F9: 0 | G9: 0 | H9: 0 | I9: =1 - J9 -> 0 | J9: =IF(AY9 > 0, 1, 0) -> 1 | K9: 4 | L9: 0 | M9: 2186441.2 | N9: 4570545.2 | O9: 4339608.6 | P9: 1589889 | Q9: 2689294.8 | R9: 616867 | S9: 2147966.8 | T9: 4560935.4 | U9: 3691327.6 | V9: 575641.8 | W9: 2539553.2 | Y9: 2.1583616 | Z9: 3.9812017 | AA9: 3.836798 | AB9: 2.0238636 | AC9: 2.9633648 | AD9: 1.6820759 | AE9: 3.1078367 | AF9: 1.8537012 | AG9: 2.0354693 | AH9: 2.9026718 | AI9: 5.0440308 | AK9: 2.1583616 | AL9: 1.9623007 | AM9: 1.8304167 | AN9: 2.0238636 | AO9: 1.4115784 | AP9: 1.6820759 | AQ9: 1.4057721 | AR9: 1.087151 | AS9: 0.60014935 | AT9: 2.9026718 | AU9: 3.6228537 | AW9: 0.31864881 | AY9: 1
A10: 21 | B10: 156XNNN | C10: Hong_Kong_Weather_3 | D10: {cloud, mean_wet_bulb_temp, rainfall, rel_humidity} | F10: 0 | G10: 1 | H10: 0 | I10: =1 - J10 -> 0 | J10: =IF(AY10 > 0, 1, 0) -> 1 | K10: 4 | L10: 0 | M10: 1359597.6 | N10: 3167304.6 | O10: 3404874 | P10: 602084 | Q10: 1300983.6 | R10: 362702.6 | S10: 1474098.6 | T10: 3787607.6 | U10: 3761598.4 | V10: 230918.4 | W10: 2099069.6 | Y10: 1.6504133 | Z10: 2.9586209 | AA10: 3.1068234 | AB10: 1.309188 | AC10: 2.0336399 | AD10: 1.7599426 | AE10: 2.5879828 | AF10: 1.216636 | AG10: 2.187835 | AH10: 1.5905149 | AI10: 4.9674127 | AK10: 1.6504133 | AL10: 1.0622237 | AM10: 1.2209281 | AN10: 1.309188 | AO10: 0.77097515 | AP10: 1.7599426 | AQ10: 0.84869093 | AR10: 0.78808016 | AS10: 0.56963752 | AT10: 1.5905149 | AU10: 3.3881653 | AW10: 0.32476171 | AY10: 1
A11: 21 | B11: 156NXXX | C11: Hong_Kong_Weather_3 | D11: {cloud, mean_wet_bulb_temp, rainfall, rel_humidity} | F11: 0 | G11: 1 | H11: 0 | I11: =1 - J11 -> 0 | J11: =IF(AY11 > 0, 1, 0) -> 1 | K11: 4 | L11: 0 | M11: 6171416.2 | N11: 6805158.4 | O11: 6857539.4 | P11: 8419143.6 | Q11: 2905263.6 | R11: 9256532.2 | S11: 6328932 | T11: 4215910.2 | U11: 4184912 | V11: 19259380 | W11: 3812327.2 | Y11: 6.5145961 | Z11: 5.4953548 | AA11: 5.4963909 | AB11: 10.051685 | AC11: 3.3562829 | AD11: 9.2313233 | AE11: 5.8270503 | AF11: 1.662673 | AG11: 2.7369827 | AH11: 10.641126 | AI11: 8.6416807 | AK11: 6.5145961 | AL11: 2.2705729 | AM11: 2.29022 | AN11: 10.051685 | AO11: 1.5883353 | AP11: 9.2313233 | AQ11: 2.323506 | AR11: 1.0560422 | AS11: 0.65100236 | AT11: 10.641126 | AU11: 6.74493 | AW11: 0.32241962 | AY11: 1
A12: 21 | B12: 156NXXN | C12: Hong_Kong_Weather_3 | D12: {cloud, mean_wet_bulb_temp, rainfall, rel_humidity} | F12: 0 | G12: 0 | H12: 0 | I12: =1 - J12 -> 0 | J12: =IF(AY12 > 0, 1, 0) -> 1 | K12: 4 | L12: 0 | M12: 6077126.4 | N12: 6523186.2 | O12: 6683859.2 | P12: 14297376 | Q12: 2766018.8 | R12: 9345182.6 | S12: 7992747.4 | T12: 4852422.4 | U12: 3966619.4 | V12: 31495539 | W12: 3691529.6 | Y12: 6.1149932 | Z12: 5.2643429 | AA12: 5.3412261 | AB12: 12.623191 | AC12: 3.3510144 | AD12: 10.215354 | AE12: 6.7976655 | AF12: 2.2462109 | AG12: 2.4651819 | AH12: 11.225533 | AI12: 8.0396503 | AK12: 6.1149932 | AL12: 2.6219385 | AM12: 2.6974127 | AN12: 12.623191 | AO12: 1.780658 | AP12: 10.215354 | AQ12: 3.9254723 | AR12: 1.259069 | AS12: 0.6301522 | AT12: 11.225533 | AU12: 6.3221946 | AW12: 0.31969761 | AY12: 1
A13: 21 | B13: 156NXNX | C13: Hong_Kong_Weather_3 | D13: {cloud, mean_wet_bulb_temp, rainfall, rel_humidity} | F13: 0 | G13: 0 | H13: 0 | I13: =1 - J13 -> 0 | J13: =IF(AY13 > 0, 1, 0) -> 1 | K13: 4 | L13: 0 | M13: 4373945.6 | N13: 3525196.8 | O13: 3542716.8 | P13: 4791875 | Q13: 1227249 | R13: 3330299.8 | S13: 1129757.4 | T13: 4221177.6 | U13: 3820898.8 | V13: 5883243.8 | W13: 2247583.4 | Y13: 4.0645885 | Z13: 3.0854349 | AA13: 3.0809418 | AB13: 3.1259433 | AC13: 1.7536643 | AD13: 3.0631603 | AE13: 2.3240296 | AF13: 1.6403528 | AG13: 2.2280405 | AH13: 4.4035068 | AI13: 4.2895956 | AK13: 4.0645885 | AL13: 1.190528 | AM13: 1.1977567 | AN13: 3.1259433 | AO13: 0.77954667 | AP13: 3.0631603 | AQ13: 0.83620563 | AR13: 1.0916918 | AS13: 0.5944944 | AT13: 4.4035068 | AU13: 2.6821506 | AW13: 0.32064945 | AY13: 1
A14: 21 | B14: 156NXNN | C14: Hong_Kong_Weather_3 | D14: {cloud, mean_wet_bulb_temp, rainfall, rel_humidity} | F14: 0 | G14: 1 | H14: 0 | I14: =1 - J14 -> 0 | J14: =IF(AY14 > 0, 1, 0) -> 1 | K14: 4 | L14: 0 | M14: 1743369.2 | N14: 5681416.4 | O14: 5716200.8 | P14: 3424600.8 | Q14: 3042341.4 | R14: 2642237 | S14: 2579986.8 | T14: 4575869 | U14: 3750440.2 | V14: 7388502.4 | W14: 4680236.4 | Y14: 1.9127118 | Z14: 4.7608887 | AA14: 4.7306703 | AB14: 3.1142022 | AC14: 3.0985967 | AD14: 3.3492492 | AE14: 3.4092037 | AF14: 1.8588019 | AG14: 2.130245 | AH14: 4.9357865 | AI14: 7.190099 | AK14: 1.9127118 | AL14: 2.2804257 | AM14: 2.2775786 | AN14: 3.1142022 | AO14: 1.5012025 | AP14: 3.3492492 | AQ14: 1.4923652 | AR14: 1.0765884 | AS14: 0.60571621 | AT14: 4.9357865 | AU14: 5.4135304 | AW14: 0.32582642 | AY14: 1
... A162: 12 | B162: 90NNN | C162: DryBean_2 | D162: {Area, Compactness, Eccentricity} | F162: 0 | G162: 1 | H162: 0 | I162: =1 - J162 -> 0 | J162: =IF(AY162 > 0, 1, 0) -> 1 | K162: 3 | L162: 0 | M162: 8551058.6 | N162: 2240817 | O162: 2249375 | P162: 18313333 | Q162: 858432.4 | R162: 9876058.6 | S162: 1364324.4 | T162: 9453028.2 | U162: 4905973.2 | V162: 10764022 | W162: 2131120.8 | Y162: 6.3840426 | Z162: 1.9849401 | AA162: 1.9789719 | AB162: 12.076818 | AC162: 1.2422673 | AD162: 7.3952776 | AE162: 1.6713525 | AF162: 5.6956633 | AG162: 3.1246839 | AH162: 5.2542972 | AI162: 2.9626138 | AK162: 6.3840426 | AL162: 0.75734993 | AM162: 0.75412688 | AN162: 12.076818 | AO162: 0.56581209 | AP162: 7.3952776 | AQ162: 0.70782051 | AR162: 3.9018358 | AS162: 0.61182996 | AT162: 5.2542972 | AU162: 1.5747192 | AW162: 0.31135368 | AY162: 1
M382: Average Benchmark (results) | Y382: Average Benchmark (sequential timing) | AK382: Average Benchmark (parallel timing)
F383: TargetN | G383: #N | H383: Target (or sym) | I383: Gain <=0 | J383: Gain > 0 | K383: Pref | L383: Pref&Target | M383: BNL | N383: BNL Causal | O383: BNL Causal HM | P383: SFS | Q383: SFS Causal | R383: SaLSa | S383: SaLSa Causal | T383: D&C | U383: D&C Causal | V383: BBS | W383: BBS Causal | Y383: BNL | Z383: BNL Causal | AA383: BNL Causal HM | AB383: SFS | AC383: SFS Causal | AD383: SaLSa | AE383: SaLSa Causal | AF383: D&C | AG383: D&C Causal | AH383: BBS | AI383: BBS Causal | AK383: BNL | AL383: BNL Causal | AM383: BNL Causal HM | AN383: SFS | AO383: SFS Causal | AP383: SaLSa | AQ383: SaLSa Causal | AR383: D&C | AS383: D&C Causal | AT383: BBS | AU383: BBS Causal
A384: 21 | B384: 156XXXX | C384: Hong_Kong_Weather_3 | D384: {cloud, mean_wet_bulb_temp, rainfall, rel_humidity} | F384: 0 | G384: 0 | H384: 1 | I384: =I3 -> 0 | J384: =J3 -> 1 | K384: 4 | L384: 4 | M384: =IF($AY3 > 0, M3, M3) -> 984737.8 | N384: =IF($AY3 > 0, N3, M3) -> 10022863 | O384: =IF($AY3 > 0, O3, M3) -> 10082711 | P384: =IF($AY3 > 0, P3, P3) -> 1004122.8 | Q384: =IF($AY3 > 0, Q3, P3) -> 5817876.8 | R384: =IF($AY3 > 0, R3, R3) -> 881239.4 | S384: =IF($AY3 > 0, S3, R3) -> 10274494 | T384: =IF($AY3 > 0, T3, T3) -> 4185627.2 | U384: =IF($AY3 > 0, U3, T3) -> 4336446.8 | V384: =IF($AY3 > 0, V3, V3) -> 1396199.2 | W384: =IF($AY3 > 0, W3, V3) -> 8664971.6 | Y384: =IF($AY3 > 0, Y3, Y3) -> 1.3718655 | Z384: =IF($AY3 > 0, Z3, Y3) -> 7.3616699 | AA384: =IF($AY3 > 0, AA3, Y3) -> 7.3149721 | AB384: =IF($AY3 > 0, AB3, AB3) -> 1.6075157 | AC384: =IF($AY3 > 0, AC3, AB3) -> 5.2482228 | AD384: =IF($AY3 > 0, AD3, AD3) -> 1.0902543 | AE384: =IF($AY3 > 0, AE3, AD3) -> 8.100779 | AF384: =IF($AY3 > 0, AF3, AF3) -> 1.5241145 | AG384: =IF($AY3 > 0, AG3, AF3) -> 2.7269407 | AH384: =IF($AY3 > 0, AH3, AH3) -> 2.9582296 | AI384: =IF($AY3 > 0, AI3, AH3) -> 14.576076 | AK384: =IF($AY3 > 0, AK3, AK3) -> 1.3718655 | AL384: =IF($AY3 > 0, AL3, AK3) -> 2.5448769 | AM384: =IF($AY3 > 0, AM3, AK3) -> 2.5492649 | AN384: =IF($AY3 > 0, AN3, AN3) -> 1.6075157 | AO384: =IF($AY3 > 0, AO3, AN3) -> 1.8831961 | AP384: =IF($AY3 > 0, AP3, AP3) -> 1.0902543 | AQ384: =IF($AY3 > 0, AQ3, AP3) -> 2.9239906 | AR384: =IF($AY3 > 0, AR3, AR3) -> 0.9750971 | AS384: =IF($AY3 > 0, AS3, AR3) -> 0.64183103 | AT384: =IF($AY3 > 0, AT3, AT3) -> 2.9582296 | AU384: =IF($AY3 > 0, AU3, AT3) -> 11.772234
A385: 21 | B385: 156XXXN | C385: Hong_Kong_Weather_3 | D385: {cloud, mean_wet_bulb_temp, rainfall, rel_humidity} | F385: 0 | G385: 1 | H385: 0 | I385: =I4 -> 0 | J385: =J4 -> 1 | K385: 4 | L385: 0 | M385: =IF($AY4 > 0, M4, M4) -> 9774060 | N385: =IF($AY4 > 0, N4, M4) -> 4768147.6 | O385: =IF($AY4 > 0, O4, M4) -> 4743320.2 | P385: =IF($AY4 > 0, P4, P4) -> 14747945 | Q385: =IF($AY4 > 0, Q4, P4) -> 1555096.6 | R385: =IF($AY4 > 0, R4, R4) -> 16571915 | S385: =IF($AY4 > 0, S4, R4) -> 3159799.4 | T385: =IF($AY4 > 0, T4, T4) -> 4907318.2 | U385: =IF($AY4 > 0, U4, T4) -> 3939126.4 | V385: =IF($AY4 > 0, V4, V4) -> 21091677 | W385: =IF($AY4 > 0, W4, V4) -> 2550318.6 | Y385: =IF($AY4 > 0, Y4, Y4) -> 8.385313 | Z385: =IF($AY4 > 0, Z4, Y4) -> 3.8032576 | AA385: =IF($AY4 > 0, AA4, Y4) -> 3.7796306 | AB385: =IF($AY4 > 0, AB4, AB4) -> 7.9825207 | AC385: =IF($AY4 > 0, AC4, AB4) -> 2.2019668 | AD385: =IF($AY4 > 0, AD4, AD4) -> 11.337875 | AE385: =IF($AY4 > 0, AE4, AD4) -> 3.3661471 | AF385: =IF($AY4 > 0, AF4, AF4) -> 2.1943271 | AG385: =IF($AY4 > 0, AG4, AF4) -> 2.3247525 | AH385: =IF($AY4 > 0, AH4, AH4) -> 7.9510913 | AI385: =IF($AY4 > 0, AI4, AH4) -> 5.5401984 | AK385: =IF($AY4 > 0, AK4, AK4) -> 8.385313 | AL385: =IF($AY4 > 0, AL4, AK4) -> 1.646166 | AM385: =IF($AY4 > 0, AM4, AK4) -> 1.6287097 | AN385: =IF($AY4 > 0, AN4, AN4) -> 7.9825207 | AO385: =IF($AY4 > 0, AO4, AN4) -> 0.97883885 | AP385: =IF($AY4 > 0, AP4, AP4) -> 11.337875 | AQ385: =IF($AY4 > 0, AQ4, AP4) -> 1.2861934 | AR385: =IF($AY4 > 0, AR4, AR4) -> 1.2434555 | AS385: =IF($AY4 > 0, AS4, AR4) -> 0.63097686 | AT385: =IF($AY4 > 0, AT4, AT4) -> 7.9510913 | AU385: =IF($AY4 > 0, AU4, AT4) -> 3.9433181
A386: 21 | B386: 156XXNX | C386: Hong_Kong_Weather_3 | D386: {cloud, mean_wet_bulb_temp, rainfall, rel_humidity} | F386: 0 | G386: 1 | H386: 0 | I386: =I5 -> 0 | J386: =J5 -> 1 | K386: 4 | L386: 0 | M386: =IF($AY5 > 0, M5, M5) -> 4329316.4 | N386: =IF($AY5 > 0, N5, M5) -> 5708330.4 | O386: =IF($AY5 > 0, O5, M5) -> 5876682.4 | P386: =IF($AY5 > 0, P5, P5) -> 1278792.2 | Q386: =IF($AY5 > 0, Q5, P5) -> 2762314.2 | R386: =IF($AY5 > 0, R5, R5) -> 616378.2 | S386: =IF($AY5 > 0, S5, R5) -> 2267205 | T386: =IF($AY5 > 0, T5, T5) -> 4215981.4 | U386: =IF($AY5 > 0, U5, T5) -> 3916185.8 | V386: =IF($AY5 > 0, V5, V5) -> 2636300 | W386: =IF($AY5 > 0, W5, V5) -> 3949562.8 | Y386: =IF($AY5 > 0, Y5, Y5) -> 3.828656 | Z386: =IF($AY5 > 0, Z5, Y5) -> 4.4432907 | AA386: =IF($AY5 > 0, AA5, Y5) -> 4.5239025 | AB386: =IF($AY5 > 0, AB5, AB5) -> 2.3397783 | AC386: =IF($AY5 > 0, AC5, AB5) -> 2.714684 | AD386: =IF($AY5 > 0, AD5, AD5) -> 1.726517 | AE386: =IF($AY5 > 0, AE5, AD5) -> 2.9614979 | AF386: =IF($AY5 > 0, AF5, AF5) -> 1.5807121 | AG386: =IF($AY5 > 0, AG5, AF5) -> 2.216917 | AH386: =IF($AY5 > 0, AH5, AH5) -> 3.6683148 | AI386: =IF($AY5 > 0, AI5, AH5) -> 7.513542 | AK386: =IF($AY5 > 0, AK5, AK5) -> 3.828656 | AL386: =IF($AY5 > 0, AL5, AK5) -> 1.5569136 | AM386: =IF($AY5 > 0, AM5, AK5) -> 1.638306 | AN386: =IF($AY5 > 0, AN5, AN5) -> 2.3397783 | AO386: =IF($AY5 > 0, AO5, AN5) -> 1.2357769 | AP386: =IF($AY5 > 0, AP5, AP5) -> 1.726517 | AQ386: =IF($AY5 > 0, AQ5, AP5) -> 1.1493316 | AR386: =IF($AY5 > 0, AR5, AR5) -> 1.0567209 | AS386: =IF($AY5 > 0, AS5, AR5) -> 0.56853997 | AT386: =IF($AY5 > 0, AT5, AT5) -> 3.6683148 | AU386: =IF($AY5 > 0, AU5, AT5) -> 5.5275729
A387: 21 | B387: 156XXNN | C387: Hong_Kong_Weather_3 | D387: {cloud, mean_wet_bulb_temp, rainfall, rel_humidity} | F387: 0 | G387: 0 | H387: 0 | I387: =I6 -> 0 | J387: =J6 -> 1 | K387: 4 | L387: 0 | M387: =IF($AY6 > 0, M6, M6) -> 4797310.6 | N387: =IF($AY6 > 0, N6, M6) -> 2327862 | O387: =IF($AY6 > 0, O6, M6) -> 2333566.4 | P387: =IF($AY6 > 0, P6, P6) -> 1475770.8 | Q387: =IF($AY6 > 0, Q6, P6) -> 639802.8 | R387: =IF($AY6 > 0, R6, R6) -> 1030299.8 | S387: =IF($AY6 > 0, S6, R6) -> 781966.2 | T387: =IF($AY6 > 0, T6, T6) -> 4594408.8 | U387: =IF($AY6 > 0, U6, T6) -> 3608168.8 | V387: =IF($AY6 > 0, V6, V6) -> 8246724.6 | W387: =IF($AY6 > 0, W6, V6) -> 1026269.8 | Y387: =IF($AY6 > 0, Y6, Y6) -> 4.3051407 | Z387: =IF($AY6 > 0, Z6, Y6) -> 2.2448575 | AA387: =IF($AY6 > 0, AA6, Y6) -> 2.2267145 | AB387: =IF($AY6 > 0, AB6, AB6) -> 2.5700545 | AC387: =IF($AY6 > 0, AC6, AB6) -> 1.3296278 | AD387: =IF($AY6 > 0, AD6, AD6) -> 2.8279426 | AE387: =IF($AY6 > 0, AE6, AD6) -> 1.9226274 | AF387: =IF($AY6 > 0, AF6, AF6) -> 1.8526587 | AG387: =IF($AY6 > 0, AG6, AF6) -> 1.9668249 | AH387: =IF($AY6 > 0, AH6, AH6) -> 5.3781422 | AI387: =IF($AY6 > 0, AI6, AH6) -> 3.0659769 | AK387: =IF($AY6 > 0, AK6, AK6) -> 4.3051407 | AL387: =IF($AY6 > 0, AL6, AK6) -> 0.87471073 | AM387: =IF($AY6 > 0, AM6, AK6) -> 0.87191543 | AN387: =IF($AY6 > 0, AN6, AN6) -> 2.5700545 | AO387: =IF($AY6 > 0, AO6, AN6) -> 0.63183793 | AP387: =IF($AY6 > 0, AP6, AP6) -> 2.8279426 | AQ387: =IF($AY6 > 0, AQ6, AP6) -> 0.74748458 | AR387: =IF($AY6 > 0, AR6, AR6) -> 1.0730149 | AS387: =IF($AY6 > 0, AS6, AR6) -> 0.53986058 | AT387: =IF($AY6 > 0, AT6, AT6) -> 5.3781422 | AU387: =IF($AY6 > 0, AU6, AT6) -> 1.910186
A388: 21 | B388: 156XNXX | C388: Hong_Kong_Weather_3 | D388: {cloud, mean_wet_bulb_temp, rainfall, rel_humidity} | F388: 0 | G388: 1 | H388: 0 | I388: =I7 -> 0 | J388: =J7 -> 1 | K388: 4 | L388: 0 | M388: =IF($AY7 > 0, M7, M7) -> 1254500 | N388: =IF($AY7 > 0, N7, M7) -> 8211267.8 | O388: =IF($AY7 > 0, O7, M7) -> 8385658.4 | P388: =IF($AY7 > 0, P7, P7) -> 3405256 | Q388: =IF($AY7 > 0, Q7, P7) -> 5392684.4 | R388: =IF($AY7 > 0, R7, R7) -> 1465331.4 | S388: =IF($AY7 > 0, S7, R7) -> 11978384 | T388: =IF($AY7 > 0, T7, T7) -> 4677209.6 | U388: =IF($AY7 > 0, U7, T7) -> 4016900.4 | V388: =IF($AY7 > 0, V7, V7) -> 7657925.2 | W388: =IF($AY7 > 0, W7, V7) -> 7117200.4 | Y388: =IF($AY7 > 0, Y7, Y7) -> 1.7459986 | Z388: =IF($AY7 > 0, Z7, Y7) -> 6.7369938 | AA388: =IF($AY7 > 0, AA7, Y7) -> 6.8520819 | AB388: =IF($AY7 > 0, AB7, AB7) -> 3.199273 | AC388: =IF($AY7 > 0, AC7, AB7) -> 4.832371 | AD388: =IF($AY7 > 0, AD7, AD7) -> 2.892981 | AE388: =IF($AY7 > 0, AE7, AD7) -> 10.556205 | AF388: =IF($AY7 > 0, AF7, AF7) -> 2.0297543 | AG388: =IF($AY7 > 0, AG7, AF7) -> 2.5032138 | AH388: =IF($AY7 > 0, AH7, AH7) -> 5.2049517 | AI388: =IF($AY7 > 0, AI7, AH7) -> 9.8846658 | AK388: =IF($AY7 > 0, AK7, AK7) -> 1.7459986 | AL388: =IF($AY7 > 0, AL7, AK7) -> 4.2834749 | AM388: =IF($AY7 > 0, AM7, AK7) -> 4.4000099 | AN388: =IF($AY7 > 0, AN7, AN7) -> 3.199273 | AO388: =IF($AY7 > 0, AO7, AN7) -> 3.0720111 | AP388: =IF($AY7 > 0, AP7, AP7) -> 2.892981 | AQ388: =IF($AY7 > 0, AQ7, AP7) -> 7.730213 | AR388: =IF($AY7 > 0, AR7, AR7) -> 1.1097154 | AS388: =IF($AY7 > 0, AS7, AR7) -> 0.7778796 | AT388: =IF($AY7 > 0, AT7, AT7) -> 5.2049517 | AU388: =IF($AY7 > 0, AU7, AT7) -> 8.2927167
A389: 21 | B389: 156XNXN | C389: Hong_Kong_Weather_3 | D389: {cloud, mean_wet_bulb_temp, rainfall, rel_humidity} | F389: 0 | G389: 0 | H389: 0 | I389: =I8 -> 0 | J389: =J8 -> 1 | K389: 4 | L389: 0 | M389: =IF($AY8 > 0, M8, M8) -> 4819087.6 | N389: =IF($AY8 > 0, N8, M8) -> 4932159 | O389: =IF($AY8 > 0, O8, M8) -> 5277290.8 | P389: =IF($AY8 > 0, P8, P8) -> 5594837.2 | Q389: =IF($AY8 > 0, Q8, P8) -> 1744670 | R389: =IF($AY8 > 0, R8, R8) -> 4114032.2 | S389: =IF($AY8 > 0, S8, R8) -> 4301307.4 | T389: =IF($AY8 > 0, T8, T8) -> 4018927.8 | U389: =IF($AY8 > 0, U8, T8) -> 4004214.4 | V389: =IF($AY8 > 0, V8, V8) -> 24198068 | W389: =IF($AY8 > 0, W8, V8) -> 2695408.4 | Y389: =IF($AY8 > 0, Y8, Y8) -> 5.2910015 | Z389: =IF($AY8 > 0, Z8, Y8) -> 4.2471254 | AA389: =IF($AY8 > 0, AA8, Y8) -> 4.4392391 | AB389: =IF($AY8 > 0, AB8, AB8) -> 6.9649184 | AC389: =IF($AY8 > 0, AC8, AB8) -> 2.5508812 | AD389: =IF($AY8 > 0, AD8, AD8) -> 6.292094 | AE389: =IF($AY8 > 0, AE8, AD8) -> 4.1369936 | AF389: =IF($AY8 > 0, AF8, AF8) -> 1.5069674 | AG389: =IF($AY8 > 0, AG8, AF8) -> 2.5294473 | AH389: =IF($AY8 > 0, AH8, AH8) -> 8.4431713 | AI389: =IF($AY8 > 0, AI8, AH8) -> 6.5814194 | AK389: =IF($AY8 > 0, AK8, AK8) -> 5.2910015 | AL389: =IF($AY8 > 0, AL8, AK8) -> 1.6044603 | AM389: =IF($AY8 > 0, AM8, AK8) -> 1.8026691 | AN389: =IF($AY8 > 0, AN8, AN8) -> 6.9649184 | AO389: =IF($AY8 > 0, AO8, AN8) -> 1.0486424 | AP389: =IF($AY8 > 0, AP8, AP8) -> 6.292094 | AQ389: =IF($AY8 > 0, AQ8, AP8) -> 1.6140749 | AR389: =IF($AY8 > 0, AR8, AR8) -> 1.0047482 | AS389: =IF($AY8 > 0, AS8, AR8) -> 0.62829525 | AT389: =IF($AY8 > 0, AT8, AT8) -> 8.4431713 | AU389: =IF($AY8 > 0, AU8, AT8) -> 4.9306731
A390: 21 | B390: 156XNNX | C390: Hong_Kong_Weather_3 | D390: {cloud, mean_wet_bulb_temp, rainfall, rel_humidity} | F390: 0 | G390: 0 | H390: 0 | I390: =I9 -> 0 | J390: =J9 -> 1 | K390: 4 | L390: 0 | M390: =IF($AY9 > 0, M9, M9) -> 2186441.2 | N390: =IF($AY9 > 0, N9, M9) -> 4570545.2 | O390: =IF($AY9 > 0, O9, M9) -> 4339608.6 | P390: =IF($AY9 > 0, P9, P9) -> 1589889 | Q390: =IF($AY9 > 0, Q9, P9) -> 2689294.8 | R390: =IF($AY9 > 0, R9, R9) -> 616867 | S390: =IF($AY9 > 0, S9, R9) -> 2147966.8 | T390: =IF($AY9 > 0, T9, T9) -> 4560935.4 | U390: =IF($AY9 > 0, U9, T9) -> 3691327.6 | V390: =IF($AY9 > 0, V9, V9) -> 575641.8 | W390: =IF($AY9 > 0, W9, V9) -> 2539553.2 | Y390: =IF($AY9 > 0, Y9, Y9) -> 2.1583616 | Z390: =IF($AY9 > 0, Z9, Y9) -> 3.9812017 | AA390: =IF($AY9 > 0, AA9, Y9) -> 3.836798 | AB390: =IF($AY9 > 0, AB9, AB9) -> 2.0238636 | AC390: =IF($AY9 > 0, AC9, AB9) -> 2.9633648 | AD390: =IF($AY9 > 0, AD9, AD9) -> 1.6820759 | AE390: =IF($AY9 > 0, AE9, AD9) -> 3.1078367 | AF390: =IF($AY9 > 0, AF9, AF9) -> 1.8537012 | AG390: =IF($AY9 > 0, AG9, AF9) -> 2.0354693 | AH390: =IF($AY9 > 0, AH9, AH9) -> 2.9026718 | AI390: =IF($AY9 > 0, AI9, AH9) -> 5.0440308 | AK390: =IF($AY9 > 0, AK9, AK9) -> 2.1583616 | AL390: =IF($AY9 > 0, AL9, AK9) -> 1.9623007 | AM390: =IF($AY9 > 0, AM9, AK9) -> 1.8304167 | AN390: =IF($AY9 > 0, AN9, AN9) -> 2.0238636 | AO390: =IF($AY9 > 0, AO9, AN9) -> 1.4115784 | AP390: =IF($AY9 > 0, AP9, AP9) -> 1.6820759 | AQ390: =IF($AY9 > 0, AQ9, AP9) -> 1.4057721 | AR390: =IF($AY9 > 0, AR9, AR9) -> 1.087151 | AS390: =IF($AY9 > 0, AS9, AR9) -> 0.60014935 | AT390: =IF($AY9 > 0, AT9, AT9) -> 2.9026718 | AU390: =IF($AY9 > 0, AU9, AT9) -> 3.6228537
A391: 21 | B391: 156XNNN | C391: Hong_Kong_Weather_3 | D391: {cloud, mean_wet_bulb_temp, rainfall, rel_humidity} | F391: 0 | G391: 1 | H391: 0 | I391: =I10 -> 0 | J391: =J10 -> 1 | K391: 4 | L391: 0 | M391: =IF($AY10 > 0, M10, M10) -> 1359597.6 | N391: =IF($AY10 > 0, N10, M10) -> 3167304.6 | O391: =IF($AY10 > 0, O10, M10) -> 3404874 | P391: =IF($AY10 > 0, P10, P10) -> 602084 | Q391: =IF($AY10 > 0, Q10, P10) -> 1300983.6 | R391: =IF($AY10 > 0, R10, R10) -> 362702.6 | S391: =IF($AY10 > 0, S10, R10) -> 1474098.6 | T391: =IF($AY10 > 0, T10, T10) -> 3787607.6 | U391: =IF($AY10 > 0, U10, T10) -> 3761598.4 | V391: =IF($AY10 > 0, V10, V10) -> 230918.4 | W391: =IF($AY10 > 0, W10, V10) -> 2099069.6 | Y391: =IF($AY10 > 0, Y10, Y10) -> 1.6504133 | Z391: =IF($AY10 > 0, Z10, Y10) -> 2.9586209 | AA391: =IF($AY10 > 0, AA10, Y10) -> 3.1068234 | AB391: =IF($AY10 > 0, AB10, AB10) -> 1.309188 | AC391: =IF($AY10 > 0, AC10, AB10) -> 2.0336399 | AD391: =IF($AY10 > 0, AD10, AD10) -> 1.7599426 | AE391: =IF($AY10 > 0, AE10, AD10) -> 2.5879828 | AF391: =IF($AY10 > 0, AF10, AF10) -> 1.216636 | AG391: =IF($AY10 > 0, AG10, AF10) -> 2.187835 | AH391: =IF($AY10 > 0, AH10, AH10) -> 1.5905149 | AI391: =IF($AY10 > 0, AI10, AH10) -> 4.9674127 | AK391: =IF($AY10 > 0, AK10, AK10) -> 1.6504133 | AL391: =IF($AY10 > 0, AL10, AK10) -> 1.0622237 | AM391: =IF($AY10 > 0, AM10, AK10) -> 1.2209281 | AN391: =IF($AY10 > 0, AN10, AN10) -> 1.309188 | AO391: =IF($AY10 > 0, AO10, AN10) -> 0.77097515 | AP391: =IF($AY10 > 0, AP10, AP10) -> 1.7599426 | AQ391: =IF($AY10 > 0, AQ10, AP10) -> 0.84869093 | AR391: =IF($AY10 > 0, AR10, AR10) -> 0.78808016 | AS391: =IF($AY10 > 0, AS10, AR10) -> 0.56963752 | AT391: =IF($AY10 > 0, AT10, AT10) -> 1.5905149 | AU391: =IF($AY10 > 0, AU10, AT10) -> 3.3881653
A392: 21 | B392: 156NXXX | C392: Hong_Kong_Weather_3 | D392: {cloud, mean_wet_bulb_temp, rainfall, rel_humidity} | F392: 0 | G392: 1 | H392: 0 | I392: =I11 -> 0 | J392: =J11 -> 1 | K392: 4 | L392: 0 | M392: =IF($AY11 > 0, M11, M11) -> 6171416.2 | N392: =IF($AY11 > 0, N11, M11) -> 6805158.4 | O392: =IF($AY11 > 0, O11, M11) -> 6857539.4 | P392: =IF($AY11 > 0, P11, P11) -> 8419143.6 | Q392: =IF($AY11 > 0, Q11, P11) -> 2905263.6 | R392: =IF($AY11 > 0, R11, R11) -> 9256532.2 | S392: =IF($AY11 > 0, S11, R11) -> 6328932 | T392: =IF($AY11 > 0, T11, T11) -> 4215910.2 | U392: =IF($AY11 > 0, U11, T11) -> 4184912 | V392: =IF($AY11 > 0, V11, V11) -> 19259380 | W392: =IF($AY11 > 0, W11, V11) -> 3812327.2 | Y392: =IF($AY11 > 0, Y11, Y11) -> 6.5145961 | Z392: =IF($AY11 > 0, Z11, Y11) -> 5.4953548 | AA392: =IF($AY11 > 0, AA11, Y11) -> 5.4963909 | AB392: =IF($AY11 > 0, AB11, AB11) -> 10.051685 | AC392: =IF($AY11 > 0, AC11, AB11) -> 3.3562829 | AD392: =IF($AY11 > 0, AD11, AD11) -> 9.2313233 | AE392: =IF($AY11 > 0, AE11, AD11) -> 5.8270503 | AF392: =IF($AY11 > 0, AF11, AF11) -> 1.662673 | AG392: =IF($AY11 > 0, AG11, AF11) -> 2.7369827 | AH392: =IF($AY11 > 0, AH11, AH11) -> 10.641126 | AI392: =IF($AY11 > 0, AI11, AH11) -> 8.6416807 | AK392: =IF($AY11 > 0, AK11, AK11) -> 6.5145961 | AL392: =IF($AY11 > 0, AL11, AK11) -> 2.2705729 | AM392: =IF($AY11 > 0, AM11, AK11) -> 2.29022 | AN392: =IF($AY11 > 0, AN11, AN11) -> 10.051685 | AO392: =IF($AY11 > 0, AO11, AN11) -> 1.5883353 | AP392: =IF($AY11 > 0, AP11, AP11) -> 9.2313233 | AQ392: =IF($AY11 > 0, AQ11, AP11) -> 2.323506 | AR392: =IF($AY11 > 0, AR11, AR11) -> 1.0560422 | AS392: =IF($AY11 > 0, AS11, AR11) -> 0.65100236 | AT392: =IF($AY11 > 0, AT11, AT11) -> 10.641126 | AU392: =IF($AY11 > 0, AU11, AT11) -> 6.74493
A393: 21 | B393: 156NXXN | C393: Hong_Kong_Weather_3 | D393: {cloud, mean_wet_bulb_temp, rainfall, rel_humidity} | F393: 0 | G393: 0 | H393: 0 | I393: =I12 -> 0 | J393: =J12 -> 1 | K393: 4 | L393: 0 | M393: =IF($AY12 > 0, M12, M12) -> 6077126.4 | N393: =IF($AY12 > 0, N12, M12) -> 6523186.2 | O393: =IF($AY12 > 0, O12, M12) -> 6683859.2 | P393: =IF($AY12 > 0, P12, P12) -> 14297376 | Q393: =IF($AY12 > 0, Q12, P12) -> 2766018.8 | R393: =IF($AY12 > 0, R12, R12) -> 9345182.6 | S393: =IF($AY12 > 0, S12, R12) -> 7992747.4 | T393: =IF($AY12 > 0, T12, T12) -> 4852422.4 | U393: =IF($AY12 > 0, U12, T12) -> 3966619.4 | V393: =IF($AY12 > 0, V12, V12) -> 31495539 | W393: =IF($AY12 > 0, W12, V12) -> 3691529.6 | Y393: =IF($AY12 > 0, Y12, Y12) -> 6.1149932 | Z393: =IF($AY12 > 0, Z12, Y12) -> 5.2643429 | AA393: =IF($AY12 > 0, AA12, Y12) -> 5.3412261 | AB393: =IF($AY12 > 0, AB12, AB12) -> 12.623191 | AC393: =IF($AY12 > 0, AC12, AB12) -> 3.3510144 | AD393: =IF($AY12 > 0, AD12, AD12) -> 10.215354 | AE393: =IF($AY12 > 0, AE12, AD12) -> 6.7976655 | AF393: =IF($AY12 > 0, AF12, AF12) -> 2.2462109 | AG393: =IF($AY12 > 0, AG12, AF12) -> 2.4651819 | AH393: =IF($AY12 > 0, AH12, AH12) -> 11.225533 | AI393: =IF($AY12 > 0, AI12, AH12) -> 8.0396503 | AK393: =IF($AY12 > 0, AK12, AK12) -> 6.1149932 | AL393: =IF($AY12 > 0, AL12, AK12) -> 2.6219385 | AM393: =IF($AY12 > 0, AM12, AK12) -> 2.6974127 | AN393: =IF($AY12 > 0, AN12, AN12) -> 12.623191 | AO393: =IF($AY12 > 0, AO12, AN12) -> 1.780658 | AP393: =IF($AY12 > 0, AP12, AP12) -> 10.215354 | AQ393: =IF($AY12 > 0, AQ12, AP12) -> 3.9254723 | AR393: =IF($AY12 > 0, AR12, AR12) -> 1.259069 | AS393: =IF($AY12 > 0, AS12, AR12) -> 0.6301522 | AT393: =IF($AY12 > 0, AT12, AT12) -> 11.225533 | AU393: =IF($AY12 > 0, AU12, AT12) -> 6.3221946
A394: 21 | B394: 156NXNX | C394: Hong_Kong_Weather_3 | D394: {cloud, mean_wet_bulb_temp, rainfall, rel_humidity} | F394: 0 | G394: 0 | H394: 0 | I394: =I13 -> 0 | J394: =J13 -> 1 | K394: 4 | L394: 0 | M394: =IF($AY13 > 0, M13, M13) -> 4373945.6 | N394: =IF($AY13 > 0, N13, M13) -> 3525196.8 | O394: =IF($AY13 > 0, O13, M13) -> 3542716.8 | P394: =IF($AY13 > 0, P13, P13) -> 4791875 | Q394: =IF($AY13 > 0, Q13, P13) -> 1227249 | R394: =IF($AY13 > 0, R13, R13) -> 3330299.8 | S394: =IF($AY13 > 0, S13, R13) -> 1129757.4 | T394: =IF($AY13 > 0, T13, T13) -> 4221177.6 | U394: =IF($AY13 > 0, U13, T13) -> 3820898.8 | V394: =IF($AY13 > 0, V13, V13) -> 5883243.8 | W394: =IF($AY13 > 0, W13, V13) -> 2247583.4 | Y394: =IF($AY13 > 0, Y13, Y13) -> 4.0645885 | Z394: =IF($AY13 > 0, Z13, Y13) -> 3.0854349 | AA394: =IF($AY13 > 0, AA13, Y13) -> 3.0809418 | AB394: =IF($AY13 > 0, AB13, AB13) -> 3.1259433 | AC394: =IF($AY13 > 0, AC13, AB13) -> 1.7536643 | AD394: =IF($AY13 > 0, AD13, AD13) -> 3.0631603 | AE394: =IF($AY13 > 0, AE13, AD13) -> 2.3240296 | AF394: =IF($AY13 > 0, AF13, AF13) -> 1.6403528 | AG394: =IF($AY13 > 0, AG13, AF13) -> 2.2280405 | AH394: =IF($AY13 > 0, AH13, AH13) -> 4.4035068 | AI394: =IF($AY13 > 0, AI13, AH13) -> 4.2895956 | AK394: =IF($AY13 > 0, AK13, AK13) -> 4.0645885 | AL394: =IF($AY13 > 0, AL13, AK13) -> 1.190528 | AM394: =IF($AY13 > 0, AM13, AK13) -> 1.1977567 | AN394: =IF($AY13 > 0, AN13, AN13) -> 3.1259433 | AO394: =IF($AY13 > 0, AO13, AN13) -> 0.77954667 | AP394: =IF($AY13 > 0, AP13, AP13) -> 3.0631603 | AQ394: =IF($AY13 > 0, AQ13, AP13) -> 0.83620563 | AR394: =IF($AY13 > 0, AR13, AR13) -> 1.0916918 | AS394: =IF($AY13 > 0, AS13, AR13) -> 0.5944944 | AT394: =IF($AY13 > 0, AT13, AT13) -> 4.4035068 | AU394: =IF($AY13 > 0, AU13, AT13) -> 2.6821506
A395: 21 | B395: 156NXNN | C395: Hong_Kong_Weather_3 | D395: {cloud, mean_wet_bulb_temp, rainfall, rel_humidity} | F395: 0 | G395: 1 | H395: 0 | I395: =I14 -> 0 | J395: =J14 -> 1 | K395: 4 | L395: 0 | M395: =IF($AY14 > 0, M14, M14) -> 1743369.2 | N395: =IF($AY14 > 0, N14, M14) -> 5681416.4 | O395: =IF($AY14 > 0, O14, M14) -> 5716200.8 | P395: =IF($AY14 > 0, P14, P14) -> 3424600.8 | Q395: =IF($AY14 > 0, Q14, P14) -> 3042341.4 | R395: =IF($AY14 > 0, R14, R14) -> 2642237 | S395: =IF($AY14 > 0, S14, R14) -> 2579986.8 | T395: =IF($AY14 > 0, T14, T14) -> 4575869 | U395: =IF($AY14 > 0, U14, T14) -> 3750440.2 | V395: =IF($AY14 > 0, V14, V14) -> 7388502.4 | W395: =IF($AY14 > 0, W14, V14) -> 4680236.4 | Y395: =IF($AY14 > 0, Y14, Y14) -> 1.9127118 | Z395: =IF($AY14 > 0, Z14, Y14) -> 4.7608887 | AA395: =IF($AY14 > 0, AA14, Y14) -> 4.7306703 | AB395: =IF($AY14 > 0, AB14, AB14) -> 3.1142022 | AC395: =IF($AY14 > 0, AC14, AB14) -> 3.0985967 | AD395: =IF($AY14 > 0, AD14, AD14) -> 3.3492492 | AE395: =IF($AY14 > 0, AE14, AD14) -> 3.4092037 | AF395: =IF($AY14 > 0, AF14, AF14) -> 1.8588019 | AG395: =IF($AY14 > 0, AG14, AF14) -> 2.130245 | AH395: =IF($AY14 > 0, AH14, AH14) -> 4.9357865 | AI395: =IF($AY14 > 0, AI14, AH14) -> 7.190099 | AK395: =IF($AY14 > 0, AK14, AK14) -> 1.9127118 | AL395: =IF($AY14 > 0, AL14, AK14) -> 2.2804257 | AM395: =IF($AY14 > 0, AM14, AK14) -> 2.2775786 | AN395: =IF($AY14 > 0, AN14, AN14) -> 3.1142022 | AO395: =IF($AY14 > 0, AO14, AN14) -> 1.5012025 | AP395: =IF($AY14 > 0, AP14, AP14) -> 3.3492492 | AQ395: =IF($AY14 > 0, AQ14, AP14) -> 1.4923652 | AR395: =IF($AY14 > 0, AR14, AR14) -> 1.0765884 | AS395: =IF($AY14 > 0, AS14, AR14) -> 0.60571621 | AT395: =IF($AY14 > 0, AT14, AT14) -> 4.9357865 | AU395: =IF($AY14 > 0, AU14, AT14) -> 5.4135304
... A543: 12 | B543: 90NNN | C543: DryBean_2 | D543: {Area, Compactness, Eccentricity} | F543: 0 | G543: 1 | H543: 0 | I543: =I162 -> 0 | J543: =J162 -> 1 | K543: 3 | L543: 0 | M543: =IF($AY162 > 0, M162, M162) -> 8551058.6 | N543: =IF($AY162 > 0, N162, M162) -> 2240817 | O543: =IF($AY162 > 0, O162, M162) -> 2249375 | P543: =IF($AY162 > 0, P162, P162) -> 18313333 | Q543: =IF($AY162 > 0, Q162, P162) -> 858432.4 | R543: =IF($AY162 > 0, R162, R162) -> 9876058.6 | S543: =IF($AY162 > 0, S162, R162) -> 1364324.4 | T543: =IF($AY162 > 0, T162, T162) -> 9453028.2 | U543: =IF($AY162 > 0, U162, T162) -> 4905973.2 | V543: =IF($AY162 > 0, V162, V162) -> 10764022 | W543: =IF($AY162 > 0, W162, V162) -> 2131120.8 | Y543: =IF($AY162 > 0, Y162, Y162) -> 6.3840426 | Z543: =IF($AY162 > 0, Z162, Y162) -> 1.9849401 | AA543: =IF($AY162 > 0, AA162, Y162) -> 1.9789719 | AB543: =IF($AY162 > 0, AB162, AB162) -> 12.076818 | AC543: =IF($AY162 > 0, AC162, AB162) -> 1.2422673 | AD543: =IF($AY162 > 0, AD162, AD162) -> 7.3952776 | AE543: =IF($AY162 > 0, AE162, AD162) -> 1.6713525 | AF543: =IF($AY162 > 0, AF162, AF162) -> 5.6956633 | AG543: =IF($AY162 > 0, AG162, AF162) -> 3.1246839 | AH543: =IF($AY162 > 0, AH162, AH162) -> 5.2542972 | AI543: =IF($AY162 > 0, AI162, AH162) -> 2.9626138 | AK543: =IF($AY162 > 0, AK162, AK162) -> 6.3840426 | AL543: =IF($AY162 > 0, AL162, AK162) -> 0.75734993 | AM543: =IF($AY162 > 0, AM162, AK162) -> 0.75412688 | AN543: =IF($AY162 > 0, AN162, AN162) -> 12.076818 | AO543: =IF($AY162 > 0, AO162, AN162) -> 0.56581209 | AP543: =IF($AY162 > 0, AP162, AP162) -> 7.3952776 | AQ543: =IF($AY162 > 0, AQ162, AP162) -> 0.70782051 | AR543: =IF($AY162 > 0, AR162, AR162) -> 3.9018358 | AS543: =IF($AY162 > 0, AS162, AR162) -> 0.61182996 | AT543: =IF($AY162 > 0, AT162, AT162) -> 5.2542972 | AU543: =IF($AY162 > 0, AU162, AT162) -> 1.5747192
M764: BNL | N764: BNL Causal | O764: BNL Causal HM | P764: SFS | Q764: SFS Causal | R764: SaLSa | S764: SaLSa Causal | T764: D&C | U764: D&C Causal | V764: BBS | W764: BBS Causal | Y764: BNL | Z764: BNL Causal | AA764: BNL Causal HM | AB764: SFS | AC764: SFS Causal | AD764: SaLSa | AE764: SaLSa Causal | AF764: D&C | AG764: D&C Causal | AH764: BBS | AI764: BBS Causal | AK764: BNL | AL764: BNL Causal | AM764: BNL Causal HM | AN764: SFS | AO764: SFS Causal | AP764: SaLSa | AQ764: SaLSa Causal | AR764: D&C | AS764: D&C Causal | AT764: BBS | AU764: BBS Causal
L765: Mean | M765: =AVERAGEIF($H$384:$H$759, "=1", M384:M759) -> 2408467.9 | N765: =AVERAGEIF($H$384:$H$759, "=1", N384:N759) -> 2743431.4 | O765: =AVERAGEIF($H$384:$H$759, "=1", O384:O759) -> 2801412.8 | P765: =AVERAGEIF($H$384:$H$759, "=1", P384:P759) -> 3929169.3 | Q765: =AVERAGEIF($H$384:$H$759, "=1", Q384:Q759) -> 2174911.3 | R765: =AVERAGEIF($H$384:$H$759, "=1", R384:R759) -> 4556204.5 | S765: =AVERAGEIF($H$384:$H$759, "=1", S384:S759) -> 2738096.8 | T765: =AVERAGEIF($H$384:$H$759, "=1", T384:T759) -> 4656147.5 | ... W765: =AVERAGEIF($H$384:$H$759, "=1", W384:W759) -> 4181764.1 | X765: Mean | Y765: =AVERAGEIF($H$384:$H$759, "=1", Y384:Y759) -> 2.1598267 | Z765: =AVERAGEIF($H$384:$H$759, "=1", Z384:Z759) -> 2.5616976 | AA765: =AVERAGEIF($H$384:$H$759, "=1", AA384:AA759) -> 2.5825795 | AB765: =AVERAGEIF($H$384:$H$759, "=1", AB384:AB759) -> 2.9966933 | AC765: =AVERAGEIF($H$384:$H$759, "=1", AC384:AC759) -> 2.467774 | AD765: =AVERAGEIF($H$384:$H$759, "=1", AD384:AD759) -> 3.7183701 | AE765: =AVERAGEIF($H$384:$H$759, "=1", AE384:AE759) -> 2.7152438 | AF765: =AVERAGEIF($H$384:$H$759, "=1", AF384:AF759) -> 2.2138696 | ... AI765: =AVERAGEIF($H$384:$H$759, "=1", AI384:AI759) -> 5.2337021 | AJ765: Mean | AK765: =AVERAGEIF($H$384:$H$759, "=1", AK384:AK759) -> 2.1598267 | AL765: =AVERAGEIF($H$384:$H$759, "=1", AL384:AL759) -> 1.1421208 | AM765: =AVERAGEIF($H$384:$H$759, "=1", AM384:AM759) -> 1.1690416 | AN765: =AVERAGEIF($H$384:$H$759, "=1", AN384:AN759) -> 2.9966933 | AO765: =AVERAGEIF($H$384:$H$759, "=1", AO384:AO759) -> 1.1999972 | AP765: =AVERAGEIF($H$384:$H$759, "=1", AP384:AP759) -> 3.7183701 | AQ765: =AVERAGEIF($H$384:$H$759, "=1", AQ384:AQ759) -> 1.2985928 | AR765: =AVERAGEIF($H$384:$H$759, "=1", AR384:AR759) -> 1.2762824 | ... AU765: =AVERAGEIF($H$384:$H$759, "=1", AU384:AU759) -> 3.711668
L766: Median | M766: {=MEDIAN(_xlfn._xlws.FILTER(M384:M759, $H$384:$H$759=1))} -> 2092332.6 | N766: {=MEDIAN(_xlfn._xlws.FILTER(N384:N759, $H$384:$H$759=1))} -> 1531539.8 | O766: {=MEDIAN(_xlfn._xlws.FILTER(O384:O759, $H$384:$H$759=1))} -> 1561343.1 | P766: {=MEDIAN(_xlfn._xlws.FILTER(P384:P759, $H$384:$H$759=1))} -> 1965994.9 | Q766: {=MEDIAN(_xlfn._xlws.FILTER(Q384:Q759, $H$384:$H$759=1))} -> 821674 | R766: {=MEDIAN(_xlfn._xlws.FILTER(R384:R759, $H$384:$H$759=1))} -> 1194948.7 | S766: {=MEDIAN(_xlfn._xlws.FILTER(S384:S759, $H$384:$H$759=1))} -> 1071795.8 | T766: {=MEDIAN(_xlfn._xlws.FILTER(T384:T759, $H$384:$H$759=1))} -> 4044156.5 | ... W766: {=MEDIAN(_xlfn._xlws.FILTER(W384:W759, $H$384:$H$759=1))} -> 1683047.9 | X766: Median | Y766: {=MEDIAN(_xlfn._xlws.FILTER(Y384:Y759, $H$384:$H$759=1))} -> 1.8740377 | Z766: {=MEDIAN(_xlfn._xlws.FILTER(Z384:Z759, $H$384:$H$759=1))} -> 1.7124742 | AA766: {=MEDIAN(_xlfn._xlws.FILTER(AA384:AA759, $H$384:$H$759=1))} -> 1.7128647 | AB766: {=MEDIAN(_xlfn._xlws.FILTER(AB384:AB759, $H$384:$H$759=1))} -> 2.1432157 | AC766: {=MEDIAN(_xlfn._xlws.FILTER(AC384:AC759, $H$384:$H$759=1))} -> 1.3509295 | AD766: {=MEDIAN(_xlfn._xlws.FILTER(AD384:AD759, $H$384:$H$759=1))} -> 2.1672701 | AE766: {=MEDIAN(_xlfn._xlws.FILTER(AE384:AE759, $H$384:$H$759=1))} -> 1.4927342 | AF766: {=MEDIAN(_xlfn._xlws.FILTER(AF384:AF759, $H$384:$H$759=1))} -> 1.7610383 | ... AI766: {=MEDIAN(_xlfn._xlws.FILTER(AI384:AI759, $H$384:$H$759=1))} -> 2.7588588 | AJ766: Median | AK766: {=MEDIAN(_xlfn._xlws.FILTER(AK384:AK759, $H$384:$H$759=1))} -> 1.8740377 | AL766: {=MEDIAN(_xlfn._xlws.FILTER(AL384:AL759, $H$384:$H$759=1))} -> 0.71356216 | AM766: {=MEDIAN(_xlfn._xlws.FILTER(AM384:AM759, $H$384:$H$759=1))} -> 0.71258516 | AN766: {=MEDIAN(_xlfn._xlws.FILTER(AN384:AN759, $H$384:$H$759=1))} -> 2.1432157 | AO766: {=MEDIAN(_xlfn._xlws.FILTER(AO384:AO759, $H$384:$H$759=1))} -> 0.59868636 | AP766: {=MEDIAN(_xlfn._xlws.FILTER(AP384:AP759, $H$384:$H$759=1))} -> 2.1672701 | AQ766: {=MEDIAN(_xlfn._xlws.FILTER(AQ384:AQ759, $H$384:$H$759=1))} -> 0.68447303 | AR766: {=MEDIAN(_xlfn._xlws.FILTER(AR384:AR759, $H$384:$H$759=1))} -> 1.0364065 | ... AU766: {=MEDIAN(_xlfn._xlws.FILTER(AU384:AU759, $H$384:$H$759=1))} -> 1.4934936
M769: BNL Causal | N769: BNL Causal HM | O769: SFS Causal | P769: SaLSa Causal | Q769: D&C Causal | R769: BBS Causal | T769: BNL Causal | U769: BNL Causal HM | V769: SFS Causal | W769: SaLSa Causal | X769: D&C Causal | Y769: BBS Causal | AA769: BNL Causal | AB769: BNL Causal HM | AC769: SFS Causal | AD769: SaLSa Causal | AE769: D&C Causal | AF769: BBS Causal
L770: Mean | M770: =N765 -> 2743431.4 | N770: =O765 -> 2801412.8 | O770: =Q765 -> 2174911.3 | P770: =S765 -> 2738096.8 | Q770: =U765 -> 3577666.4 | R770: =W765 -> 4181764.1 | S770: Mean | T770: =Z765 -> 2.5616976 | U770: =AA765 -> 2.5825795 | V770: =AC765 -> 2.467774 | W770: =AE765 -> 2.7152438 | X770: =AG765 -> 2.1536799 | Y770: =AI765 -> 5.2337021 | Z770: Mean | AA770: =AL765 -> 1.1421208 | AB770: =AM765 -> 1.1690416 | AC770: =AO765 -> 1.1999972 | AD770: =AQ765 -> 1.2985928 | AE770: =AS765 -> 0.53040182 | AF770: =AU765 -> 3.711668
L771: Median | M771: =N766 -> 1531539.8 | N771: =O766 -> 1561343.1 | O771: =Q766 -> 821674 | P771: =S766 -> 1071795.8 | Q771: =U766 -> 3780997.2 | R771: =W766 -> 1683047.9 | S771: Median | T771: =Z766 -> 1.7124742 | U771: =AA766 -> 1.7128647 | V771: =AC766 -> 1.3509295 | W771: =AE766 -> 1.4927342 | X771: =AG766 -> 2.395895 | Y771: =AI766 -> 2.7588588 | Z771: Median | AA771: =AL766 -> 0.71356216 | AB771: =AM766 -> 0.71258516 | AC771: =AO766 -> 0.59868636 | AD771: =AQ766 -> 0.68447303 | AE771: =AS766 -> 0.52318076 | AF771: =AU766 -> 1.4934936

Sheet Provided DAG
M1: Average Benchmark (results) | Y1: Average Benchmark (sequential timing) | AK1: Average Benchmark (parallel timing) | AW1: Average Benchmark (cluster_time)
F2: TargetN | G2: #N | H2: Target (or sym) | I2: Gain <=0 | J2: Gain > 0 | K2: Pref | L2: Pref&Target | M2: BNL | N2: BNL Causal | O2: BNL Causal HM | P2: SFS | Q2: SFS Causal | R2: SaLSa | S2: SaLSa Causal | T2: D&C | U2: D&C Causal | V2: BBS | W2: BBS Causal | Y2: BNL | Z2: BNL Causal | AA2: BNL Causal HM | AB2: SFS | AC2: SFS Causal | AD2: SaLSa | AE2: SaLSa Causal | AF2: D&C | AG2: D&C Causal | AH2: BBS | AI2: BBS Causal | AK2: BNL | AL2: BNL Causal | AM2: BNL Causal HM | AN2: SFS | AO2: SFS Causal | AP2: SaLSa | AQ2: SaLSa Causal | AR2: D&C | AS2: D&C Causal | AT2: BBS | AU2: BBS Causal | AW2: KMeans Time (seconds) | AY2: Gain
A3: 21 | B3: 156XXXX | C3: Hong_Kong_Weather_3 | D3: {cloud, mean_wet_bulb_temp, rainfall, rel_humidity} | F3: 0 | G3: 0 | H3: 1 | I3: =1 - J3 -> 1 | J3: =IF(AY3 > 0, 1, 0) -> 0 | K3: 4 | L3: 4 | M3: 984737.8 | N3: 2065519.6 | O3: 2077746.6 | P3: 1004122.8 | Q3: 1196804 | R3: 881239.4 | S3: 1531567.8 | T3: 4185627.2 | U3: 4029461.6 | V3: 1396199.2 | W3: 1952768.8 | Y3: 1.3528373 | Z3: 1.7804736 | AA3: 1.7989318 | AB3: 1.6085036 | AC3: 1.5691071 | AD3: 1.0889937 | AE3: 1.8664091 | AF3: 1.5281492 | AG3: 2.3591296 | AH3: 3.0406892 | AI3: 3.9605328 | AK3: 1.3528373 | AL3: 0.46523461 | AM3: 0.47606677 | AN3: 1.6085036 | AO3: 0.46240435 | AP3: 1.0889937 | AQ3: 0.49387636 | AR3: 0.9788534 | AS3: 0.38676819 | AT3: 3.0406892 | AU3: 2.3079172 | AW3: 0.1348423 | AY3: -0.35233006
A4: 21 | B4: 156XXXN | C4: Hong_Kong_Weather_3 | D4: {cloud, mean_wet_bulb_temp, rainfall, rel_humidity} | F4: 0 | G4: 1 | H4: 0 | I4: =1 - J4 -> 1 | J4: =IF(AY4 > 0, 1, 0) -> 0 | K4: 4 | L4: 0 | M4: 9774060 | N4: 7787347 | O4: 8018262 | P4: 14747945 | Q4: 3371952.2 | R4: 16571915 | S4: 7294842.6 | T4: 4907318.2 | U4: 4075037.2 | V4: 21091677 | W4: 8771390.6 | Y4: 8.3987104 | Z4: 5.6995866 | AA4: 5.7888324 | AB4: 7.9635834 | AC4: 3.1551361 | AD4: 11.354685 | AE4: 5.8008374 | AF4: 2.2395781 | AG4: 2.5840377 | AH4: 8.2811846 | AI4: 9.2663306 | AK4: 8.3987104 | AL4: 1.9179783 | AM4: 2.0175544 | AN4: 7.9635834 | AO4: 0.96779636 | AP4: 11.354685 | AQ4: 1.6019943 | AR4: 1.2717491 | AS4: 0.53269426 | AT4: 8.2811846 | AU4: 6.6443375 | AW4: 0.14268781 | AY4: -0.058564036
A5: 21 | B5: 156XXNX | C5: Hong_Kong_Weather_3 | D5: {cloud, mean_wet_bulb_temp, rainfall, rel_humidity} | F5: 0 | G5: 1 | H5: 0 | I5: =1 - J5 -> 1 | J5: =IF(AY5 > 0, 1, 0) -> 0 | K5: 4 | L5: 0 | M5: 4329316.4 | N5: 4073765 | O5: 4093826 | P5: 1278792.2 | Q5: 1169461.2 | R5: 616378.2 | S5: 799303.4 | T5: 4215981.4 | U5: 3930543 | V5: 2636300 | W5: 1993208.4 | Y5: 3.8965804 | Z5: 3.1293145 | AA5: 3.116569 | AB5: 2.3151185 | AC5: 1.7877581 | AD5: 1.7500886 | AE5: 1.8185798 | AF5: 1.5827515 | AG5: 2.1768203 | AH5: 3.8325772 | AI5: 4.0426015 | AK5: 3.8965804 | AL5: 1.0829029 | AM5: 1.0814225 | AN5: 2.3151185 | AO5: 0.69547894 | AP5: 1.7500886 | AQ5: 0.57646844 | AR5: 1.0548224 | AS5: 0.44379588 | AT5: 3.8325772 | AU5: 2.4709772 | AW5: 0.14560111 | AY5: -0.12790196
A6: 21 | B6: 156XXNN | C6: Hong_Kong_Weather_3 | D6: {cloud, mean_wet_bulb_temp, rainfall, rel_humidity} | F6: 0 | G6: 0 | H6: 0 | I6: =1 - J6 -> 0 | J6: =IF(AY6 > 0, 1, 0) -> 1 | K6: 4 | L6: 0 | M6: 4797310.6 | N6: 3169061.2 | O6: 3209813.8 | P6: 1475770.8 | Q6: 1107489.6 | R6: 1030299.8 | S6: 843579.4 | T6: 4594408.8 | U6: 3273800.2 | V6: 8246724.6 | W6: 912914.4 | Y6: 4.4553712 | Z6: 2.7874209 | AA6: 2.7923472 | AB6: 2.5663724 | AC6: 1.7913468 | AD6: 2.8465808 | AE6: 2.205985 | AF6: 1.858877 | AG6: 1.6046602 | AH6: 5.5633515 | AI6: 3.1314774 | AK6: 4.4553712 | AL6: 0.84792238 | AM6: 0.85889341 | AN6: 2.5663724 | AO6: 0.52177113 | AP6: 2.8465808 | AQ6: 0.62075655 | AR6: 1.0765732 | AS6: 0.35352484 | AT6: 5.5633515 | AU6: 1.756572 | AW6: 0.14919988 | AY6: 0.11627095
A7: 21 | B7: 156XNXX | C7: Hong_Kong_Weather_3 | D7: {cloud, mean_wet_bulb_temp, rainfall, rel_humidity} | F7: 0 | G7: 1 | H7: 0 | I7: =1 - J7 -> 0 | J7: =IF(AY7 > 0, 1, 0) -> 1 | K7: 4 | L7: 0 | M7: 1254500 | N7: 854464.6 | O7: 865056 | P7: 3405256 | Q7: 420193.2 | R7: 1465331.4 | S7: 452451.4 | T7: 4677209.6 | U7: 3486548 | V7: 7657925.2 | W7: 607417.4 | Y7: 1.7351722 | Z7: 1.1185581 | AA7: 1.1202911 | AB7: 3.1639451 | AC7: 0.9085771 | AD7: 2.8603667 | AE7: 1.0576217 | AF7: 2.0229268 | AG7: 1.9813764 | AH7: 5.3503982 | AI7: 1.6870069 | AK7: 1.7351722 | AL7: 0.37783066 | AM7: 0.37746638 | AN7: 3.1639451 | AO7: 0.29410914 | AP7: 2.8603667 | AQ7: 0.35026507 | AR7: 1.1069986 | AS7: 0.34609188 | AT7: 5.3503982 | AU7: 0.89005566 | AW7: 0.14613112 | AY7: 0.23808718
A8: 21 | B8: 156XNXN | C8: Hong_Kong_Weather_3 | D8: {cloud, mean_wet_bulb_temp, rainfall, rel_humidity} | F8: 0 | G8: 0 | H8: 0 | I8: =1 - J8 -> 0 | J8: =IF(AY8 > 0, 1, 0) -> 1 | K8: 4 | L8: 0 | M8: 4819087.6 | N8: 9194756.6 | O8: 9225581.6 | P8: 5594837.2 | Q8: 5151482.2 | R8: 4114032.2 | S8: 9043081.2 | T8: 4018927.8 | U8: 4749899.6 | V8: 24198068 | W8: 10271220 | Y8: 5.2229898 | Z8: 6.630317 | AA8: 6.6486502 | AB8: 6.95158 | AC8: 3.5294612 | AD8: 6.202183 | AE8: 6.1441774 | AF8: 1.5137357 | AG8: 3.3892191 | AH8: 8.7058219 | AI8: 10.909901 | AK8: 5.2229898 | AL8: 1.7391515 | AM8: 1.7550641 | AN8: 6.95158 | AO8: 1.0336697 | AP8: 6.202183 | AQ8: 1.4187322 | AR8: 1.0106222 | AS8: 0.57144635 | AT8: 8.7058219 | AU8: 7.8596672 | AW8: 0.14654988 | AY8: 0.089505628
A9: 21 | B9: 156XNNX | C9: Hong_Kong_Weather_3 | D9: {cloud, mean_wet_bulb_temp, rainfall, rel_humidity} | F9: 0 | G9: 0 | H9: 0 | I9: =1 - J9 -> 0 | J9: =IF(AY9 > 0, 1, 0) -> 1 | K9: 4 | L9: 0 | M9: 2186441.2 | N9: 1668403.8 | O9: 1682591.4 | P9: 1589889 | Q9: 514547 | R9: 616867 | S9: 338645.6 | T9: 4560935.4 | U9: 3373792.6 | V9: 575641.8 | W9: 331350.8 | Y9: 2.1961748 | Z9: 1.6452419 | AA9: 1.6530101 | AB9: 2.0306719 | AC9: 1.0224316 | AD9: 1.6907598 | AE9: 1.4326806 | AF9: 1.8487289 | AG9: 1.7457337 | AH9: 2.9566901 | AI9: 1.8409904 | AK9: 2.1961748 | AL9: 0.53567567 | AM9: 0.5423391 | AN9: 2.0306719 | AO9: 0.34388079 | AP9: 1.6907598 | AQ9: 0.41130289 | AR9: 1.0833852 | AS9: 0.35068646 | AT9: 2.9566901 | AU9: 1.0378047 | AW9: 0.14718906 | AY9: 0.14655348
A10: 21 | B10: 156XNNN | C10: Hong_Kong_Weather_3 | D10: {cloud, mean_wet_bulb_temp, rainfall, rel_humidity} | F10: 0 | G10: 1 | H10: 0 | I10: =1 - J10 -> 1 | J10: =IF(AY10 > 0, 1, 0) -> 0 | K10: 4 | L10: 0 | M10: 1359597.6 | N10: 3649525.2 | O10: 3650279.8 | P10: 602084 | Q10: 817863.6 | R10: 362702.6 | S10: 671099.8 | T10: 3787607.6 | U10: 3757844.6 | V10: 230918.4 | W10: 1156873.6 | Y10: 1.6715629 | Z10: 2.9774983 | AA10: 2.9584463 | AB10: 1.310768 | AC10: 1.4444231 | AD10: 1.7632602 | AE10: 1.998365 | AF10: 1.2172114 | AG10: 2.0724427 | AH10: 1.647316 | AI10: 3.8715441 | AK10: 1.6715629 | AL10: 0.7004594 | AM10: 0.69548993 | AN10: 1.310768 | AO10: 0.42149887 | AP10: 1.7632602 | AQ10: 0.51170982 | AR10: 0.78862274 | AS10: 0.36825285 | AT10: 1.647316 | AU10: 2.3746505 | AW10: 0.14691303 | AY10: -0.051621186
A11: 21 | B11: 156NXXX | C11: Hong_Kong_Weather_3 | D11: {cloud, mean_wet_bulb_temp, rainfall, rel_humidity} | F11: 0 | G11: 1 | H11: 0 | I11: =1 - J11 -> 1 | J11: =IF(AY11 > 0, 1, 0) -> 0 | K11: 4 | L11: 0 | M11: 6171416.2 | N11: 9424711.4 | O11: 9544685.6 | P11: 8419143.6 | Q11: 4707499.8 | R11: 9256532.2 | S11: 8285529 | T11: 4215910.2 | U11: 4220468 | V11: 19259380 | W11: 10297368 | Y11: 6.5223588 | Z11: 7.1476849 | AA11: 7.1972472 | AB11: 9.8975207 | AC11: 4.9967839 | AD11: 9.0448171 | AE11: 7.5961739 | AF11: 1.6637397 | AG11: 2.7373301 | AH11: 11.037261 | AI11: 12.134643 | AK11: 6.5223588 | AL11: 2.1240042 | AM11: 2.1837949 | AN11: 9.8975207 | AO11: 1.7949825 | AP11: 9.0448171 | AQ11: 2.3521798 | AR11: 1.0548462 | AS11: 0.45948701 | AT11: 11.037261 | AU11: 8.7985225 | AW11: 0.14972612 | AY11: -0.051621186
A12: 21 | B12: 156NXXN | C12: Hong_Kong_Weather_3 | D12: {cloud, mean_wet_bulb_temp, rainfall, rel_humidity} | F12: 0 | G12: 0 | H12: 0 | I12: =1 - J12 -> 0 | J12: =IF(AY12 > 0, 1, 0) -> 1 | K12: 4 | L12: 0 | M12: 6077126.4 | N12: 4788292.2 | O12: 4908316.6 | P12: 14297376 | Q12: 4634993 | R12: 9345182.6 | S12: 3977858.2 | T12: 4852422.4 | U12: 3896412.2 | V12: 31495539 | W12: 8837163.8 | Y12: 6.2782799 | Z12: 3.9825321 | AA12: 4.0014622 | AB12: 12.602408 | AC12: 4.8429511 | AD12: 10.168708 | AE12: 4.9109572 | AF12: 2.2487687 | AG12: 2.4664407 | AH12: 12.011528 | AI12: 7.1827714 | AK12: 6.2782799 | AL12: 1.6904926 | AM12: 1.7273519 | AN12: 12.602408 | AO12: 2.0950829 | AP12: 10.168708 | AQ12: 1.852761 | AR12: 1.2610892 | AS12: 0.48172694 | AT12: 12.011528 | AU12: 4.8324112 | AW12: 0.1481168 | AY12: 0.14655348
A13: 21 | B13: 156NXNX | C13: Hong_Kong_Weather_3 | D13: {cloud, mean_wet_bulb_temp, rainfall, rel_humidity} | F13: 0 | G13: 0 | H13: 0 | I13: =1 - J13 -> 0 | J13: =IF(AY13 > 0, 1, 0) -> 1 | K13: 4 | L13: 0 | M13: 4373945.6 | N13: 5166110.2 | O13: 5196902.2 | P13: 4791875 | Q13: 3060713.4 | R13: 3330299.8 | S13: 2322256 | T13: 4221177.6 | U13: 3961783.8 | V13: 5883243.8 | W13: 4457433.8 | Y13: 4.0905487 | Z13: 4.0030112 | AA13: 4.0161636 | AB13: 3.0819296 | AC13: 2.0569688 | AD13: 3.0702919 | AE13: 2.4800829 | AF13: 1.6390705 | AG13: 2.2868724 | AH13: 4.6049951 | AI13: 5.1316579 | AK13: 4.0905487 | AL13: 0.98756992 | AM13: 1.0003291 | AN13: 3.0819296 | AO13: 0.59641164 | AP13: 3.0702919 | AQ13: 0.68027285 | AR13: 1.0911277 | AS13: 0.45440456 | AT13: 4.6049951 | AU13: 3.177034 | AW13: 0.15011578 | AY13: 0.089505628
A14: 21 | B14: 156NXNN | C14: Hong_Kong_Weather_3 | D14: {cloud, mean_wet_bulb_temp, rainfall, rel_humidity} | F14: 0 | G14: 1 | H14: 0 | I14: =1 - J14 -> 0 | J14: =IF(AY14 > 0, 1, 0) -> 1 | K14: 4 | L14: 0 | M14: 1743369.2 | N14: 902504.8 | O14: 910647 | P14: 3424600.8 | Q14: 368793.2 | R14: 2642237 | S14: 300920.2 | T14: 4575869 | U14: 3203077.8 | V14: 7388502.4 | W14: 456413 | Y14: 1.9183217 | Z14: 1.106608 | AA14: 1.1134915 | AB14: 2.9494921 | AC14: 0.82871261 | AD14: 3.329059 | AE14: 1.4496438 | AF14: 1.8651351 | AG14: 1.5719113 | AH14: 5.2431721 | AI14: 1.2671094 | AK14: 1.9183217 | AL14: 0.37765025 | AM14: 0.37994315 | AN14: 2.9494921 | AO14: 0.31626448 | AP14: 3.329059 | AQ14: 0.44560159 | AR14: 1.0808784 | AS14: 0.33644002 | AT14: 5.2431721 | AU14: 0.68625468 | AW14: 0.14877639 | AY14: 0.23808718
... A162: 12 | B162: 90NNN | C162: DryBean_2 | D162: {Area, Compactness, Eccentricity} | F162: 0 | G162: 1 | H162: 0 | I162: =1 - J162 -> 1 | J162: =IF(AY162 > 0, 1, 0) -> 0 | K162: 3 | L162: 0 | M162: 8551058.6 | N162: 4571756.4 | O162: 4676105.4 | P162: 18313333 | Q162: 2134872.6 | R162: 9876058.6 | S162: 4439149.6 | T162: 9453028.2 | U162: 6416550 | V162: 10764022 | W162: 3477250.4 | Y162: 6.7679427 | Z162: 3.6607623 | AA162: 3.6954577 | AB162: 11.926315 | AC162: 2.2739149 | AD162: 7.7026616 | AE162: 4.1734693 | AF162: 6.0664399 | AG162: 4.5623388 | AH162: 5.604095 | AI162: 4.8963437 | AK162: 6.7679427 | AL162: 1.201209 | AM162: 1.2445468 | AN162: 11.926315 | AO162: 0.9010368 | AP162: 7.7026616 | AQ162: 1.3072388 | AR162: 4.158231 | AS162: 0.79657594 | AT162: 5.604095 | AU162: 3.0885223 | AW162: 0.3571418 | AY162: -0.27155102
M382: Average Benchmark (results) | Y382: Average Benchmark (sequential timing) | AK382: Average Benchmark (parallel timing)
F383: TargetN | G383: #N | H383: Target (or sym) | I383: Gain <=0 | J383: Gain > 0 | K383: Pref | L383: Pref&Target | M383: BNL | N383: BNL Causal | O383: BNL Causal HM | P383: SFS | Q383: SFS Causal | R383: SaLSa | S383: SaLSa Causal | T383: D&C | U383: D&C Causal | V383: BBS | W383: BBS Causal | Y383: BNL | Z383: BNL Causal | AA383: BNL Causal HM | AB383: SFS | AC383: SFS Causal | AD383: SaLSa | AE383: SaLSa Causal | AF383: D&C | AG383: D&C Causal | AH383: BBS | AI383: BBS Causal | AK383: BNL | AL383: BNL Causal | AM383: BNL Causal HM | AN383: SFS | AO383: SFS Causal | AP383: SaLSa | AQ383: SaLSa Causal | AR383: D&C | AS383: D&C Causal | AT383: BBS | AU383: BBS Causal
A384: 21 | B384: 156XXXX | C384: Hong_Kong_Weather_3 | D384: {cloud, mean_wet_bulb_temp, rainfall, rel_humidity} | F384: 0 | G384: 0 | H384: 1 | I384: =I3 -> 1 | J384: =J3 -> 0 | K384: 4 | L384: 4 | M384: =IF($AY3 > 0, M3, M3) -> 984737.8 | N384: =IF($AY3 > 0, N3, M3) -> 984737.8 | O384: =IF($AY3 > 0, O3, M3) -> 984737.8 | P384: =IF($AY3 > 0, P3, P3) -> 1004122.8 | Q384: =IF($AY3 > 0, Q3, P3) -> 1004122.8 | R384: =IF($AY3 > 0, R3, R3) -> 881239.4 | S384: =IF($AY3 > 0, S3, R3) -> 881239.4 | T384: =IF($AY3 > 0, T3, T3) -> 4185627.2 | U384: =IF($AY3 > 0, U3, T3) -> 4185627.2 | V384: =IF($AY3 > 0, V3, V3) -> 1396199.2 | W384: =IF($AY3 > 0, W3, V3) -> 1396199.2 | Y384: =IF($AY3 > 0, Y3, Y3) -> 1.3528373 | Z384: =IF($AY3 > 0, Z3, Y3) -> 1.3528373 | AA384: =IF($AY3 > 0, AA3, Y3) -> 1.3528373 | AB384: =IF($AY3 > 0, AB3, AB3) -> 1.6085036 | AC384: =IF($AY3 > 0, AC3, AB3) -> 1.6085036 | AD384: =IF($AY3 > 0, AD3, AD3) -> 1.0889937 | AE384: =IF($AY3 > 0, AE3, AD3) -> 1.0889937 | AF384: =IF($AY3 > 0, AF3, AF3) -> 1.5281492 | AG384: =IF($AY3 > 0, AG3, AF3) -> 1.5281492 | AH384: =IF($AY3 > 0, AH3, AH3) -> 3.0406892 | AI384: =IF($AY3 > 0, AI3, AH3) -> 3.0406892 | AK384: =IF($AY3 > 0, AK3, AK3) -> 1.3528373 | AL384: =IF($AY3 > 0, AL3, AK3) -> 1.3528373 | AM384: =IF($AY3 > 0, AM3, AK3) -> 1.3528373 | AN384: =IF($AY3 > 0, AN3, AN3) -> 1.6085036 | AO384: =IF($AY3 > 0, AO3, AN3) -> 1.6085036 | AP384: =IF($AY3 > 0, AP3, AP3) -> 1.0889937 | AQ384: =IF($AY3 > 0, AQ3, AP3) -> 1.0889937 | AR384: =IF($AY3 > 0, AR3, AR3) -> 0.9788534 | AS384: =IF($AY3 > 0, AS3, AR3) -> 0.9788534 | AT384: =IF($AY3 > 0, AT3, AT3) -> 3.0406892 | AU384: =IF($AY3 > 0, AU3, AT3) -> 3.0406892
A385: 21 | B385: 156XXXN | C385: Hong_Kong_Weather_3 | D385: {cloud, mean_wet_bulb_temp, rainfall, rel_humidity} | F385: 0 | G385: 1 | H385: 0 | I385: =I4 -> 1 | J385: =J4 -> 0 | K385: 4 | L385: 0 | M385: =IF($AY4 > 0, M4, M4) -> 9774060 | N385: =IF($AY4 > 0, N4, M4) -> 9774060 | O385: =IF($AY4 > 0, O4, M4) -> 9774060 | P385: =IF($AY4 > 0, P4, P4) -> 14747945 | Q385: =IF($AY4 > 0, Q4, P4) -> 14747945 | R385: =IF($AY4 > 0, R4, R4) -> 16571915 | S385: =IF($AY4 > 0, S4, R4) -> 16571915 | T385: =IF($AY4 > 0, T4, T4) -> 4907318.2 | U385: =IF($AY4 > 0, U4, T4) -> 4907318.2 | V385: =IF($AY4 > 0, V4, V4) -> 21091677 | W385: =IF($AY4 > 0, W4, V4) -> 21091677 | Y385: =IF($AY4 > 0, Y4, Y4) -> 8.3987104 | Z385: =IF($AY4 > 0, Z4, Y4) -> 8.3987104 | AA385: =IF($AY4 > 0, AA4, Y4) -> 8.3987104 | AB385: =IF($AY4 > 0, AB4, AB4) -> 7.9635834 | AC385: =IF($AY4 > 0, AC4, AB4) -> 7.9635834 | AD385: =IF($AY4 > 0, AD4, AD4) -> 11.354685 | AE385: =IF($AY4 > 0, AE4, AD4) -> 11.354685 | AF385: =IF($AY4 > 0, AF4, AF4) -> 2.2395781 | AG385: =IF($AY4 > 0, AG4, AF4) -> 2.2395781 | AH385: =IF($AY4 > 0, AH4, AH4) -> 8.2811846 | AI385: =IF($AY4 > 0, AI4, AH4) -> 8.2811846 | AK385: =IF($AY4 > 0, AK4, AK4) -> 8.3987104 | AL385: =IF($AY4 > 0, AL4, AK4) -> 8.3987104 | AM385: =IF($AY4 > 0, AM4, AK4) -> 8.3987104 | AN385: =IF($AY4 > 0, AN4, AN4) -> 7.9635834 | AO385: =IF($AY4 > 0, AO4, AN4) -> 7.9635834 | AP385: =IF($AY4 > 0, AP4, AP4) -> 11.354685 | AQ385: =IF($AY4 > 0, AQ4, AP4) -> 11.354685 | AR385: =IF($AY4 > 0, AR4, AR4) -> 1.2717491 | AS385: =IF($AY4 > 0, AS4, AR4) -> 1.2717491 | AT385: =IF($AY4 > 0, AT4, AT4) -> 8.2811846 | AU385: =IF($AY4 > 0, AU4, AT4) -> 8.2811846
A386: 21 | B386: 156XXNX | C386: Hong_Kong_Weather_3 | D386: {cloud, mean_wet_bulb_temp, rainfall, rel_humidity} | F386: 0 | G386: 1 | H386: 0 | I386: =I5 -> 1 | J386: =J5 -> 0 | K386: 4 | L386: 0 | M386: =IF($AY5 > 0, M5, M5) -> 4329316.4 | N386: =IF($AY5 > 0, N5, M5) -> 4329316.4 | O386: =IF($AY5 > 0, O5, M5) -> 4329316.4 | P386: =IF($AY5 > 0, P5, P5) -> 1278792.2 | Q386: =IF($AY5 > 0, Q5, P5) -> 1278792.2 | R386: =IF($AY5 > 0, R5, R5) -> 616378.2 | S386: =IF($AY5 > 0, S5, R5) -> 616378.2 | T386: =IF($AY5 > 0, T5, T5) -> 4215981.4 | U386: =IF($AY5 > 0, U5, T5) -> 4215981.4 | V386: =IF($AY5 > 0, V5, V5) -> 2636300 | W386: =IF($AY5 > 0, W5, V5) -> 2636300 | Y386: =IF($AY5 > 0, Y5, Y5) -> 3.8965804 | Z386: =IF($AY5 > 0, Z5, Y5) -> 3.8965804 | AA386: =IF($AY5 > 0, AA5, Y5) -> 3.8965804 | AB386: =IF($AY5 > 0, AB5, AB5) -> 2.3151185 | AC386: =IF($AY5 > 0, AC5, AB5) -> 2.3151185 | AD386: =IF($AY5 > 0, AD5, AD5) -> 1.7500886 | AE386: =IF($AY5 > 0, AE5, AD5) -> 1.7500886 | AF386: =IF($AY5 > 0, AF5, AF5) -> 1.5827515 | AG386: =IF($AY5 > 0, AG5, AF5) -> 1.5827515 | AH386: =IF($AY5 > 0, AH5, AH5) -> 3.8325772 | AI386: =IF($AY5 > 0, AI5, AH5) -> 3.8325772 | AK386: =IF($AY5 > 0, AK5, AK5) -> 3.8965804 | AL386: =IF($AY5 > 0, AL5, AK5) -> 3.8965804 | AM386: =IF($AY5 > 0, AM5, AK5) -> 3.8965804 | AN386: =IF($AY5 > 0, AN5, AN5) -> 2.3151185 | AO386: =IF($AY5 > 0, AO5, AN5) -> 2.3151185 | AP386: =IF($AY5 > 0, AP5, AP5) -> 1.7500886 | AQ386: =IF($AY5 > 0, AQ5, AP5) -> 1.7500886 | AR386: =IF($AY5 > 0, AR5, AR5) -> 1.0548224 | AS386: =IF($AY5 > 0, AS5, AR5) -> 1.0548224 | AT386: =IF($AY5 > 0, AT5, AT5) -> 3.8325772 | AU386: =IF($AY5 > 0, AU5, AT5) -> 3.8325772
